<mujoco model="reachy2">
  <compiler angle="radian" meshdir="./obj_meshes/"/>
  <asset>
    <mesh name="mobile_base_visual" file="mobile_base_visual.obj"/>
    <mesh name="torso_visual_high" file="torso_visual_high.obj"/>
    <mesh name="torso_collider_no_cone" file="torso_collider_no_cone.obj"/>
    <mesh name="head_visual" file="head_visual.obj"/>
    <mesh name="head_collider" file="head_collider.obj"/>
    <mesh name="2D_sphere_visual" file="2D_sphere_visual.obj"/>
    <mesh name="upper_arm_visual" file="upper_arm_visual.obj"/>
    <mesh name="upper_arm_collider" file="upper_arm_collider.obj"/>
    <mesh name="forearm_visual" file="forearm_visual.obj"/>
    <mesh name="forearm_collider" file="forearm_collider.obj"/>
    <mesh name="pincette_right_collider" file="pincette_right_collider.obj"/>
    <mesh name="pincette_right_visual" file="pincette_right_visual.obj"/>
    <mesh name="pincette_proximal_collider" file="pincette_proximal_collider.obj"/>
    <mesh name="pincette_proximal_visual" file="pincette_proximal_visual.obj"/>
    <mesh name="pincette_distal_collider" file="pincette_distal_collider.obj"/>
    <mesh name="pincette_distal" file="pincette_distal.obj"/>
    <mesh name="pincette_left_collider" file="pincette_left_collider.obj"/>
    <mesh name="pincette_left_visual" file="pincette_left_visual.obj"/>
  </asset>
  <default>
      <joint damping="10" frictionloss="10"/>
      <position kp="100"/>
  </default>
  <worldbody>
    <body name="base_link">
      <freejoint/>
      <inertial pos="0.008 -0.00048 0.112" quat="-0.0363977 0.704069 0.0372966 0.708217" mass="24" diaginertia="0.709918 0.423857 0.407726"/>
      <geom type="mesh" contype="0" conaffinity="0" group="1" density="0" rgba="0.8 0.8 0.8 1" mesh="mobile_base_visual"/>
      <geom size="0.245 0.13045" pos="0 0 0.13045" type="cylinder" rgba="0.8 0.8 0.8 1"/>
      <body name="back_bar" pos="-0.122 0 0.164">
        <geom size="0.02 0.02 0.318" pos="0 0 0.318" type="box" contype="0" conaffinity="0" group="1" density="0" rgba="0.8 0.8 0.8 1"/>
        <geom size="0.02 0.02 0.318" pos="0 0 0.318" type="box" rgba="0.8 0.8 0.8 1"/>
        <body name="torso" pos="0.0768 0 0.836">
          <inertial pos="-0.051614 -0.000471 -0.018363" quat="0.708121 0.704566 0.0268143 -0.0378516" mass="6.314" diaginertia="0.0741454 0.0547883 0.0445377"/>
          <geom type="mesh" contype="0" conaffinity="0" group="1" density="0" mesh="torso_visual_high"/>
          <geom type="mesh" mesh="torso_collider_no_cone"/>
          <body name="logo" pos="0.047 0 0">
            <inertial pos="0 0 0" quat="0.820473 0.339851 -0.17592 0.424708" mass="0.001" diaginertia="1.02e-06 9.9e-07 9.9e-07"/>
            <body name="sr_cam_l_optical" pos="0.002597 0.009989 0.038089" quat="0.253404 -0.660141 0.660141 -0.253404">
              <inertial pos="0 0 0" quat="0.820473 0.339851 -0.17592 0.424708" mass="0.001" diaginertia="1.02e-06 9.9e-07 9.9e-07"/>
            </body>
            <body name="sr_cam_l_frame" pos="0.002597 0.009989 0.038089" quat="0.913545 0 0.406737 0">
              <inertial pos="0 0 0" quat="0.820473 0.339851 -0.17592 0.424708" mass="0.001" diaginertia="1.02e-06 9.9e-07 9.9e-07"/>
            </body>
            <body name="sr_cam_r_optical" pos="0.002597 -0.009989 0.038089" quat="0.253404 -0.660141 0.660141 -0.253404">
              <inertial pos="0 0 0" quat="0.820473 0.339851 -0.17592 0.424708" mass="0.001" diaginertia="1.02e-06 9.9e-07 9.9e-07"/>
            </body>
            <body name="sr_cam_r_frame" pos="0.002597 -0.009989 0.038089" quat="0.913545 0 0.406737 0">
              <inertial pos="0 0 0" quat="0.820473 0.339851 -0.17592 0.424708" mass="0.001" diaginertia="1.02e-06 9.9e-07 9.9e-07"/>
            </body>
          </body>
          <body name="neck_base_link" pos="0 0 0.125" quat="0.996195 0 0.0871557 0">
            <inertial pos="0 0 0" quat="0.820473 0.339851 -0.17592 0.424708" mass="0.001" diaginertia="1.02e-06 9.9e-07 9.9e-07"/>
            <body name="neck_dummy_link1">
              <inertial pos="0 0 0" quat="0.5 0.5 -0.5 0.5" mass="0.005" diaginertia="3e-06 2.54167e-06 2.54167e-06"/>
              <joint name="neck_roll" pos="0 0 0" axis="1 0 0" range="-0.35 0.35" actuatorfrcrange="-1000 1000"/>
              <body name="neck_dummy_link2">
                <inertial pos="0 0 0" quat="0.5 0.5 -0.5 0.5" mass="0.005" diaginertia="3e-06 2.54167e-06 2.54167e-06"/>
                <joint name="neck_pitch" pos="0 0 0" axis="0 1 0" range="-0.35 0.35" actuatorfrcrange="-1000 1000"/>
                <body name="neck_link">
                  <inertial pos="0 0 -0.025" quat="0.5 0.5 -0.5 0.5" mass="0.49" diaginertia="0.000294 0.000249083 0.000249083"/>
                  <joint name="neck_yaw" pos="0 0 0" axis="0 0 1" range="-1.57 1.57" actuatorfrcrange="-1000 1000"/>
                  <camera name="left_teleop_cam"  pos="0 0 0" euler="0 0 0"/>
                  <body name="neck_ball_link">
                    <inertial pos="0 0 0" quat="0.820473 0.339851 -0.17592 0.424708" mass="0.001" diaginertia="1.02e-06 9.9e-07 9.9e-07"/>
                    <body name="neck_out_link">
                      <inertial pos="0 0 0" quat="0.820473 0.339851 -0.17592 0.424708" mass="0.001" diaginertia="1.02e-06 9.9e-07 9.9e-07"/>
                      <body name="head">
                        <inertial pos="0.0116978 -0.00022144 0.0611705" quat="0.552073 0.545887 -0.44927 0.442017" mass="0.325" diaginertia="0.000897058 0.000850732 0.00063132"/>
                        <geom type="mesh" contype="0" conaffinity="0" group="1" density="0" mesh="head_visual"/>
                        <geom type="mesh" mesh="head_collider"/>
                        <body name="head_base">
                          <inertial pos="0 0 0" quat="0.820473 0.339851 -0.17592 0.424708" mass="0.001" diaginertia="1.02e-06 9.9e-07 9.9e-07"/>
                        </body>
                        <body name="head_tip" pos="0.057 0 0.056">
                          <inertial pos="0 0 0" quat="0.820473 0.339851 -0.17592 0.424708" mass="0.001" diaginertia="1.02e-06 9.9e-07 9.9e-07"/>
                        </body>
                        <body name="left_camera" pos="0.03531 0.0325 0.056">
                          <inertial pos="0 0 0" mass="1e-05" diaginertia="1e-06 1e-06 1e-06"/>
                          <body name="left_camera_optical" quat="0.5 -0.5 0.5 -0.5">
                            <inertial pos="0 0 0" quat="0.820473 0.339851 -0.17592 0.424708" mass="0.001" diaginertia="1.02e-06 9.9e-07 9.9e-07"/>
                          </body>
                        </body>
                        <body name="right_camera" pos="0.03531 -0.0325 0.056">
                          <inertial pos="0 0 0" mass="1e-05" diaginertia="1e-06 1e-06 1e-06"/>
                          <body name="right_camera_optical" quat="0.5 -0.5 0.5 -0.5"/>
                        </body>
                      </body>
                    </body>
                  </body>
                </body>
              </body>
            </body>
          </body>
          <body name="r_shoulder_base_link" pos="0 -0.2 0" quat="0.637288 0.759491 0.0999889 0.0839006">
            <inertial pos="0 0 0" quat="0.820473 0.339851 -0.17592 0.424708" mass="0.001" diaginertia="1.02e-06 9.9e-07 9.9e-07"/>
            <body name="r_shoulder_dummy_link1">
              <inertial pos="0 0 0" quat="0.820473 0.339851 -0.17592 0.424708" mass="0.001" diaginertia="1.02e-06 9.9e-07 9.9e-07"/>
              <body name="r_shoulder_dummy_link2" quat="0.707107 -0.707107 0 0">
                <inertial pos="0 0 0" quat="0.820473 0.339851 -0.17592 0.424708" mass="0.001" diaginertia="1.02e-06 9.9e-07 9.9e-07"/>
                <body name="r_shoulder_first_link">
                  <inertial pos="9.6e-05 -1.5e-05 -0.01777" quat="0.996708 0.000282525 0.00106617 -0.0810711" mass="0.487" diaginertia="0.000578016 0.000572943 0.000243342"/>
                  <joint name="r_shoulder_pitch" pos="0 0 0" axis="0 1 0" range="-1.5708 1.5708" actuatorfrcrange="-1000 1000"/>
                  <geom quat="0.707107 0.707107 0 0" type="mesh" contype="0" conaffinity="0" group="1" density="0" mesh="2D_sphere_visual"/>
                  <body name="r_shoulder_ball_link">
                    <inertial pos="0 0 0" quat="0.820473 0.339851 -0.17592 0.424708" mass="0.001" diaginertia="1.02e-06 9.9e-07 9.9e-07"/>
                    <joint name="r_shoulder_roll" pos="0 0 0" axis="1 0 0" range="-1.5708 0" actuatorfrcrange="-1000 1000"/>
                    <body name="r_shoulder_fix_link" quat="0.707107 0.707107 0 0">
                      <inertial pos="0 0 0" quat="0.820473 0.339851 -0.17592 0.424708" mass="0.001" diaginertia="1.02e-06 9.9e-07 9.9e-07"/>
                      <body name="r_elbow_arm_link" quat="0.5 0.5 0.5 -0.5">
                        <inertial pos="-0.000669 0.000509 0.144798" quat="0.999882 0.0118024 0.0097362 0.00163562" mass="1.62" diaginertia="0.00786631 0.00700087 0.00182283"/>
                        <geom type="mesh" contype="0" conaffinity="0" group="1" density="0" mesh="upper_arm_visual"/>
                        <geom type="mesh" mesh="upper_arm_collider"/>
                        <body name="r_elbow_base_link" pos="0 0 0.28">
                          <inertial pos="0 0 0" quat="0.820473 0.339851 -0.17592 0.424708" mass="0.001" diaginertia="1.02e-06 9.9e-07 9.9e-07"/>
                          <body name="r_elbow_dummy_link1">
                            <inertial pos="0 0 0" quat="0.820473 0.339851 -0.17592 0.424708" mass="0.001" diaginertia="1.02e-06 9.9e-07 9.9e-07"/>
                            <body name="r_elbow_dummy_link2" quat="2.31079e-07 0.707107 0.707107 2.31079e-07">
                              <inertial pos="0 0 0" quat="0.820473 0.339851 -0.17592 0.424708" mass="0.001" diaginertia="1.02e-06 9.9e-07 9.9e-07"/>
                              <body name="r_elbow_first_link">
                                <inertial pos="9.6e-05 -1.5e-05 -0.01777" quat="0.996708 0.000282525 0.00106617 -0.0810711" mass="0.487" diaginertia="0.000578016 0.000572943 0.000243342"/>
                                <joint name="r_elbow_yaw" pos="0 0 0" axis="0 0 1" range="-1.5708 1.5708" actuatorfrcrange="-1000 1000"/>
                                <geom quat="2.31079e-07 0.707107 -0.707107 -2.31079e-07" type="mesh" contype="0" conaffinity="0" group="1" density="0" mesh="2D_sphere_visual"/>
                                <body name="r_elbow_ball_link">
                                  <inertial pos="0 0 0" quat="0.820473 0.339851 -0.17592 0.424708" mass="0.001" diaginertia="1.02e-06 9.9e-07 9.9e-07"/>
                                  <joint name="r_elbow_pitch" pos="0 0 0" axis="0 1 0" range="-2.25 0.1" actuatorfrcrange="-1000 1000" damping="0.1" frictionloss="0.1"/>
                                  <body name="r_elbow_fix_link" quat="2.31079e-07 0.707107 0.707107 2.31079e-07">
                                    <inertial pos="0 0 0" quat="0.820473 0.339851 -0.17592 0.424708" mass="0.001" diaginertia="1.02e-06 9.9e-07 9.9e-07"/>
                                    <body name="r_elbow_forearm_link">
                                      <inertial pos="0.00092892 -0.00254548 0.140212" quat="0.699789 -0.0153163 -0.00639197 0.714157" mass="0.907191" diaginertia="0.00445918 0.00428633 0.00047192"/>
                                      <geom type="mesh" contype="0" conaffinity="0" group="1" density="0" mesh="forearm_visual"/>
                                      <geom type="mesh" mesh="forearm_collider"/>
                                      <body name="r_wrist_base_link" pos="0 0 0.28" quat="0 0.707107 0.707107 0">
                                        <inertial pos="0 0 0" quat="0.820473 0.339851 -0.17592 0.424708" mass="0.001" diaginertia="1.02e-06 9.9e-07 9.9e-07"/>
                                        <body name="r_wrist_dummy_link1">
                                          <inertial pos="0 0 0" quat="0.5 0.5 -0.5 0.5" mass="0.001" diaginertia="2.66667e-07 1.41667e-07 1.41667e-07"/>
                                          <joint name="r_wrist_roll" pos="0 0 0" axis="1 0 0" range="-0.785398 0.785398" actuatorfrcrange="-1000 1000"/>
                                          <body name="r_wrist_dummy_link2">
                                            <inertial pos="0 0 0" quat="0.5 0.5 -0.5 0.5" mass="0.001" diaginertia="2.66667e-07 1.41667e-07 1.41667e-07"/>
                                            <joint name="r_wrist_pitch" pos="0 0 0" axis="0 1 0" range="-0.785398 0.785398" actuatorfrcrange="-1000 1000"/>
                                            <body name="r_wrist_link">
                                              <inertial pos="0 0 -0.005" quat="0.5 0.5 -0.5 0.5" mass="0.098" diaginertia="2.61333e-05 1.38833e-05 1.38833e-05"/>
                                              <joint name="r_wrist_yaw" pos="0 0 0" axis="0 0 1" range="-1.57 1.57" actuatorfrcrange="-1000 1000"/>
                                              <geom size="0.02 0.005" type="cylinder" contype="0" conaffinity="0" group="1" density="0" rgba="0.8 0.8 0.8 1"/>
                                              <geom size="0.02 0.005" pos="0 0 0.005" type="cylinder" rgba="0.8 0.8 0.8 1"/>
                                              <body name="r_wrist_ball_link">
                                                <inertial pos="0 0 0" quat="0.820473 0.339851 -0.17592 0.424708" mass="0.001" diaginertia="1.02e-06 9.9e-07 9.9e-07"/>
                                                <body name="r_wrist_out_link" quat="3.26795e-07 1 0 0">
                                                  <inertial pos="0 0 0" quat="0.820473 0.339851 -0.17592 0.424708" mass="0.001" diaginertia="1.02e-06 9.9e-07 9.9e-07"/>
                                                  <body name="r_hand_palm_link">
                                                    <inertial pos="0.00883565 0.00950712 0.0451131" quat="0.407719 0.162455 -0.763476 0.473791" mass="0.30798" diaginertia="0.000246008 0.000226522 0.00014863"/>
                                                    <geom type="mesh" mesh="pincette_right_collider"/>
                                                    <geom type="mesh" contype="0" conaffinity="0" group="1" density="0" mesh="pincette_right_visual"/>
                                                    <body name="r_hand_virtual_gripper_link" pos="0 0 0.070028">
                                                      <inertial pos="0 0 0" quat="0.820473 0.339851 -0.17592 0.424708" mass="0.001" diaginertia="1.02e-06 9.9e-07 9.9e-07"/>
                                                      <joint name="r_hand_finger" pos="0 0 0" axis="1 0 0" range="0 2.27" actuatorfrcrange="-100 100"/>
                                                    </body>
                                                    <body name="r_hand_proximal_link" pos="-0.010196 0.03792 0.070028">
                                                      <inertial pos="4.101e-05 0.002756 0.019654" quat="0.707941 0.00659338 -0.00992804 0.706171" mass="0.0392639" diaginertia="2.00384e-05 1.93703e-05 4.62126e-06"/>
                                                      <joint name="r_hand_finger_proximal" pos="0 0 0" axis="1 0 0" range="-0.51 0.554" actuatorfrcrange="-100 100"/>
                                                      <geom type="mesh" mesh="pincette_proximal_collider"/>
                                                      <geom type="mesh" contype="0" conaffinity="0" group="1" density="0" mesh="pincette_proximal_visual"/>
                                                      <body name="r_hand_distal_link" pos="0 0 0.049997">
                                                        <inertial pos="6.95e-06 -6.402e-05 0.0177268" quat="0.700477 0.096599 -0.096599 0.700477" mass="0.0282109" diaginertia="7.31707e-06 6.83e-06 2.44293e-06"/>
                                                        <joint name="r_hand_finger_distal" pos="0 0 0" axis="1 0 0" range="-0.51 0.554" actuatorfrcrange="-100 100"/>
                                                        <geom type="mesh" mesh="pincette_distal_collider"/>
                                                        <geom type="mesh" contype="0" conaffinity="0" group="1" density="0" mesh="pincette_distal"/>
                                                      </body>
                                                    </body>
                                                    <body name="r_hand_proximal_mimic_link" pos="-0.010196 -0.03792 0.070028" quat="3.26795e-07 0 0 1">
                                                      <inertial pos="4.101e-05 0.002756 0.019654" quat="0.707941 0.00659338 -0.00992804 0.706171" mass="0.0392639" diaginertia="2.00384e-05 1.93703e-05 4.62126e-06"/>
                                                      <joint name="r_hand_finger_proximal_mimic" pos="0 0 0" axis="1 0 0" range="-0.51 0.554" actuatorfrcrange="-100 100"/>
                                                      <geom type="mesh" mesh="pincette_proximal_collider"/>
                                                      <geom type="mesh" contype="0" conaffinity="0" group="1" density="0" mesh="pincette_proximal_visual"/>
                                                      <body name="r_hand_distal_mimic_link" pos="0 0 0.049997">
                                                        <inertial pos="6.95e-06 -6.402e-05 0.0177268" quat="0.700477 0.096599 -0.096599 0.700477" mass="0.0282109" diaginertia="7.31707e-06 6.83e-06 2.44293e-06"/>
                                                        <joint name="r_hand_finger_distal_mimic" pos="0 0 0" axis="1 0 0" range="-0.51 0.554" actuatorfrcrange="-100 100" damping="0.1" frictionloss="0.1"/>
                                                        <geom type="mesh" mesh="pincette_distal_collider"/>
                                                        <geom type="mesh" contype="0" conaffinity="0" group="1" density="0" mesh="pincette_distal"/>
                                                      </body>
                                                    </body>
                                                    <body name="r_arm_tip" pos="0 0 0.1" quat="0 1 0 0">
                                                      <inertial pos="0 0 0" quat="0.820473 0.339851 -0.17592 0.424708" mass="0.001" diaginertia="1.02e-06 9.9e-07 9.9e-07"/>
                                                    </body>
                                                  </body>
                                                </body>
                                              </body>
                                            </body>
                                          </body>
                                        </body>
                                      </body>
                                    </body>
                                  </body>
                                </body>
                              </body>
                            </body>
                          </body>
                        </body>
                      </body>
                    </body>
                  </body>
                </body>
              </body>
            </body>
          </body>
          <body name="l_shoulder_base_link" pos="0 0.2 0" quat="0.637288 -0.759491 0.0999889 -0.0839006">
            <inertial pos="0 0 0" quat="0.820473 0.339851 -0.17592 0.424708" mass="0.001" diaginertia="1.02e-06 9.9e-07 9.9e-07"/>
            <body name="l_shoulder_dummy_link1">
              <inertial pos="0 0 0" quat="0.820473 0.339851 -0.17592 0.424708" mass="0.001" diaginertia="1.02e-06 9.9e-07 9.9e-07"/>
              <body name="l_shoulder_dummy_link2" quat="0.707107 0.707107 0 0">
                <inertial pos="0 0 0" quat="0.820473 0.339851 -0.17592 0.424708" mass="0.001" diaginertia="1.02e-06 9.9e-07 9.9e-07"/>
                <body name="l_shoulder_first_link">
                  <inertial pos="9.6e-05 -1.5e-05 -0.01777" quat="0.996708 0.000282525 0.00106617 -0.0810711" mass="0.487" diaginertia="0.000578016 0.000572943 0.000243342"/>
                  <joint name="l_shoulder_pitch" pos="0 0 0" axis="0 1 0" range="-1.5708 1.5708" actuatorfrcrange="-1000 1000"/>
                  <geom quat="0.707107 -0.707107 0 0" type="mesh" contype="0" conaffinity="0" group="1" density="0" mesh="2D_sphere_visual"/>
                  <body name="l_shoulder_ball_link">
                    <inertial pos="0 0 0" quat="0.820473 0.339851 -0.17592 0.424708" mass="0.001" diaginertia="1.02e-06 9.9e-07 9.9e-07"/>
                    <joint name="l_shoulder_roll" pos="0 0 0" axis="1 0 0" range="0 1.5708" actuatorfrcrange="-1000 1000" damping="0.1" frictionloss="0.1"/>
                    <body name="l_shoulder_fix_link" quat="0.707107 0.707107 0 0">
                      <inertial pos="0 0 0" quat="0.820473 0.339851 -0.17592 0.424708" mass="0.001" diaginertia="1.02e-06 9.9e-07 9.9e-07"/>
                      <body name="l_elbow_arm_link" quat="0.5 0.5 -0.5 0.5">
                        <inertial pos="-0.000669 0.000509 0.144798" quat="0.999882 0.0118024 0.0097362 0.00163562" mass="1.62" diaginertia="0.00786631 0.00700087 0.00182283"/>
                        <geom type="mesh" contype="0" conaffinity="0" group="1" density="0" mesh="upper_arm_visual"/>
                        <geom type="mesh" mesh="upper_arm_collider"/>
                        <body name="l_elbow_base_link" pos="0 0 0.28">
                          <inertial pos="0 0 0" quat="0.820473 0.339851 -0.17592 0.424708" mass="0.001" diaginertia="1.02e-06 9.9e-07 9.9e-07"/>
                          <body name="l_elbow_dummy_link1">
                            <inertial pos="0 0 0" quat="0.820473 0.339851 -0.17592 0.424708" mass="0.001" diaginertia="1.02e-06 9.9e-07 9.9e-07"/>
                            <body name="l_elbow_dummy_link2" quat="2.31079e-07 0.707107 -0.707107 -2.31079e-07">
                              <inertial pos="0 0 0" quat="0.820473 0.339851 -0.17592 0.424708" mass="0.001" diaginertia="1.02e-06 9.9e-07 9.9e-07"/>
                              <body name="l_elbow_first_link">
                                <inertial pos="9.6e-05 -1.5e-05 -0.01777" quat="0.996708 0.000282525 0.00106617 -0.0810711" mass="0.487" diaginertia="0.000578016 0.000572943 0.000243342"/>
                                <joint name="l_elbow_yaw" pos="0 0 0" axis="0 0 1" range="-1.5708 1.5708" actuatorfrcrange="-1000 1000"/>
                                <geom quat="2.31079e-07 0.707107 0.707107 2.31079e-07" type="mesh" contype="0" conaffinity="0" group="1" density="0" mesh="2D_sphere_visual"/>
                                <body name="l_elbow_ball_link">
                                  <inertial pos="0 0 0" quat="0.820473 0.339851 -0.17592 0.424708" mass="0.001" diaginertia="1.02e-06 9.9e-07 9.9e-07"/>
                                  <joint name="l_elbow_pitch" pos="0 0 0" axis="0 1 0" range="-2.25 0.1" actuatorfrcrange="-1000 1000"/>
                                  <body name="l_elbow_fix_link" quat="2.31079e-07 0.707107 0.707107 2.31079e-07">
                                    <inertial pos="0 0 0" quat="0.820473 0.339851 -0.17592 0.424708" mass="0.001" diaginertia="1.02e-06 9.9e-07 9.9e-07"/>
                                    <body name="l_elbow_forearm_link">
                                      <inertial pos="0.00092892 -0.00254548 0.140212" quat="0.699789 -0.0153163 -0.00639197 0.714157" mass="0.907191" diaginertia="0.00445918 0.00428633 0.00047192"/>
                                      <geom type="mesh" contype="0" conaffinity="0" group="1" density="0" mesh="forearm_visual"/>
                                      <geom type="mesh" mesh="forearm_collider"/>
                                      <body name="l_wrist_base_link" pos="0 0 0.28" quat="0 0.707107 0.707107 0">
                                        <inertial pos="0 0 0" quat="0.820473 0.339851 -0.17592 0.424708" mass="0.001" diaginertia="1.02e-06 9.9e-07 9.9e-07"/>
                                        <body name="l_wrist_dummy_link1">
                                          <inertial pos="0 0 0" quat="0.5 0.5 -0.5 0.5" mass="0.001" diaginertia="2.66667e-07 1.41667e-07 1.41667e-07"/>
                                          <joint name="l_wrist_roll" pos="0 0 0" axis="1 0 0" range="-0.785398 0.785398" actuatorfrcrange="-1000 1000"/>
                                          <body name="l_wrist_dummy_link2">
                                            <inertial pos="0 0 0" quat="0.5 0.5 -0.5 0.5" mass="0.001" diaginertia="2.66667e-07 1.41667e-07 1.41667e-07"/>
                                            <joint name="l_wrist_pitch" pos="0 0 0" axis="0 1 0" range="-0.785398 0.785398" actuatorfrcrange="-1000 1000"/>
                                            <body name="l_wrist_link">
                                              <inertial pos="0 0 -0.005" quat="0.5 0.5 -0.5 0.5" mass="0.098" diaginertia="2.61333e-05 1.38833e-05 1.38833e-05"/>
                                              <joint name="l_wrist_yaw" pos="0 0 0" axis="0 0 1" range="-1.57 1.57" actuatorfrcrange="-1000 1000" damping="0.1" frictionloss="0.1"/>
                                              <geom size="0.02 0.005" type="cylinder" contype="0" conaffinity="0" group="1" density="0" rgba="0.8 0.8 0.8 1"/>
                                              <geom size="0.02 0.005" pos="0 0 0.005" type="cylinder" rgba="0.8 0.8 0.8 1"/>
                                              <body name="l_wrist_ball_link">
                                                <inertial pos="0 0 0" quat="0.820473 0.339851 -0.17592 0.424708" mass="0.001" diaginertia="1.02e-06 9.9e-07 9.9e-07"/>
                                                <body name="l_wrist_out_link" quat="3.26795e-07 1 0 0">
                                                  <inertial pos="0 0 0" quat="0.820473 0.339851 -0.17592 0.424708" mass="0.001" diaginertia="1.02e-06 9.9e-07 9.9e-07"/>
                                                  <body name="l_hand_palm_link">
                                                    <inertial pos="0.00883565 -0.00950712 0.0451131" quat="0.183598 0.40094 -0.476281 0.76072" mass="0.30798" diaginertia="0.000244648 0.000225194 0.000149038"/>
                                                    <geom type="mesh" mesh="pincette_left_collider"/>
                                                    <geom type="mesh" contype="0" conaffinity="0" group="1" density="0" mesh="pincette_left_visual"/>
                                                    <body name="l_hand_virtual_gripper_link" pos="0 0 0.070028">
                                                      <inertial pos="0 0 0" quat="0.820473 0.339851 -0.17592 0.424708" mass="0.001" diaginertia="1.02e-06 9.9e-07 9.9e-07"/>
                                                      <joint name="l_hand_finger" pos="0 0 0" axis="1 0 0" range="0 2.27" actuatorfrcrange="-100 100"/>
                                                    </body>
                                                    <body name="l_hand_proximal_link" pos="-0.010196 0.03792 0.070028">
                                                      <inertial pos="4.101e-05 0.002756 0.019654" quat="0.707941 0.00659338 -0.00992804 0.706171" mass="0.0392639" diaginertia="2.00384e-05 1.93703e-05 4.62126e-06"/>
                                                      <joint name="l_hand_finger_proximal" pos="0 0 0" axis="1 0 0" range="-0.51 0.554" actuatorfrcrange="-100 100"/>
                                                      <geom type="mesh" mesh="pincette_proximal_collider"/>
                                                      <geom type="mesh" contype="0" conaffinity="0" group="1" density="0" mesh="pincette_proximal_visual"/>
                                                      <body name="l_hand_distal_link" pos="0 0 0.049997">
                                                        <inertial pos="6.95e-06 -6.402e-05 0.0177268" quat="0.700477 0.096599 -0.096599 0.700477" mass="0.0282109" diaginertia="7.31707e-06 6.83e-06 2.44293e-06"/>
                                                        <joint name="l_hand_finger_distal" pos="0 0 0" axis="1 0 0" range="-0.51 0.554" actuatorfrcrange="-100 100"/>
                                                        <geom type="mesh" mesh="pincette_distal_collider"/>
                                                        <geom type="mesh" contype="0" conaffinity="0" group="1" density="0" mesh="pincette_distal"/>
                                                      </body>
                                                    </body>
                                                    <body name="l_hand_proximal_mimic_link" pos="-0.010196 -0.03792 0.070028" quat="3.26795e-07 0 0 1">
                                                      <inertial pos="4.101e-05 0.002756 0.019654" quat="0.707941 0.00659338 -0.00992804 0.706171" mass="0.0392639" diaginertia="2.00384e-05 1.93703e-05 4.62126e-06"/>
                                                      <joint name="l_hand_finger_proximal_mimic" pos="0 0 0" axis="1 0 0" range="-0.51 0.554" actuatorfrcrange="-100 100"/>
                                                      <geom type="mesh" mesh="pincette_proximal_collider"/>
                                                      <geom type="mesh" contype="0" conaffinity="0" group="1" density="0" mesh="pincette_proximal_visual"/>
                                                      <body name="l_hand_distal_mimic_link" pos="0 0 0.049997">
                                                        <inertial pos="6.95e-06 -6.402e-05 0.0177268" quat="0.700477 0.096599 -0.096599 0.700477" mass="0.0282109" diaginertia="7.31707e-06 6.83e-06 2.44293e-06"/>
                                                        <joint name="l_hand_finger_distal_mimic" pos="0 0 0" axis="1 0 0" range="-0.51 0.554" actuatorfrcrange="-100 100" damping="0.1" frictionloss="0.1"/>
                                                        <geom type="mesh" mesh="pincette_distal_collider"/>
                                                        <geom type="mesh" contype="0" conaffinity="0" group="1" density="0" mesh="pincette_distal"/>
                                                      </body>
                                                    </body>
                                                    <body name="l_arm_tip" pos="0 0 0.1" quat="0 1 0 0">
                                                      <inertial pos="0 0 0" quat="0.820473 0.339851 -0.17592 0.424708" mass="0.001" diaginertia="1.02e-06 9.9e-07 9.9e-07"/>
                                                    </body>
                                                  </body>
                                                </body>
                                              </body>
                                            </body>
                                          </body>
                                        </body>
                                      </body>
                                    </body>
                                  </body>
                                </body>
                              </body>
                            </body>
                          </body>
                        </body>
                      </body>
                    </body>
                  </body>
                </body>
              </body>
            </body>
          </body>
        </body>
      </body>
      <body name="left_bar" pos="0.080966 0.117182 0.164" quat="0.965846 0.0254078 -0.103998 0.235966">
        <geom size="0.02 0.02 0.32546" pos="0 0 0.32546" type="box" contype="0" conaffinity="0" group="1" density="0" rgba="0.8 0.8 0.8 1"/>
        <geom size="0.02 0.02 0.32546" pos="0 0 0.32546" type="box" rgba="0.8 0.8 0.8 1"/>
      </body>
      <body name="right_bar" pos="0.080966 -0.117182 0.164" quat="0.965846 -0.0254078 -0.103998 -0.235966">
        <geom size="0.02 0.02 0.32546" pos="0 0 0.32546" type="box" contype="0" conaffinity="0" group="1" density="0" rgba="0.8 0.8 0.8 1"/>
        <geom size="0.02 0.02 0.32546" pos="0 0 0.32546" type="box" rgba="0.8 0.8 0.8 1"/>
      </body>
    </body>
  </worldbody>
  <actuator>
    <position name="neck_roll" joint="neck_roll" gear="1" inheritrange="1"  />
    <position name="neck_pitch" joint="neck_pitch" gear="1" inheritrange="1"  />
    <position name="neck_yaw" joint="neck_yaw" gear="1" inheritrange="1"  />
    <position name="l_shoulder_pitch" joint="l_shoulder_pitch" gear="1" inheritrange="1"  />
    <position name="l_shoulder_roll" joint="l_shoulder_roll" gear="1" inheritrange="1"  />
    <position name="l_elbow_yaw" joint="l_elbow_yaw" gear="1" inheritrange="1"  />
    <position name="l_elbow_pitch" joint="l_elbow_pitch" gear="1" inheritrange="1"  />
    <position name="l_wrist_roll" joint="l_wrist_roll" gear="1" inheritrange="1"  />
    <position name="l_wrist_pitch" joint="l_wrist_pitch" gear="1" inheritrange="1"  />
    <position name="l_wrist_yaw" joint="l_wrist_yaw" gear="1" inheritrange="1"  />
    <position name="r_shoulder_pitch" joint="r_shoulder_pitch" gear="1" inheritrange="1"  />
    <position name="r_shoulder_roll" joint="r_shoulder_roll" gear="1" inheritrange="1"  />
    <position name="r_elbow_yaw" joint="r_elbow_yaw" gear="1" inheritrange="1"  />
    <position name="r_elbow_pitch" joint="r_elbow_pitch" gear="1" inheritrange="1"  />
    <position name="r_wrist_roll" joint="r_wrist_roll" gear="1" inheritrange="1"  />
    <position name="r_wrist_pitch" joint="r_wrist_pitch" gear="1" inheritrange="1"  />
    <position name="r_wrist_yaw" joint="r_wrist_yaw" gear="1" inheritrange="1"  />
    <!-- <position name="r_hand_finger" joint="r_hand_finger" gear="1" inheritrange="1"  />
    <position name="r_hand_finger_proximal" joint="r_hand_finger_proximal" gear="1" inheritrange="1"  />
    <position name="r_hand_finger_distal" joint="r_hand_finger_distal" gear="1" inheritrange="1"  />
    <position name="l_hand_finger" joint="l_hand_finger" gear="1" inheritrange="1"  />
    <position name="l_hand_finger_proximal" joint="l_hand_finger_proximal" gear="1" inheritrange="1"  />
    <position name="l_hand_finger_distal" joint="l_hand_finger_distal" gear="1" inheritrange="1"  />
    <position name="r_hand_finger_proximal_mimic" joint="r_hand_finger_proximal_mimic" gear="1" inheritrange="1"  />
    <position name="r_hand_finger_distal_mimic" joint="r_hand_finger_distal_mimic" gear="1" inheritrange="1"  />
    <position name="l_hand_finger_proximal_mimic" joint="l_hand_finger_proximal_mimic" gear="1" inheritrange="1"  />
    <position name="l_hand_finger_distal_mimic" joint="l_hand_finger_distal_mimic" gear="1" inheritrange="1"  /> -->
  </actuator>
</mujoco>