<?xml version="1.0" ?>
<!-- =================================================================================== -->
<!-- |    This document was autogenerated by xacro from urdf/reachy.urdf.xacro         | -->
<!-- |    EDITING THIS FILE BY HAND IS NOT RECOMMENDED                                 | -->
<!-- =================================================================================== -->
<robot name="reachy2">
  <mujoco>
    <compiler
        meshdir="./obj_meshes"
        balanceinertia="true"
        discardvisual="false"
        fusestatic="true" />
  </mujoco>
  <!-- convergence angle (rad) of the cameras. 0=parallel-->
  <!-- URDF definition is so stupid we have to do that... -->
  <!-- <material name="gripperblack"> -->
  <!--     <color rgba="0.4 0.4 0.4 1"/> -->
  <!-- </material> -->
  <!-- <material name="gripperwhite"> -->
  <!--     <color rgba="0.9 0.9 0.9 1"/> -->
  <!-- </material> -->
  <!-- <material name="reachy_yellow"> -->
  <!--     <color rgba="0.8 0.8 0.0 1"/> -->
  <!-- </material> -->
  <!-- <material name="reachy_grey"> -->
  <!--     <color rgba="0.8 0.8 0.8 1"/> -->
  <!-- </material> -->
  <!-- <material name="reachy_metal"> -->
  <!--     <color rgba="0.85 0.85 0.85 1.0"/> -->
  <!-- </material> -->
  <!-- <material name="torsoblack"> -->
  <!--     <color rgba="0.5 0.5 0.5 1.0"/> -->
  <!-- </material> -->
  <!-- <material name="eyewhite"> -->
  <!--     <color rgba="1.0 1.0 1.0 1.0"/> -->
  <!-- </material> -->
  <!-- <material name="orbita2dmetal"> -->
  <!--     <color rgba="0.85 0.85 0.85 1.0"/> -->
  <!-- </material> -->
  <!-- <material name="orbita2dgrey"> -->
  <!--     <color rgba="0.8 0.8 0.8 1.0"/> -->
  <!-- </material> -->
  <!-- <material name="orbita3d_yellow"> -->
  <!--     <color rgba="0.8 0.8 0.0 1"/> -->
  <!-- </material> -->
  <!-- <material name="orbita3d_grey"> -->
  <!--     <color rgba="0.8 0.8 0.8 1"/> -->
  <!-- </material> -->
  <material name="camblack">
    <color rgba="0.2 0.2 0.2 1"/>
  </material>
  <material name="neckwhite">
    <color rgba="0.9 0.9 0.9 1"/>
  </material>
  <!-- URDF definition is so stupid we have to do that... -->
  <!-- <material name="gripperblack"> -->
  <!--     <color rgba="0.4 0.4 0.4 1"/> -->
  <!-- </material> -->
  <!-- <material name="gripperwhite"> -->
  <!--     <color rgba="0.9 0.9 0.9 1"/> -->
  <!-- </material> -->
  <!-- <material name="reachy_yellow"> -->
  <!--     <color rgba="0.8 0.8 0.0 1"/> -->
  <!-- </material> -->
  <!-- <material name="reachy_grey"> -->
  <!--     <color rgba="0.8 0.8 0.8 1"/> -->
  <!-- </material> -->
  <!-- <material name="reachy_metal"> -->
  <!--     <color rgba="0.85 0.85 0.85 1.0"/> -->
  <!-- </material> -->
  <!-- <material name="torsoblack"> -->
  <!--     <color rgba="0.5 0.5 0.5 1.0"/> -->
  <!-- </material> -->
  <!-- <material name="eyewhite"> -->
  <!--     <color rgba="1.0 1.0 1.0 1.0"/> -->
  <!-- </material> -->
  <!-- <material name="orbita2dmetal"> -->
  <!--     <color rgba="0.85 0.85 0.85 1.0"/> -->
  <!-- </material> -->
  <!-- <material name="orbita2dgrey"> -->
  <!--     <color rgba="0.8 0.8 0.8 1.0"/> -->
  <!-- </material> -->
  <!-- <material name="orbita3d_yellow"> -->
  <!--     <color rgba="0.8 0.8 0.0 1"/> -->
  <!-- </material> -->
  <!-- <material name="orbita3d_grey"> -->
  <!--     <color rgba="0.8 0.8 0.8 1"/> -->
  <!-- </material> -->
  <!-- Zuuu mobile base -->
  <link name="drivewhl1_link">
    <!-- <visual>
          <origin xyz="0 0 0" rpy="${pi/2} 0 0"/>
          <geometry>
              <cylinder radius="${wheel_radius}" length="${wheel_width}"/>
              <box size="${wheel_radius} ${wheel_radius} ${wheel_width+0.02}"/>
          </geometry>
          <material name="Bricks"></material>
        </visual> -->
    <collision>
      <origin rpy="1.5707963267948966 0 0" xyz="0 0 0"/>
      <geometry>
        <cylinder length="0.035" radius="0.105"/>
      </geometry>
    </collision>
    <inertial>
      <origin rpy="1.5707963267948966 0 0" xyz="0 0 0"/>
      <mass value="0.5"/>
      <inertia ixx="0.0014291666666666665" ixy="0" ixz="0" iyy="0.0014291666666666665" iyz="0" izz="0.0027562499999999996"/>
    </inertial>
  </link>
  <!-- If use_fixed_wheels the wheels can't rotate, they will slide on the floor -->
  <joint name="drivewhl1_joint" type="fixed">
    <parent link="base_link"/>
    <child link="drivewhl1_link"/>
    <origin rpy="0 0 0.5235987755982989" xyz="0.09900000000000003 -0.17147302994931884 0.105"/>
    <axis xyz="0 1 0"/>
    <joint_properties damping="0.5" friction="0.1"/>
  </joint>
  <gazebo reference="drivewhl1_link">
    <mu1 value="0.1"/>
    <mu2 value="0.1"/>
    <kp value="10000000.0"/>
    <kd value="1.0"/>
    <fdir1 value="1 0 0"/>
    <maxVel>1.0</maxVel>
    <minDepth>0.0</minDepth>
    <turnGravityOff>false</turnGravityOff>
  </gazebo>
  <!-- Just so that we can see the wheels turn when they turn -->
  <link name="drivewhl1_extra_link">
    <!-- <visual>
          <origin xyz="0 0 0" rpy="${pi/2} 0 0"/>
          <geometry>
              <box size="${wheel_radius} ${wheel_radius} ${wheel_width+0.02}"/>
          </geometry>
        </visual> -->
  </link>
  <joint name="drivewhl1_extra_joint" type="fixed">
    <origin rpy="0 0 0" xyz="0 0 0"/>
    <axis xyz="0 0 0"/>
    <parent link="drivewhl1_link"/>
    <child link="drivewhl1_extra_link"/>
  </joint>
  <link name="drivewhl2_link">
    <!-- <visual>
          <origin xyz="0 0 0" rpy="${pi/2} 0 0"/>
          <geometry>
              <cylinder radius="${wheel_radius}" length="${wheel_width}"/>
              <box size="${wheel_radius} ${wheel_radius} ${wheel_width+0.02}"/>
          </geometry>
          <material name="Bricks"></material>
        </visual> -->
    <collision>
      <origin rpy="1.5707963267948966 0 0" xyz="0 0 0"/>
      <geometry>
        <cylinder length="0.035" radius="0.105"/>
      </geometry>
    </collision>
    <inertial>
      <origin rpy="1.5707963267948966 0 0" xyz="0 0 0"/>
      <mass value="0.5"/>
      <inertia ixx="0.0014291666666666665" ixy="0" ixz="0" iyy="0.0014291666666666665" iyz="0" izz="0.0027562499999999996"/>
    </inertial>
  </link>
  <!-- If use_fixed_wheels the wheels can't rotate, they will slide on the floor -->
  <joint name="drivewhl2_joint" type="fixed">
    <parent link="base_link"/>
    <child link="drivewhl2_link"/>
    <origin rpy="0 0 -3.6651914291880923" xyz="0.09900000000000003 0.17147302994931884 0.105"/>
    <axis xyz="0 1 0"/>
    <joint_properties damping="0.5" friction="0.1"/>
  </joint>
  <gazebo reference="drivewhl2_link">
    <mu1 value="0.1"/>
    <mu2 value="0.1"/>
    <kp value="10000000.0"/>
    <kd value="1.0"/>
    <fdir1 value="1 0 0"/>
    <maxVel>1.0</maxVel>
    <minDepth>0.0</minDepth>
    <turnGravityOff>false</turnGravityOff>
  </gazebo>
  <!-- Just so that we can see the wheels turn when they turn -->
  <link name="drivewhl2_extra_link">
    <!-- <visual>
          <origin xyz="0 0 0" rpy="${pi/2} 0 0"/>
          <geometry>
              <box size="${wheel_radius} ${wheel_radius} ${wheel_width+0.02}"/>
          </geometry>
        </visual> -->
  </link>
  <joint name="drivewhl2_extra_joint" type="fixed">
    <origin rpy="0 0 0" xyz="0 0 0"/>
    <axis xyz="0 0 0"/>
    <parent link="drivewhl2_link"/>
    <child link="drivewhl2_extra_link"/>
  </joint>
  <link name="drivewhl3_link">
    <!-- <visual>
          <origin xyz="0 0 0" rpy="${pi/2} 0 0"/>
          <geometry>
              <cylinder radius="${wheel_radius}" length="${wheel_width}"/>
              <box size="${wheel_radius} ${wheel_radius} ${wheel_width+0.02}"/>
          </geometry>
          <material name="Bricks"></material>
        </visual> -->
    <collision>
      <origin rpy="1.5707963267948966 0 0" xyz="0 0 0"/>
      <geometry>
        <cylinder length="0.035" radius="0.105"/>
      </geometry>
    </collision>
    <inertial>
      <origin rpy="1.5707963267948966 0 0" xyz="0 0 0"/>
      <mass value="0.5"/>
      <inertia ixx="0.0014291666666666665" ixy="0" ixz="0" iyy="0.0014291666666666665" iyz="0" izz="0.0027562499999999996"/>
    </inertial>
  </link>
  <!-- If use_fixed_wheels the wheels can't rotate, they will slide on the floor -->
  <joint name="drivewhl3_joint" type="fixed">
    <parent link="base_link"/>
    <child link="drivewhl3_link"/>
    <origin rpy="0 0 -1.5707963267948966" xyz="-0.198 -2.4248006623117595e-17 0.105"/>
    <axis xyz="0 1 0"/>
    <joint_properties damping="0.5" friction="0.1"/>
  </joint>
  <gazebo reference="drivewhl3_link">
    <mu1 value="0.1"/>
    <mu2 value="0.1"/>
    <kp value="10000000.0"/>
    <kd value="1.0"/>
    <fdir1 value="1 0 0"/>
    <maxVel>1.0</maxVel>
    <minDepth>0.0</minDepth>
    <turnGravityOff>false</turnGravityOff>
  </gazebo>
  <!-- Just so that we can see the wheels turn when they turn -->
  <link name="drivewhl3_extra_link">
    <!-- <visual>
          <origin xyz="0 0 0" rpy="${pi/2} 0 0"/>
          <geometry>
              <box size="${wheel_radius} ${wheel_radius} ${wheel_width+0.02}"/>
          </geometry>
        </visual> -->
  </link>
  <joint name="drivewhl3_extra_joint" type="fixed">
    <origin rpy="0 0 0" xyz="0 0 0"/>
    <axis xyz="0 0 0"/>
    <parent link="drivewhl3_link"/>
    <child link="drivewhl3_extra_link"/>
  </joint>
  <!-- <!-\- Robot Footprint. The robot's root link -\-> -->
  <!-- <link name="base_footprint">
        <xacro:cylinder_inertia m="0.01" r="0.01" h="0.01" />
    </link>

    <joint name="base_footprint_joint" type="fixed">
      <origin rpy="0 0 0" xyz="0 0 0"/>
      <axis xyz="0 0 ${(base_top_height-base_depth/2)}"/>
      <joint_properties damping="${global_damping}" friction="${global_friction}"/>
      <parent link="base_footprint"/>
      <child link="base_link"/>
    </joint> -->
  <link name="base_link">
    <visual>
      <origin rpy="0 0 0" xyz="0 0 0"/>
      <geometry>
        <mesh filename="obj_meshes/mobile_base_visual.obj"/>
      </geometry>
      <!-- <xacro:reachy_grey/> -->
    </visual>
    <!-- Real collision -->
    <collision>
      <origin rpy="0 0 0" xyz="0 0 0.145"/>
      <geometry>
        <cylinder length="0.19" radius="0.245"/>
      </geometry>
    </collision>
    <!-- exagerated collision to avoid the mobile base sliding on Gazebo -->
    <!-- <collision>
        <origin xyz="0 0 0.12" rpy="0 0 0"/>
        <geometry>
          <cylinder radius="0.245" length="0.24"/>
        </geometry>
      </collision> -->
    <inertial>
      <origin rpy="0 0 0" xyz="0.008 -0.00048 0.112"/>
      <mass value="24.0"/>
      <inertia ixx="0.40791094" ixy="-0.00167148" ixz="-0.00178789" iyx="-0.00167148" iyy="0.4236827" iyz="0.00026596" izx="-0.00178789" izy="0.00026596" izz="0.70990763"/>
    </inertial>
  </link>
  <link name="lidar_link">
    <inertial>
      <origin rpy="0 0 0" xyz="0 0 0"/>
      <mass value="0.125"/>
      <inertia ixx="0.001" ixy="0" ixz="0" iyy="0.001" iyz="0" izz="0.001"/>
    </inertial>
    <collision>
      <origin rpy="0 0 0" xyz="0 0 0"/>
      <geometry>
        <cylinder length="0.055" radius="0.0508"/>
      </geometry>
    </collision>
    <!-- <visual>
        <origin xyz="0 0 0" rpy="0 0 0"/>
        <geometry>
          <cylinder radius="0.0508" length="0.055"/>
        </geometry>
      </visual> -->
  </link>
  <joint name="lidar_joint" type="fixed">
    <parent link="base_link"/>
    <child link="lidar_link"/>
    <!-- <origin xyz="0.155 0 0.2" rpy="0 0 0"/> -->
    <!-- The -0.0129 were added on 22 April 2022 for the second version of Zuuu. The 2mm pads are
      not taken into account -->
    <!-- <origin xyz="0.155 0 ${-(base_top_height-base_depth/2)+base_top_height+0.105 -0.0129}" rpy="0 0 0" /> -->
    <origin rpy="0 0 3.141592653589793" xyz="0.184 0 0.25"/>
  </joint>
  <ros2_control name="zuuu_ros2_control" type="system">
    <hardware>
      <plugin>fake_components/GenericSystem</plugin>
      <!-- <xacro:if value="$(arg use_fake_components)"> -->
      <!-- <plugin>fake_components/GenericSystem</plugin> -->
      <!-- </xacro:if> -->
      <!-- <xacro:unless value="$(arg use_fake_components)"> -->
      <!-- <plugin>gazebo_ros2_control/GazeboSystem</plugin> -->
      <!-- </xacro:unless> -->
    </hardware>
    <joint name="drivewhl1_joint">
      <command_interface name="velocity">
        <param name="min">-1</param>
        <param name="max">1</param>
      </command_interface>
      <state_interface name="position"/>
      <state_interface name="velocity"/>
    </joint>
    <joint name="drivewhl2_joint">
      <command_interface name="velocity">
        <param name="min">-1</param>
        <param name="max">1</param>
      </command_interface>
      <state_interface name="position"/>
      <state_interface name="velocity"/>
    </joint>
    <joint name="drivewhl3_joint">
      <command_interface name="velocity">
        <param name="min">-1</param>
        <param name="max">1</param>
      </command_interface>
      <state_interface name="position"/>
      <state_interface name="velocity"/>
    </joint>
  </ros2_control>
  <!-- End of Zuuu mobile base -->
  <!-- config  -->
  <link name="back_bar_base">
    <visual>
      <origin rpy="0 0 0" xyz="0 0 0.2425"/>
      <geometry>
        <box size="0.04 0.04 0.485"/>
      </geometry>
      <material name="reachy_grey">
        <color rgba="0.8 0.8 0.8 1"/>
      </material>
    </visual>
    <collision>
      <origin rpy="0 0 0" xyz="0 0 0.2425"/>
      <geometry>
        <box size="0.05 0.05 0.485"/>
      </geometry>
    </collision>
    <inertial>
      <origin rpy="1.5707963267948966 0 1.5707963267948966" xyz="0 0 0"/>
      <mass value="0.759"/>
      <inertia ixx="0.00020240000000000001" ixy="0.0" ixz="0.0" iyy="0.00020240000000000001" iyz="0.0" izz="0.00020240000000000001"/>
    </inertial>
  </link>
  <joint name="back_bar_joint" type="fixed">
    <origin rpy="0 0 0" xyz="-0.09 0 0.241"/>
    <parent link="base_link"/>
    <child link="back_bar_base"/>
  </joint>
  <link name="back_bar_inner">
    <visual>
      <origin rpy="0 0 0" xyz="0 0 0.2425"/>
      <geometry>
        <box size="0.03 0.03 0.485"/>
      </geometry>
      <material name="reachy_grey">
        <color rgba="0.8 0.8 0.8 1"/>
      </material>
    </visual>
    <collision>
      <origin rpy="0 0 0" xyz="0 0 0.2425"/>
      <geometry>
        <box size="0.05 0.05 0.485"/>
      </geometry>
    </collision>
    <inertial>
      <origin rpy="1.5707963267948966 0 1.5707963267948966" xyz="0 0 0"/>
      <mass value="0.759"/>
      <inertia ixx="0.00020240000000000001" ixy="0.0" ixz="0.0" iyy="0.00020240000000000001" iyz="0.0" izz="0.00020240000000000001"/>
    </inertial>
  </link>
  <joint name="tripod_joint" type="prismatic">
    <origin rpy="0 0 0" xyz="0 0 0.035"/>
    <parent link="back_bar_base"/>
    <child link="back_bar_inner"/>
    <limit effort="1.0" lower="0.0" upper="0.210" velocity="0.1"/>
    <axis xyz="0 0 1"/>
    <dynamics damping="0.01" friction="0.1"/>
  </joint>
  <link name="left_bar_base">
    <visual>
      <origin rpy="0 0 0" xyz="0 0 -0.2425"/>
      <!-- <origin xyz="0 0 0" rpy="0 0 0" /> -->
      <geometry>
        <box size="0.04 0.04 0.485"/>
      </geometry>
      <material name="reachy_grey">
        <color rgba="0.8 0.8 0.8 1"/>
      </material>
    </visual>
    <collision>
      <origin rpy="0 0 0" xyz="0 0 -0.2425"/>
      <geometry>
        <box size="0.05 0.05 0.485"/>
      </geometry>
    </collision>
    <inertial>
      <origin rpy="1.5707963267948966 0 1.5707963267948966" xyz="0 0 0"/>
      <mass value="1.759"/>
      <inertia ixx="0.0004690666666666666" ixy="0.0" ixz="0.0" iyy="0.0004690666666666666" iyz="0.0" izz="0.0004690666666666666"/>
    </inertial>
  </link>
  <link name="left_bar_anchor">
    <visual>
      <origin rpy="0 0 0.19088666029061982" xyz="0 0 0.015"/>
      <geometry>
        <box size="0.03 0.03 0.03"/>
      </geometry>
      <material name="reachy_grey">
        <color rgba="0.8 0.8 0.8 1"/>
      </material>
    </visual>
    <collision>
      <origin rpy="0 0 0.19088666029061982" xyz="0 0 0.015"/>
      <geometry>
        <box size="0.03 0.03 0.03"/>
      </geometry>
    </collision>
    <inertial>
      <origin rpy="1.5707963267948966 0 1.5707963267948966" xyz="0 0 0"/>
      <mass value="1.759"/>
      <inertia ixx="0.00026384999999999994" ixy="0.0" ixz="0.0" iyy="0.00026384999999999994" iyz="0.0" izz="0.00026384999999999994"/>
    </inertial>
  </link>
  <joint name="left_bar_anchor_to_base" type="fixed">
    <origin rpy="0 0 0" xyz="0.084 0.066 0.241"/>
    <parent link="base_link"/>
    <child link="left_bar_anchor"/>
  </joint>
  <joint name="left_bar_joint_mimic" type="revolute">
    <origin rpy="0 0 0.19088666029061982" xyz="0 0.048 -0.258"/>
    <parent link="torso"/>
    <child link="left_bar_inner"/>
    <limit effort="0.01" lower="-1.0" upper="1.0" velocity="0.01"/>
    <axis xyz="0 1 0"/>
    <mimic joint="tripod_joint" multiplier="0.2864183599287582" offset="-0.1967146343049915"/>
    <!-- <mimic joint="tripod_joint" multiplier="0" offset="0" /> -->
    <dynamics damping="0.01" friction="0.1"/>
  </joint>
  <link name="left_bar_inner">
    <visual>
      <origin rpy="0 0 0" xyz="0 0 -0.2425"/>
      <geometry>
        <box size="0.03 0.03 0.485"/>
      </geometry>
      <material name="reachy_grey">
        <color rgba="0.8 0.8 0.8 1"/>
      </material>
    </visual>
    <collision>
      <origin rpy="0 0 0" xyz="0 0 -0.2425"/>
      <geometry>
        <box size="0.05 0.05 0.485"/>
      </geometry>
    </collision>
    <inertial>
      <origin rpy="1.5707963267948966 0 1.5707963267948966" xyz="0 0 0"/>
      <mass value="0.759"/>
      <inertia ixx="0.00020240000000000001" ixy="0.0" ixz="0.0" iyy="0.00020240000000000001" iyz="0.0" izz="0.00020240000000000001"/>
    </inertial>
  </link>
  <joint name="left_bar_prism_joint_mimic" type="prismatic">
    <origin rpy="0 0 0" xyz="0 0 -0.485"/>
    <parent link="left_bar_inner"/>
    <child link="left_bar_base"/>
    <limit effort="1.0" lower="-1.0" upper="1.0" velocity="0.5"/>
    <axis xyz="0 0 1"/>
    <mimic joint="tripod_joint" multiplier="-0.9861535348976198" offset="0.4814718126556904"/>
    <dynamics damping="0.01" friction="0.1"/>
  </joint>
  <!-- right bar -->
  <link name="right_bar_base">
    <visual>
      <origin rpy="0 0 0" xyz="0 0 -0.2425"/>
      <!-- <origin xyz="0 0 0" rpy="0 0 0" /> -->
      <geometry>
        <box size="0.04 0.04 0.485"/>
      </geometry>
      <material name="reachy_grey">
        <color rgba="0.8 0.8 0.8 1"/>
      </material>
    </visual>
    <collision>
      <origin rpy="0 0 0" xyz="0 0 -0.2425"/>
      <geometry>
        <box size="0.05 0.05 0.485"/>
      </geometry>
    </collision>
    <inertial>
      <origin rpy="1.5707963267948966 0 1.5707963267948966" xyz="0 0 0"/>
      <mass value="1.759"/>
      <inertia ixx="0.0004690666666666666" ixy="0.0" ixz="0.0" iyy="0.0004690666666666666" iyz="0.0" izz="0.0004690666666666666"/>
    </inertial>
  </link>
  <link name="right_bar_anchor">
    <visual>
      <origin rpy="0 0 -0.19088666029061982" xyz="0 0 0.015"/>
      <geometry>
        <box size="0.03 0.03 0.03"/>
      </geometry>
      <material name="reachy_grey">
        <color rgba="0.8 0.8 0.8 1"/>
      </material>
    </visual>
    <collision>
      <origin rpy="0 0 -0.19088666029061982" xyz="0 0 0.015"/>
      <geometry>
        <box size="0.03 0.03 0.03"/>
      </geometry>
    </collision>
    <inertial>
      <origin rpy="1.5707963267948966 0 1.5707963267948966" xyz="0 0 0"/>
      <mass value="1.759"/>
      <inertia ixx="0.00026384999999999994" ixy="0.0" ixz="0.0" iyy="0.00026384999999999994" iyz="0.0" izz="0.00026384999999999994"/>
    </inertial>
  </link>
  <joint name="right_bar_anchor_to_base" type="fixed">
    <origin rpy="0 0 0" xyz="0.084 -0.066 0.241"/>
    <parent link="base_link"/>
    <child link="right_bar_anchor"/>
  </joint>
  <joint name="right_bar_joint_mimic" type="revolute">
    <origin rpy="0 0 -0.19088666029061982" xyz="0 -0.048 -0.258"/>
    <parent link="torso"/>
    <child link="right_bar_inner"/>
    <limit effort="0.01" lower="-1.0" upper="1.0" velocity="0.01"/>
    <axis xyz="0 1 0"/>
    <mimic joint="tripod_joint" multiplier="0.2864183599287582" offset="-0.1967146343049915"/>
    <!-- <mimic joint="tripod_joint" multiplier="0" offset="0" /> -->
    <dynamics damping="0.01" friction="0.1"/>
  </joint>
  <link name="right_bar_inner">
    <visual>
      <origin rpy="0 0 0" xyz="0 0 -0.2425"/>
      <geometry>
        <box size="0.03 0.03 0.485"/>
      </geometry>
      <material name="reachy_grey">
        <color rgba="0.8 0.8 0.8 1"/>
      </material>
    </visual>
    <collision>
      <origin rpy="0 0 0" xyz="0 0 -0.2425"/>
      <geometry>
        <box size="0.05 0.05 0.485"/>
      </geometry>
    </collision>
    <inertial>
      <origin rpy="1.5707963267948966 0 1.5707963267948966" xyz="0 0 0"/>
      <mass value="0.759"/>
      <inertia ixx="0.00020240000000000001" ixy="0.0" ixz="0.0" iyy="0.00020240000000000001" iyz="0.0" izz="0.00020240000000000001"/>
    </inertial>
  </link>
  <joint name="right_bar_prism_joint_mimic" type="prismatic">
    <origin rpy="0 0 0" xyz="0 0 -0.485"/>
    <parent link="right_bar_inner"/>
    <child link="right_bar_base"/>
    <limit effort="1.0" lower="-1.0" upper="1.0" velocity="0.5"/>
    <axis xyz="0 0 1"/>
    <mimic joint="tripod_joint" multiplier="-0.9861535348976198" offset="0.4814718126556904"/>
    <dynamics damping="0.01" friction="0.1"/>
  </joint>
  <ros2_control name="tripod" type="system">
    <hardware>
      <plugin>fake_components/GenericSystem</plugin>
    </hardware>
    <joint name="tripod_joint">
      <state_interface name="position">
        <param name="initial_value">0.0</param>
      </state_interface>
      <state_interface name="velocity">
        <param name="initial_value">0.0</param>
      </state_interface>
      <state_interface name="effort">
        <param name="initial_value">0.0</param>
      </state_interface>
      <!-- <command_interface name="position"> -->
      <!--   <param name="min">0.0</param> -->
      <!--   <param name="max">0.21</param> -->
      <!-- </command_interface> -->
      <command_interface name="position"/>
    </joint>
  </ros2_control>
  <!-- TORSO -->
  <link name="torso">
    <visual>
      <origin rpy="0 0 0" xyz="0 0 0 "/>
      <geometry>
        <!-- <mesh filename="file://$(find reachy_description)/meshes/torso_visual_high.obj" /> -->
        <mesh filename="obj_meshes/torso_visual.obj"/>
      </geometry>
    </visual>
    <inertial>
      <!-- <origin xyz="-0.098614 -0.000471 -0.018363" rpy="0 0 0"/> -->
      <origin rpy="0 0 0" xyz="-0.051614 -0.000471 -0.018363"/>
      <mass value="6.314"/>
      <inertia ixx="0.07397673" ixy="-4.624e-4" ixz="-0.00175905" iyx="-0.00046237" iyy="0.04454533" iyz="0.00008675" izx="-0.00175905" izy="0.00008675" izz="0.05494939"/>
    </inertial>
    <collision>
      <origin rpy="0 0 0" xyz="0 0 0 "/>
      <geometry>
        <!-- <mesh filename="file://$(find reachy_description)/meshes/torso_collider_no_cone.obj" /> -->
        <mesh filename="obj_meshes/torso_collider.obj"/>
      </geometry>
    </collision>
  </link>
  <joint name="torso_base" type="fixed">
    <!-- <origin xyz="0.08 0 ${0.235 + back_bar_length}" rpy="0 0 0" /> -->
    <origin rpy="0 0 0" xyz="0.08 0 0.72"/>
    <parent link="back_bar_inner"/>
    <child link="torso"/>
  </joint>
  <!-- <joint name="torso_base" type="fixed"> -->
  <!--   <origin xyz="0.08 0 1.0" rpy="0 0 0" /> -->
  <!--   <parent link="base_link" /> -->
  <!--   <child link="torso" /> -->
  <!-- </joint> -->
  <!-- <link name="logo"> -->
  <!--   <inertial> -->
  <!--     <origin xyz="0.0 0.0 0.0" rpy="0.0 0.0 0.0" /> -->
  <!--     <mass value="0.001" /> -->
  <!--     <inertia ixx="1.0e-6" ixy="1.0e-8" ixz="1.0e-8" iyy="1.0e-6" iyz="1.0e-8" izz="1.0e-6" /> -->
  <!--   </inertial> -->
  <!-- </link> -->
  <!-- <joint name="logo_joint" type="fixed"> -->
  <!--   <origin xyz="0.047 0 0.0" rpy="0 0 0" /> -->
  <!--   <parent link="torso" /> -->
  <!--   <child link="logo" /> -->
  <!-- </joint> -->
  <!-- <gazebo reference="torso"> -->
  <!--   <!-\- <material>Gazebo/Black</material> -\-> -->
  <!--   <static>true</static> -->
  <!-- </gazebo> -->
  <!--
      Orbita3d

    link                         (joint)

    ${parent}                    (${name}_base_joint) fixed
      ${name}_base_link          (${name}_roll) revolute
        ${name}_dummy_link1      (${name}_pitch) revolute
          ${name}_dummy_link2    (${name}_yaw) revolute
            ${name}_link         (${name}_ball_joint) fixed
              ${name}_ball_link
    -->
  <link name="neck_dummy_link1">
    <inertial>
      <mass value="0.005"/>
      <origin rpy="0 0 0" xyz="0 0 0"/>
      <inertia ixx="2.5416666666666668e-06" ixy="0.0" ixz="0.0" iyy="2.5416666666666668e-06" iyz="0.0" izz="3e-06"/>
    </inertial>
  </link>
  <link name="neck_dummy_link2">
    <inertial>
      <mass value="0.005"/>
      <origin rpy="0 0 0" xyz="0 0 0"/>
      <inertia ixx="2.5416666666666668e-06" ixy="0.0" ixz="0.0" iyy="2.5416666666666668e-06" iyz="0.0" izz="3e-06"/>
    </inertial>
  </link>
  <link name="neck_link">
    <!-- <visual> -->
    <!-- 	<origin xyz="0 0 0" rpy="0 0 0"/> -->
    <!-- 	<geometry> -->
    <!--     <cylinder length="${length}" radius="${radius}"/> -->
    <!-- 	</geometry> -->
    <!-- 	<xacro:orbita3d_grey/> -->
    <!-- </visual> -->
    <!-- <collision> -->
    <!-- 	<origin xyz="0 0 ${length/2}" rpy="0 0 0"/> -->
    <!-- 	<geometry> -->
    <!--     <cylinder length="${length}" radius="${radius}"/> -->
    <!-- 	</geometry> -->
    <!-- </collision> -->
    <inertial>
      <mass value="0.49"/>
      <origin rpy="0 0 0" xyz="0 0 -0.025"/>
      <inertia ixx="0.00024908333333333336" ixy="0.0" ixz="0.0" iyy="0.00024908333333333336" iyz="0.0" izz="0.000294"/>
    </inertial>
  </link>
  <link name="neck_ball_link">
    <!-- <visual> -->
    <!-- 	<origin xyz="0 0 0" rpy="0 0 0"/> -->
    <!-- 	<geometry> -->
    <!--     <sphere radius="${radius*1.2}"/> -->
    <!-- 	</geometry> -->
    <!-- 	<xacro:orbita3d_grey/> -->
    <!-- </visual> -->
    <!-- <collision> -->
    <!-- 	<origin xyz="0 0 0" rpy="0 0 0"/> -->
    <!-- 	<geometry> -->
    <!--     <sphere radius="${radius*1.2}"/> -->
    <!-- 	</geometry> -->
    <!-- </collision> -->
    <!-- <xacro:inertial_sphere mass="${mass*0.5}" diameter="${2*radius*1.2}"/> -->
    <inertial>
      <origin rpy="0.0 0.0 0.0" xyz="0.0 0.0 0.0"/>
      <mass value="0.001"/>
      <inertia ixx="1.0e-6" ixy="1.0e-8" ixz="1.0e-8" iyy="1.0e-6" iyz="1.0e-8" izz="1.0e-6"/>
    </inertial>
  </link>
  <joint name="neck_ball_joint" type="fixed">
    <origin rpy="0 0 0" xyz="0 0 0"/>
    <parent link="neck_link"/>
    <child link="neck_ball_link"/>
  </joint>
  <link name="neck_base_link">
    <!-- <visual> -->
    <!-- 	<origin xyz="0 0 0.0672" rpy="0 0 0"/> -->
    <!-- 	<geometry> -->
    <!--     <cylinder radius="0.0278" length="0.0336"/> -->
    <!-- 	</geometry> -->
    <!-- 	<xacro:orbita3d_grey/> -->
    <!-- </visual> -->
    <inertial>
      <origin rpy="0.0 0.0 0.0" xyz="0.0 0.0 0.0"/>
      <mass value="0.001"/>
      <inertia ixx="1.0e-6" ixy="1.0e-8" ixz="1.0e-8" iyy="1.0e-6" iyz="1.0e-8" izz="1.0e-6"/>
    </inertial>
  </link>
  <joint name="neck_base_joint" type="fixed">
    <origin rpy="0 0.17453292519943295 0.0" xyz="0.0 0 0.115"/>
    <parent link="torso"/>
    <child link="neck_base_link"/>
  </joint>
  <link name="neck_out_link">
    <inertial>
      <origin rpy="0.0 0.0 0.0" xyz="0.0 0.0 0.0"/>
      <mass value="0.001"/>
      <inertia ixx="1.0e-6" ixy="1.0e-8" ixz="1.0e-8" iyy="1.0e-6" iyz="1.0e-8" izz="1.0e-6"/>
    </inertial>
  </link>
  <joint name="neck_out_joint" type="fixed">
    <!-- <origin xyz="0 0 0" rpy="3.141592 0 0"/> -->
    <origin rpy="0 0 0" xyz="0 0 0"/>
    <parent link="neck_ball_link"/>
    <child link="neck_out_link"/>
  </joint>
  <joint name="neck_roll" type="revolute">
    <!-- <origin xyz="${xyz}" rpy="${rpy}"/> -->
    <origin rpy="0 0 0" xyz="0 0 0"/>
    <!-- <parent link="${parent}"/> -->
    <parent link="neck_base_link"/>
    <child link="neck_dummy_link1"/>
    <axis xyz="1 0 0"/>
    <limit effort="1000.0" lower="-0.35" upper="0.35" velocity="100.0"/>
    <dynamics damping="0.01" friction="0.1"/>
  </joint>
  <joint name="neck_pitch" type="revolute">
    <origin rpy="0 0 0" xyz="0 0 0"/>
    <parent link="neck_dummy_link1"/>
    <child link="neck_dummy_link2"/>
    <axis xyz="0 1 0"/>
    <limit effort="1000.0" lower="-0.35" upper="0.35" velocity="100.0"/>
    <dynamics damping="0.01" friction="0.1"/>
  </joint>
  <joint name="neck_yaw" type="revolute">
    <origin rpy="0 0 0" xyz="0 0 0"/>
    <parent link="neck_dummy_link2"/>
    <child link="neck_link"/>
    <axis xyz="0 0 1"/>
    <limit effort="1000.0" lower="-1.57" upper="1.57" velocity="100.0"/>
    <dynamics damping="0.01" friction="0.1"/>
  </joint>
  <ros2_control name="neck" type="system">
    <hardware>
      <!-- Standard ROS fake system -->
      <!-- <plugin>fake_components/GenericSystem</plugin> -->
      <!-- Pollen controller fake system -->
      <plugin>orbita3d_system_hwi/Orbita3dSystem</plugin>
      <param name="config_file">/home/reachy/reachy_ws/install/orbita3d_description/share/orbita3d_description/config/fake_neck.yaml</param>
    </hardware>
    <gpio name="neck">
      <state_interface name="torque">
        <param name="initial_value">0.0</param>
      </state_interface>
      <state_interface name="errors"/>
      <command_interface name="torque"/>
    </gpio>
    <joint name="neck_roll">
      <state_interface name="position">
        <param name="initial_value">0.0</param>
      </state_interface>
      <state_interface name="velocity">
        <param name="initial_value">0.0</param>
      </state_interface>
      <state_interface name="effort">
        <param name="initial_value">0.0</param>
      </state_interface>
      <command_interface name="position"/>
    </joint>
    <joint name="neck_pitch">
      <state_interface name="position">
        <param name="initial_value">0.0</param>
      </state_interface>
      <state_interface name="velocity">
        <param name="initial_value">0.0</param>
      </state_interface>
      <state_interface name="effort">
        <param name="initial_value">0.0</param>
      </state_interface>
      <command_interface name="position"/>
    </joint>
    <joint name="neck_yaw">
      <state_interface name="position">
        <param name="initial_value">0.0</param>
      </state_interface>
      <state_interface name="velocity">
        <param name="initial_value">0.0</param>
      </state_interface>
      <state_interface name="effort">
        <param name="initial_value">0.0</param>
      </state_interface>
      <command_interface name="position"/>
    </joint>
    <gpio name="neck_raw_motor_1">
      <state_interface name="speed_limit"/>
      <command_interface name="speed_limit"/>
      <state_interface name="torque_limit"/>
      <command_interface name="torque_limit"/>
      <state_interface name="p_gain"/>
      <command_interface name="p_gain"/>
      <state_interface name="i_gain"/>
      <command_interface name="i_gain"/>
      <state_interface name="d_gain"/>
      <command_interface name="d_gain"/>
      <state_interface name="motor_temperature"/>
      <state_interface name="board_temperature"/>
      <state_interface name="motor_currents"/>
      <state_interface name="motor_velocities"/>
    </gpio>
    <gpio name="neck_raw_motor_2">
      <state_interface name="speed_limit"/>
      <command_interface name="speed_limit"/>
      <state_interface name="torque_limit"/>
      <command_interface name="torque_limit"/>
      <state_interface name="p_gain"/>
      <command_interface name="p_gain"/>
      <state_interface name="i_gain"/>
      <command_interface name="i_gain"/>
      <state_interface name="d_gain"/>
      <command_interface name="d_gain"/>
      <state_interface name="motor_temperature"/>
      <state_interface name="board_temperature"/>
      <state_interface name="motor_currents"/>
      <state_interface name="motor_velocities"/>
    </gpio>
    <gpio name="neck_raw_motor_3">
      <state_interface name="speed_limit"/>
      <command_interface name="speed_limit"/>
      <state_interface name="torque_limit"/>
      <command_interface name="torque_limit"/>
      <state_interface name="p_gain"/>
      <command_interface name="p_gain"/>
      <state_interface name="i_gain"/>
      <command_interface name="i_gain"/>
      <state_interface name="d_gain"/>
      <command_interface name="d_gain"/>
      <state_interface name="motor_temperature"/>
      <state_interface name="board_temperature"/>
      <state_interface name="motor_currents"/>
      <state_interface name="motor_velocities"/>
    </gpio>
  </ros2_control>
  <joint name="neck_fixed" type="fixed">
    <origin rpy="0.0 0.0 0.0" xyz="0 0 0"/>
    <parent link="neck_out_link"/>
    <child link="head"/>
  </joint>
  <!-- Head Links -->
  <link name="head">
    <inertial>
      <origin rpy="0.0 0.0 0.0" xyz="0.0116978 -0.00022144 0.0611705"/>
      <mass value="0.325"/>
      <inertia ixx="0.00085265" ixy="-0.00000298" ixz="0.00000932" iyx="-0.00000298" iyy="0.00063136" iyz="-0.000000039" izx="0.00000932" izy="-0.000000039" izz="0.0008951"/>
    </inertial>
    <visual>
      <origin rpy="0.0 0.0 0.0" xyz="0.00 0.0 0.0"/>
      <geometry>
        <mesh filename="obj_meshes/head_visual.obj"/>
        <!-- <mesh filename="file://$(find reachy_description)/meshes/head_visual_high.obj"/> -->
      </geometry>
    </visual>
    <collision>
      <!-- <origin xyz="0.0 0.0 0.05" rpy="0.0 0.0 0.0"/> -->
      <origin rpy="0.0 0.0 0.0" xyz="0.0 0.0 0.0"/>
      <geometry>
        <!-- <box size="0.12 0.162 0.1"/> -->
        <mesh filename="obj_meshes/head_collider.obj"/>
      </geometry>
    </collision>
  </link>
  <link name="head_base">
    <inertial>
      <origin rpy="0.0 0.0 0.0" xyz="0.0 0.0 0.0"/>
      <mass value="0.001"/>
      <inertia ixx="1.0e-6" ixy="1.0e-8" ixz="1.0e-8" iyy="1.0e-6" iyz="1.0e-8" izz="1.0e-6"/>
    </inertial>
  </link>
  <joint name="head_base_fixed" type="fixed">
    <origin rpy="0.0 0.0 0" xyz="0.0 0 0.0"/>
    <parent link="head"/>
    <child link="head_base"/>
  </joint>
  <!-- <link name="head_tracker"> -->
  <!--   <visual name=""> -->
  <!--     <origin xyz="0 0 0" rpy="0.0 0.0 0.0"/> -->
  <!--     <geometry> -->
  <!-- 	  <cylinder length="0.04" radius="0.04"/> -->
  <!--     </geometry> -->
  <!-- 	<material name="camblack"/> -->
  <!--   </visual> -->
  <!-- </link> -->
  <!-- <joint name="head_tracker_fixed" type="fixed"> -->
  <!--   <origin xyz="-0.030 0.0 0.111" rpy="0.0 0.0 0"/> -->
  <!--   <parent link="head" /> -->
  <!--   <child link="head_tracker" /> -->
  <!-- </joint> -->
  <link name="head_tip">
    <inertial>
      <origin rpy="0.0 0.0 0.0" xyz="0.0 0.0 0.0"/>
      <mass value="0.001"/>
      <inertia ixx="1.0e-6" ixy="1.0e-8" ixz="1.0e-8" iyy="1.0e-6" iyz="1.0e-8" izz="1.0e-6"/>
    </inertial>
  </link>
  <joint name="head_tip_fixed" type="fixed">
    <!-- between the cameras -->
    <origin rpy="0 0.0 0" xyz="0.05643 0.0 0.062"/>
    <!-- Rotation center -->
    <!-- <origin xyz="0.0 0 0.0" rpy="0.0 0.0 0"/> -->
    <parent link="head"/>
    <child link="head_tip"/>
  </joint>
  <!-- test antennas -->
  <link name="antenna_left_link">
    <inertial>
      <origin rpy="0.0 0.0 0.0" xyz="0.0 0.0 0.0"/>
      <mass value="0.001"/>
      <inertia ixx="1.0e-6" ixy="1.0e-8" ixz="1.0e-8" iyy="1.0e-6" iyz="1.0e-8" izz="1.0e-6"/>
    </inertial>
    <!-- cylinder geometry -->
    <visual>
      <origin rpy="0 0 0" xyz="0 0 0"/>
      <geometry>
        <!-- <cylinder length="0.1" radius="0.005"/> -->
        <mesh filename="obj_meshes/head_antenna_visual.obj"/>
      </geometry>
      <material name="neckwhite"/>
    </visual>
  </link>
  <!-- revolute joint -->
  <joint name="antenna_left" type="revolute">
    <!-- <origin xyz="-0.023 0.055 0.091" rpy="${radians(145-90)} 0.0 ${radians(32)}"/> -->
    <!-- <origin xyz="-0.023 0.055 0.091" rpy="${radians(32)} ${radians(-55)} ${radians(-90)}"/> -->
    <!-- Horrible... -->
    <origin rpy="0.07374016089676041 -1.061282358260192 -1.0035643198967394" xyz="-0.023 0.055 0.091"/>
    <parent link="head"/>
    <child link="antenna_left_link"/>
    <axis xyz="0 0 1"/>
    <limit effort="0.0" lower="-1.5707963267948966" upper="1.5707963267948966" velocity="0.0"/>
  </joint>
  <link name="antenna_right_link">
    <inertial>
      <origin rpy="0.0 0.0 0.0" xyz="0.0 0.0 0.0"/>
      <mass value="0.001"/>
      <inertia ixx="1.0e-6" ixy="1.0e-8" ixz="1.0e-8" iyy="1.0e-6" iyz="1.0e-8" izz="1.0e-6"/>
    </inertial>
    <!-- cylinder geometry -->
    <visual>
      <origin rpy="0 0 0" xyz="0 0 0"/>
      <geometry>
        <!-- <cylinder length="0.1" radius="0.005"/> -->
        <mesh filename="obj_meshes/head_antenna_visual.obj"/>
      </geometry>
      <material name="neckwhite"/>
    </visual>
  </link>
  <!-- revolute joint -->
  <joint name="antenna_right" type="revolute">
    <!-- <origin xyz="0.0 -0.1 0.1" rpy="0 0.0 0"/> -->
    <origin rpy="-0.07374016089676041 -1.061282358260192 1.0035643198967394" xyz="-0.023 -0.055 0.091"/>
    <parent link="head"/>
    <child link="antenna_right_link"/>
    <axis xyz="0 0 1"/>
    <limit effort="0.0" lower="-1.5707963267948966" upper="1.5707963267948966" velocity="0.0"/>
  </joint>
  <ros2_control name="antenna" type="system">
    <hardware>
      <!-- <plugin>fake_components/GenericSystem</plugin> -->
      <!-- test -->
      <plugin>dynamixel_2joints_system_hwi/DynamixelSystem</plugin>
      <param name="dxl_config_file">/home/reachy/reachy_ws/install/dynamixel_description/share/dynamixel_description/config/two_fake.yaml</param>
    </hardware>
    <gpio name="antenna_left">
      <state_interface name="torque">
        <param name="initial_value">0.0</param>
      </state_interface>
      <command_interface name="torque"/>
    </gpio>
    <gpio name="antenna_right">
      <state_interface name="torque">
        <param name="initial_value">0.0</param>
      </state_interface>
      <command_interface name="torque"/>
    </gpio>
    <joint name="antenna_left">
      <state_interface name="position">
        <param name="initial_value">0.0</param>
      </state_interface>
      <state_interface name="velocity">
        <param name="initial_value">0.0</param>
      </state_interface>
      <state_interface name="effort">
        <param name="initial_value">0.0</param>
      </state_interface>
      <command_interface name="position"/>
    </joint>
    <joint name="antenna_right">
      <state_interface name="position">
        <param name="initial_value">0.0</param>
      </state_interface>
      <state_interface name="velocity">
        <param name="initial_value">0.0</param>
      </state_interface>
      <state_interface name="effort">
        <param name="initial_value">0.0</param>
      </state_interface>
      <command_interface name="position"/>
    </joint>
    <gpio name="antenna_left_raw_motor">
      <state_interface name="speed_limit"/>
      <command_interface name="speed_limit"/>
      <state_interface name="torque_limit"/>
      <command_interface name="torque_limit"/>
      <state_interface name="temperature"/>
      <state_interface name="mode"/>
      <command_interface name="mode"/>
      <state_interface name="p_gain"/>
      <command_interface name="p_gain"/>
      <state_interface name="i_gain"/>
      <command_interface name="i_gain"/>
      <state_interface name="d_gain"/>
      <command_interface name="d_gain"/>
      <state_interface name="current"/>
      <command_interface name="current"/>
    </gpio>
    <gpio name="antenna_right_raw_motor">
      <state_interface name="speed_limit"/>
      <command_interface name="speed_limit"/>
      <state_interface name="torque_limit"/>
      <command_interface name="torque_limit"/>
      <state_interface name="temperature"/>
      <state_interface name="mode"/>
      <command_interface name="mode"/>
      <state_interface name="p_gain"/>
      <command_interface name="p_gain"/>
      <state_interface name="i_gain"/>
      <command_interface name="i_gain"/>
      <state_interface name="d_gain"/>
      <command_interface name="d_gain"/>
      <state_interface name="current"/>
      <command_interface name="current"/>
    </gpio>
  </ros2_control>
  <!-- Reachy Cameras -->
  <joint name="left_cam_fixed" type="fixed">
    <origin rpy="0.0 0.0  -0.0" xyz="0.03531 0.0325 0.062"/>
    <parent link="head"/>
    <child link="left_camera"/>
  </joint>
  <link name="left_camera">
    <inertial>
      <mass value="1e-5"/>
      <origin rpy="0 0 0" xyz="0 0 0"/>
      <inertia ixx="1e-6" ixy="0" ixz="0" iyy="1e-6" iyz="0" izz="1e-6"/>
    </inertial>
  </link>
  <link name="left_camera_optical">
    <inertial>
      <origin rpy="0.0 0.0 0.0" xyz="0.0 0.0 0.0"/>
      <mass value="0.001"/>
      <inertia ixx="1.0e-6" ixy="1.0e-8" ixz="1.0e-8" iyy="1.0e-6" iyz="1.0e-8" izz="1.0e-6"/>
    </inertial>
  </link>
  <joint name="left_camera_optical_joint" type="fixed">
    <!-- these values have to be these values otherwise the gazebo camera
             image won't be aligned properly with the frame it is supposedly
             originating from -->
    <origin rpy="-1.5707963267948966 0 -1.5707963267948966" xyz="0 0 0"/>
    <parent link="left_camera"/>
    <child link="left_camera_optical"/>
  </joint>
  <joint name="right_cam_fixed" type="fixed">
    <origin rpy="0.0 0.0 0.0" xyz="0.03531 -0.0325 0.062"/>
    <parent link="head"/>
    <child link="right_camera"/>
  </joint>
  <link name="right_camera">
    <inertial>
      <mass value="1e-5"/>
      <origin rpy="0 0 0" xyz="0 0 0"/>
      <inertia ixx="1e-6" ixy="0" ixz="0" iyy="1e-6" iyz="0" izz="1e-6"/>
    </inertial>
  </link>
  <link name="right_camera_optical">
      </link>
  <joint name="right_camera_optical_joint" type="fixed">
    <!-- these values have to be these values otherwise the gazebo camera
             image won't be aligned properly with the frame it is supposedly
             originating from -->
    <origin rpy="-1.5707963267948966 0 -1.5707963267948966" xyz="0 0 0"/>
    <!-- <origin xyz="0.03531 -0.0325 0.056" rpy="${-pi/2.0} 0 ${-pi/2.0}"/> -->
    <parent link="right_camera"/>
    <child link="right_camera_optical"/>
  </joint>
  <joint name="tof_cam_fixed" type="fixed">
    <origin rpy="0.0 0.0 0" xyz="0.05643 0 0.061954"/>
    <parent link="head"/>
    <child link="tof_camera"/>
  </joint>
  <link name="tof_camera">
    <inertial>
      <mass value="1e-5"/>
      <origin rpy="0 0 0" xyz="0 0 0"/>
      <inertia ixx="1e-6" ixy="0" ixz="0" iyy="1e-6" iyz="0" izz="1e-6"/>
    </inertial>
  </link>
  <link name="tof_camera_optical">
      </link>
  <joint name="tof_camera_optical_joint" type="fixed">
    <!-- these values have to be these values otherwise the gazebo camera
             image won't be aligned properly with the frame it is supposedly
             originating from -->
    <origin rpy="-1.5707963267948966 0 -1.5707963267948966" xyz="0 0 0"/>
    <!-- <origin xyz="0.03531 -0.0325 0.056" rpy="${-pi/2.0} 0 ${-pi/2.0}"/> -->
    <parent link="tof_camera"/>
    <child link="tof_camera_optical"/>
  </joint>
  <!-- RIGHT ARM -->
  <!-- URDF definition is so stupid we have to do that... -->
  <!-- <material name="gripperblack"> -->
  <!--     <color rgba="0.4 0.4 0.4 1"/> -->
  <!-- </material> -->
  <!-- <material name="gripperwhite"> -->
  <!--     <color rgba="0.9 0.9 0.9 1"/> -->
  <!-- </material> -->
  <!-- <material name="reachy_yellow"> -->
  <!--     <color rgba="0.8 0.8 0.0 1"/> -->
  <!-- </material> -->
  <!-- <material name="reachy_grey"> -->
  <!--     <color rgba="0.8 0.8 0.8 1"/> -->
  <!-- </material> -->
  <!-- <material name="reachy_metal"> -->
  <!--     <color rgba="0.85 0.85 0.85 1.0"/> -->
  <!-- </material> -->
  <!-- <material name="torsoblack"> -->
  <!--     <color rgba="0.5 0.5 0.5 1.0"/> -->
  <!-- </material> -->
  <!-- <material name="eyewhite"> -->
  <!--     <color rgba="1.0 1.0 1.0 1.0"/> -->
  <!-- </material> -->
  <!-- <material name="orbita2dmetal"> -->
  <!--     <color rgba="0.85 0.85 0.85 1.0"/> -->
  <!-- </material> -->
  <!-- <material name="orbita2dgrey"> -->
  <!--     <color rgba="0.8 0.8 0.8 1.0"/> -->
  <!-- </material> -->
  <!-- <material name="orbita3d_yellow"> -->
  <!--     <color rgba="0.8 0.8 0.0 1"/> -->
  <!-- </material> -->
  <!-- <material name="orbita3d_grey"> -->
  <!--     <color rgba="0.8 0.8 0.8 1"/> -->
  <!-- </material> -->
  <!-- URDF definition is so stupid we have to do that... -->
  <!-- <material name="gripperblack"> -->
  <!--     <color rgba="0.4 0.4 0.4 1"/> -->
  <!-- </material> -->
  <!-- <material name="gripperwhite"> -->
  <!--     <color rgba="0.9 0.9 0.9 1"/> -->
  <!-- </material> -->
  <!-- <material name="reachy_yellow"> -->
  <!--     <color rgba="0.8 0.8 0.0 1"/> -->
  <!-- </material> -->
  <!-- <material name="reachy_grey"> -->
  <!--     <color rgba="0.8 0.8 0.8 1"/> -->
  <!-- </material> -->
  <!-- <material name="reachy_metal"> -->
  <!--     <color rgba="0.85 0.85 0.85 1.0"/> -->
  <!-- </material> -->
  <!-- <material name="torsoblack"> -->
  <!--     <color rgba="0.5 0.5 0.5 1.0"/> -->
  <!-- </material> -->
  <!-- <material name="eyewhite"> -->
  <!--     <color rgba="1.0 1.0 1.0 1.0"/> -->
  <!-- </material> -->
  <!-- <material name="orbita2dmetal"> -->
  <!--     <color rgba="0.85 0.85 0.85 1.0"/> -->
  <!-- </material> -->
  <!-- <material name="orbita2dgrey"> -->
  <!--     <color rgba="0.8 0.8 0.8 1.0"/> -->
  <!-- </material> -->
  <!-- <material name="orbita3d_yellow"> -->
  <!--     <color rgba="0.8 0.8 0.0 1"/> -->
  <!-- </material> -->
  <!-- <material name="orbita3d_grey"> -->
  <!--     <color rgba="0.8 0.8 0.8 1"/> -->
  <!-- </material> -->
  <!-- <xacro:include filename="$(find reachy_description)/ros2_control/arm.ros2_control.xacro" /> -->
  <!-- <!-\- Orbita2d config -\-> -->
  <!-- <xacro:arg name="orbita2d_shoulder_config" default="$(find
    orbita2d_description)/config/fake.yaml"/> -->
  <!-- <xacro:arg name="orbita2d_elbow_config" default="$(find
    orbita2d_description)/config/fake.yaml"/> -->
  <!-- <!-\- Orbita3d config -\-> -->
  <!-- <xacro:arg name="orbita3d_wrist_config" default="$(find
    orbita3d_controller)/config/fake.yaml"/> -->
  <!-- Define robot model argument -->
  <!-- -15 degrees -->
  <!-- ARM PARAMETERS -->
  <link name="r_shoulder_base_link">
    <inertial>
      <origin rpy="0.0 0.0 0.0" xyz="0.0 0.0 0.0"/>
      <mass value="0.001"/>
      <inertia ixx="1.0e-6" ixy="1.0e-8" ixz="1.0e-8" iyy="1.0e-6" iyz="1.0e-8" izz="1.0e-6"/>
    </inertial>
  </link>
  <joint name="r_shoulder_base_joint" type="fixed">
    <!-- <origin xyz="${arm_offset_x} ${arm_offset_y*reflect} ${arm_offset_z}"
      rpy="${(1.5707963267948966+(virtual_shoulder_roll_offset - arm_offset_roll))*reflect} 0
      ${arm_offset_yaw*reflect}" /> -->
    <origin rpy="1.3089969389957472 0 0.17453292519943295" xyz="0.0 -0.2 0.0"/>
    <parent link="torso"/>
    <child link="r_shoulder_base_link"/>
  </joint>
  <!--
      Orbita 2 dof

    link                         (joint)

    ${parent}                    (${name}_dummy_1) fixed
      ${name}_dummy_link1        (${name}_dummy_2) fixed
        ${name}_dummy_link2      (${name}_joint1) revolute
          ${name}_first_link     (${name}_joint2) revolute
      	    ${name}_ball_link    (${name}_dummy_out) fixed
	      ${name}_fix_link


    -->
  <!-- used to "place" the joint with the correct axis. For some reason rotation of the inertia matrix does not work... -->
  <link name="r_shoulder_dummy_link1">
    <inertial>
      <origin rpy="0.0 0.0 0.0" xyz="0.0 0.0 0.0"/>
      <mass value="0.001"/>
      <inertia ixx="1.0e-6" ixy="1.0e-8" ixz="1.0e-8" iyy="1.0e-6" iyz="1.0e-8" izz="1.0e-6"/>
    </inertial>
  </link>
  <joint name="r_shoulder_dummy_1" type="fixed">
    <origin rpy="0 0 0" xyz="0 0 0"/>
    <parent link="r_shoulder_base_link"/>
    <child link="r_shoulder_dummy_link1"/>
  </joint>
  <link name="r_shoulder_dummy_link2">
    <inertial>
      <origin rpy="0.0 0.0 0.0" xyz="0.0 0.0 0.0"/>
      <mass value="0.001"/>
      <inertia ixx="1.0e-6" ixy="1.0e-8" ixz="1.0e-8" iyy="1.0e-6" iyz="1.0e-8" izz="1.0e-6"/>
    </inertial>
  </link>
  <!-- used to rotatate the joint to respect the conventional axis -->
  <joint name="r_shoulder_dummy_2" type="fixed">
    <origin rpy="-1.5707963267948966 0 0" xyz="0 0 0"/>
    <!-- <origin xyz="0 0 0" rpy="0 0 0"/> -->
    <parent link="r_shoulder_dummy_link1"/>
    <child link="r_shoulder_dummy_link2"/>
  </joint>
  <link name="r_shoulder_first_link">
    <visual>
      <origin rpy="1.5707963267948966 0 0" xyz="0 0 0"/>
      <geometry>
        <!-- <mesh filename="file://$(find arm_description)/meshes/Orbita2D_ball.obj" /> -->
        <mesh filename="obj_meshes/2D_sphere_visual.obj"/>
      </geometry>
    </visual>
    <!-- <collision> -->
    <!--   <geometry> -->
    <!--     <sphere radius="0.0425"/> -->
    <!--   </geometry> -->
    <!-- </collision> -->
    <inertial>
      <!-- <origin xyz="0.0 0 0" rpy="1.5707963267948966 0 0"/> -->
      <!-- rotation does not work? -->
      <origin rpy="0 0 0" xyz="0.000096 -0.000015 -0.01777"/>
      <mass value="0.487"/>
      <inertia ixx="0.000577881945" ixy="-8.085000000000001e-7" ixz="-6.962790000000001e-7" iyx="-8.085000000000001e-7" iyy="0.000573075516" iyz="2.44386e-7" izx="-6.962790000000001e-7" izy="2.44386e-7" izz="0.000243343676"/>
    </inertial>
  </link>
  <!-- First joint  -->
  <joint name="r_shoulder_pitch" type="revolute">
    <origin rpy="0 0 0" xyz="0 0 0"/>
    <!-- <parent link="${parent}"/> -->
    <parent link="r_shoulder_dummy_link2"/>
    <child link="r_shoulder_first_link"/>
    <axis xyz="0 1 0"/>
    <!-- <axis xyz="0 0 -1"/> -->
    <limit effort="1000.0" lower="-3.141592653589793" upper="3.141592653589793" velocity="100.0"/>
    <safety_controller k_position="500" k_velocity="500" soft_lower_limit="-3.141592" soft_upper_limit="3.1415"/>
    <dynamics damping="0.01" friction="0.1"/>
  </joint>
  <!-- <!-\- Used to get back to the correct orientation -\-> -->
  <!-- <link name="${name}_dummy_link3"> -->
  <!-- </link> -->
  <!-- <joint name="${name}_dummy_3" type="fixed"> -->
  <!--   <!-\- <origin xyz="0 0 0" rpy="-1.5707963267948966 0 0"/> -\-> -->
  <!--   <origin xyz="0 0 0" rpy="3.141592653589793 0 0"/> -->
  <!--   <parent link="${name}_first_link"/> -->
  <!--   <child link="${name}_dummy_link3"/> -->
  <!-- </joint> -->
  <!-- Output link -->
  <link name="r_shoulder_ball_link">
    <inertial>
      <origin rpy="0.0 0.0 0.0" xyz="0.0 0.0 0.0"/>
      <mass value="0.001"/>
      <inertia ixx="1.0e-6" ixy="1.0e-8" ixz="1.0e-8" iyy="1.0e-6" iyz="1.0e-8" izz="1.0e-6"/>
    </inertial>
  </link>
  <joint name="r_shoulder_roll" type="revolute">
    <origin rpy=" 0 0 0" xyz="0 0 0"/>
    <parent link="r_shoulder_first_link"/>
    <child link="r_shoulder_ball_link"/>
    <axis xyz="1 0 0"/>
    <!-- <axis xyz="1 0 0"/> -->
    <limit effort="1000.0" lower="-3.141592653589793" upper="0.0" velocity="100.0"/>
    <safety_controller k_position="500" k_velocity="500" soft_lower_limit="-3.1415" soft_upper_limit="3.1415"/>
    <dynamics damping="0.01" friction="0.1"/>
  </joint>
  <link name="r_shoulder_fix_link">
    <inertial>
      <origin rpy="0.0 0.0 0.0" xyz="0.0 0.0 0.0"/>
      <mass value="0.001"/>
      <inertia ixx="1.0e-6" ixy="1.0e-8" ixz="1.0e-8" iyy="1.0e-6" iyz="1.0e-8" izz="1.0e-6"/>
    </inertial>
  </link>
  <!-- used to rotate the joint to respect the conventional axis -->
  <joint name="r_shoulder_dummy_out" type="fixed">
    <origin rpy="1.5707963267948966 0 0" xyz="0 0 0"/>
    <!-- <origin xyz="0 0 0" rpy="0 0 0"/> -->
    <parent link="r_shoulder_ball_link"/>
    <child link="r_shoulder_fix_link"/>
  </joint>
  <ros2_control name="r_shoulder" type="system">
    <hardware>
      <!-- Standard ROS fake system -->
      <!-- <plugin>fake_components/GenericSystem</plugin> -->
      <!-- Pollen controller fake system -->
      <plugin>orbita2d_system_hwi/Orbita2dSystem</plugin>
      <param name="config_file">/home/reachy/reachy_ws/install/orbita2d_description/share/orbita2d_description/config/fake.yaml</param>
    </hardware>
    <gpio name="r_shoulder">
      <state_interface name="torque">
        <param name="initial_value">0.0</param>
      </state_interface>
      <state_interface name="errors"/>
      <command_interface name="torque"/>
    </gpio>
    <joint name="r_shoulder_pitch">
      <state_interface name="position">
        <param name="initial_value">0.0</param>
      </state_interface>
      <state_interface name="velocity">
        <param name="initial_value">0.0</param>
      </state_interface>
      <state_interface name="effort">
        <param name="initial_value">0.0</param>
      </state_interface>
      <command_interface name="position"/>
    </joint>
    <joint name="r_shoulder_roll">
      <state_interface name="position">
        <param name="initial_value">0.0</param>
      </state_interface>
      <state_interface name="velocity">
        <param name="initial_value">0.0</param>
      </state_interface>
      <state_interface name="effort">
        <param name="initial_value">0.0</param>
      </state_interface>
      <command_interface name="position"/>
    </joint>
    <gpio name="r_shoulder_raw_motor_1">
      <state_interface name="speed_limit"/>
      <command_interface name="speed_limit"/>
      <state_interface name="torque_limit"/>
      <command_interface name="torque_limit"/>
      <state_interface name="p_gain"/>
      <command_interface name="p_gain"/>
      <state_interface name="i_gain"/>
      <command_interface name="i_gain"/>
      <state_interface name="d_gain"/>
      <command_interface name="d_gain"/>
      <state_interface name="motor_temperature"/>
      <state_interface name="board_temperature"/>
      <state_interface name="motor_currents"/>
      <state_interface name="motor_velocities"/>
    </gpio>
    <gpio name="r_shoulder_raw_motor_2">
      <state_interface name="speed_limit"/>
      <command_interface name="speed_limit"/>
      <state_interface name="torque_limit"/>
      <command_interface name="torque_limit"/>
      <state_interface name="p_gain"/>
      <command_interface name="p_gain"/>
      <state_interface name="i_gain"/>
      <command_interface name="i_gain"/>
      <state_interface name="d_gain"/>
      <command_interface name="d_gain"/>
      <state_interface name="motor_temperature"/>
      <state_interface name="board_temperature"/>
      <state_interface name="motor_currents"/>
      <state_interface name="motor_velocities"/>
    </gpio>
  </ros2_control>
  <link name="r_elbow_arm_link">
    <visual>
      <origin rpy="0 0 0" xyz="0 0 0"/>
      <geometry>
        <!-- <mesh filename="package://arm_description/meshes/upper_arm_visual.obj" /> -->
        <mesh filename="obj_meshes/upper_arm_visual.obj"/>
      </geometry>
    </visual>
    <collision>
      <!-- <origin xyz="0 0 ${arm_length/2}" rpy="0 0 0"/> -->
      <origin rpy="0 0 0" xyz="0 0 0"/>
      <geometry>
        <!-- <mesh filename="package://arm_description/meshes/upper_arm_collider.obj" /> -->
        <mesh filename="obj_meshes/upper_arm_collider.obj"/>
      </geometry>
    </collision>
    <inertial>
      <origin rpy="0 0 0" xyz="-0.000669 0.000509 0.144798"/>
      <mass value="1.620"/>
      <inertia ixx="0.007864" ixy="0.000005410021" ixz="-0.000117782969" iyx="0.000005410021" iyy="0.006998" iyz="0.000121931452" izx="-0.000117782969" izy="0.000121931452" izz="0.001828"/>
    </inertial>
  </link>
  <joint name="r_elbow_arm_joint" type="fixed">
    <origin rpy="0 1.5707963267948966 -1.5707963267948966" xyz="0 0 0.0"/>
    <!-- <origin xyz="0 0 0.0" rpy="0 0 0" /> -->
    <!-- <parent link="${p}_shoulder_ball_link" /> -->
    <parent link="r_shoulder_fix_link"/>
    <child link="r_elbow_arm_link"/>
  </joint>
  <link name="r_elbow_base_link">
    <inertial>
      <origin rpy="0.0 0.0 0.0" xyz="0.0 0.0 0.0"/>
      <mass value="0.001"/>
      <inertia ixx="1.0e-6" ixy="1.0e-8" ixz="1.0e-8" iyy="1.0e-6" iyz="1.0e-8" izz="1.0e-6"/>
    </inertial>
  </link>
  <!-- <joint name="${prefix}_elbow_base_joint" type="fixed"> -->
  <!--   <origin xyz="0 0 0" rpy="0 ${(1.5707963267948966 + virtual_elbow_offset_yaw)*reflect} 0" /> -->
  <!--   <parent link="${p}_shoulder_ball_link" /> -->
  <!--   <child link="${prefix}_elbow_base_link" /> -->
  <!-- </joint> -->
  <!-- <xacro:orbita2d -->
  <!--   name="${p}_elbow" parent="${prefix}_elbow_base_link" -->
  <!--   length="${forearm_length}" radius="${forearm_radius}" mass="${forearm_mass}" -->
  <!--   xyz="0 -${arm_length} 0" rpy="${1.5707963267948966} 0 0" -->
  <!--   damping="${damping}" friction="${friction}" -->
  <!--   joint1="yaw" joint2="pitch" -->
  <!--   joint1_min_angle="-${pi/2}" joint1_max_angle="${pi/2}" -->
  <!--   joint2_min_angle="-2.25" joint2_max_angle="0.1" -->
  <!-- /> -->
  <joint name="r_elbow_base_joint" type="fixed">
    <origin rpy="0 0 0" xyz="0 0 0.28"/>
    <parent link="r_elbow_arm_link"/>
    <child link="r_elbow_base_link"/>
  </joint>
  <!--
      Orbita 2 dof

    link                         (joint)

    ${parent}                    (${name}_dummy_1) fixed
      ${name}_dummy_link1        (${name}_dummy_2) fixed
        ${name}_dummy_link2      (${name}_joint1) revolute
          ${name}_first_link     (${name}_joint2) revolute
      	    ${name}_ball_link    (${name}_dummy_out) fixed
	      ${name}_fix_link


    -->
  <!-- used to "place" the joint with the correct axis. For some reason rotation of the inertia matrix does not work... -->
  <link name="r_elbow_dummy_link1">
    <inertial>
      <origin rpy="0.0 0.0 0.0" xyz="0.0 0.0 0.0"/>
      <mass value="0.001"/>
      <inertia ixx="1.0e-6" ixy="1.0e-8" ixz="1.0e-8" iyy="1.0e-6" iyz="1.0e-8" izz="1.0e-6"/>
    </inertial>
  </link>
  <joint name="r_elbow_dummy_1" type="fixed">
    <origin rpy="0 0 0" xyz="0 0 0"/>
    <parent link="r_elbow_base_link"/>
    <child link="r_elbow_dummy_link1"/>
  </joint>
  <link name="r_elbow_dummy_link2">
    <inertial>
      <origin rpy="0.0 0.0 0.0" xyz="0.0 0.0 0.0"/>
      <mass value="0.001"/>
      <inertia ixx="1.0e-6" ixy="1.0e-8" ixz="1.0e-8" iyy="1.0e-6" iyz="1.0e-8" izz="1.0e-6"/>
    </inertial>
  </link>
  <!-- used to rotatate the joint to respect the conventional axis -->
  <joint name="r_elbow_dummy_2" type="fixed">
    <origin rpy="3.141592 0 1.5707963267948966" xyz="0 0 0"/>
    <!-- <origin xyz="0 0 0" rpy="0 0 0"/> -->
    <parent link="r_elbow_dummy_link1"/>
    <child link="r_elbow_dummy_link2"/>
  </joint>
  <link name="r_elbow_first_link">
    <visual>
      <origin rpy="3.141592 0 -1.5707963267948966" xyz="0 0 0"/>
      <geometry>
        <!-- <mesh filename="file://$(find arm_description)/meshes/Orbita2D_ball.obj" /> -->
        <mesh filename="obj_meshes/2D_sphere_visual.obj"/>
      </geometry>
    </visual>
    <!-- <collision> -->
    <!--   <geometry> -->
    <!--     <sphere radius="0.0425"/> -->
    <!--   </geometry> -->
    <!-- </collision> -->
    <inertial>
      <!-- <origin xyz="0.0 0 0" rpy="1.5707963267948966 0 0"/> -->
      <!-- rotation does not work? -->
      <origin rpy="0 0 0" xyz="0.000096 -0.000015 -0.01777"/>
      <mass value="0.487"/>
      <inertia ixx="0.000577881945" ixy="-8.085000000000001e-7" ixz="-6.962790000000001e-7" iyx="-8.085000000000001e-7" iyy="0.000573075516" iyz="2.44386e-7" izx="-6.962790000000001e-7" izy="2.44386e-7" izz="0.000243343676"/>
    </inertial>
  </link>
  <!-- First joint  -->
  <joint name="r_elbow_yaw" type="revolute">
    <origin rpy="0 0 0" xyz="0 0 0"/>
    <!-- <parent link="${parent}"/> -->
    <parent link="r_elbow_dummy_link2"/>
    <child link="r_elbow_first_link"/>
    <axis xyz="0 0 1"/>
    <!-- <axis xyz="0 0 -1"/> -->
    <limit effort="1000.0" lower="-3.141592653589793" upper="3.141592653589793" velocity="100.0"/>
    <safety_controller k_position="500" k_velocity="500" soft_lower_limit="-3.141592" soft_upper_limit="3.1415"/>
    <dynamics damping="0.01" friction="0.1"/>
  </joint>
  <!-- <!-\- Used to get back to the correct orientation -\-> -->
  <!-- <link name="${name}_dummy_link3"> -->
  <!-- </link> -->
  <!-- <joint name="${name}_dummy_3" type="fixed"> -->
  <!--   <!-\- <origin xyz="0 0 0" rpy="-1.5707963267948966 0 0"/> -\-> -->
  <!--   <origin xyz="0 0 0" rpy="3.141592653589793 0 0"/> -->
  <!--   <parent link="${name}_first_link"/> -->
  <!--   <child link="${name}_dummy_link3"/> -->
  <!-- </joint> -->
  <!-- Output link -->
  <link name="r_elbow_ball_link">
    <inertial>
      <origin rpy="0.0 0.0 0.0" xyz="0.0 0.0 0.0"/>
      <mass value="0.001"/>
      <inertia ixx="1.0e-6" ixy="1.0e-8" ixz="1.0e-8" iyy="1.0e-6" iyz="1.0e-8" izz="1.0e-6"/>
    </inertial>
  </link>
  <joint name="r_elbow_pitch" type="revolute">
    <origin rpy=" 0 0 0" xyz="0 0 0"/>
    <parent link="r_elbow_first_link"/>
    <child link="r_elbow_ball_link"/>
    <axis xyz="0 1 0"/>
    <!-- <axis xyz="1 0 0"/> -->
    <limit effort="1000.0" lower="-2.25" upper="0.1" velocity="100.0"/>
    <safety_controller k_position="500" k_velocity="500" soft_lower_limit="-3.1415" soft_upper_limit="3.1415"/>
    <dynamics damping="0.01" friction="0.1"/>
  </joint>
  <link name="r_elbow_fix_link">
    <inertial>
      <origin rpy="0.0 0.0 0.0" xyz="0.0 0.0 0.0"/>
      <mass value="0.001"/>
      <inertia ixx="1.0e-6" ixy="1.0e-8" ixz="1.0e-8" iyy="1.0e-6" iyz="1.0e-8" izz="1.0e-6"/>
    </inertial>
  </link>
  <!-- used to rotate the joint to respect the conventional axis -->
  <joint name="r_elbow_dummy_out" type="fixed">
    <origin rpy="3.141592 0 1.5707963267948966" xyz="0 0 0"/>
    <!-- <origin xyz="0 0 0" rpy="0 0 0"/> -->
    <parent link="r_elbow_ball_link"/>
    <child link="r_elbow_fix_link"/>
  </joint>
  <ros2_control name="r_elbow" type="system">
    <hardware>
      <!-- Standard ROS fake system -->
      <!-- <plugin>fake_components/GenericSystem</plugin> -->
      <!-- Pollen controller fake system -->
      <plugin>orbita2d_system_hwi/Orbita2dSystem</plugin>
      <param name="config_file">/home/reachy/reachy_ws/install/orbita2d_description/share/orbita2d_description/config/fake.yaml</param>
    </hardware>
    <gpio name="r_elbow">
      <state_interface name="torque">
        <param name="initial_value">0.0</param>
      </state_interface>
      <state_interface name="errors"/>
      <command_interface name="torque"/>
    </gpio>
    <joint name="r_elbow_yaw">
      <state_interface name="position">
        <param name="initial_value">0.0</param>
      </state_interface>
      <state_interface name="velocity">
        <param name="initial_value">0.0</param>
      </state_interface>
      <state_interface name="effort">
        <param name="initial_value">0.0</param>
      </state_interface>
      <command_interface name="position"/>
    </joint>
    <joint name="r_elbow_pitch">
      <state_interface name="position">
        <param name="initial_value">0.0</param>
      </state_interface>
      <state_interface name="velocity">
        <param name="initial_value">0.0</param>
      </state_interface>
      <state_interface name="effort">
        <param name="initial_value">0.0</param>
      </state_interface>
      <command_interface name="position"/>
    </joint>
    <gpio name="r_elbow_raw_motor_1">
      <state_interface name="speed_limit"/>
      <command_interface name="speed_limit"/>
      <state_interface name="torque_limit"/>
      <command_interface name="torque_limit"/>
      <state_interface name="p_gain"/>
      <command_interface name="p_gain"/>
      <state_interface name="i_gain"/>
      <command_interface name="i_gain"/>
      <state_interface name="d_gain"/>
      <command_interface name="d_gain"/>
      <state_interface name="motor_temperature"/>
      <state_interface name="board_temperature"/>
      <state_interface name="motor_currents"/>
      <state_interface name="motor_velocities"/>
    </gpio>
    <gpio name="r_elbow_raw_motor_2">
      <state_interface name="speed_limit"/>
      <command_interface name="speed_limit"/>
      <state_interface name="torque_limit"/>
      <command_interface name="torque_limit"/>
      <state_interface name="p_gain"/>
      <command_interface name="p_gain"/>
      <state_interface name="i_gain"/>
      <command_interface name="i_gain"/>
      <state_interface name="d_gain"/>
      <command_interface name="d_gain"/>
      <state_interface name="motor_temperature"/>
      <state_interface name="board_temperature"/>
      <state_interface name="motor_currents"/>
      <state_interface name="motor_velocities"/>
    </gpio>
  </ros2_control>
  <!-- <link name="${prefix}_elbow_forearm_link"> -->
  <!--   <visual> -->
  <!--   	<origin xyz="0 0 0" rpy="0 0 0"/> -->
  <!--   	<geometry> -->
  <!-- 	  <mesh filename="package://arm_description/meshes/Orbita2D_forearm.obj" /> -->
  <!--   	</geometry> -->
  <!--   </visual> -->
  <!--   <inertial> -->
  <!--   	<origin xyz="0.00092892 -0.00254548 0.14021211" rpy="0 0 0"/> -->
  <!-- 	<mass value="0.90719109"/> -->
  <!-- 	 <inertia ixx="0.00428278" ixy="-0.00000203" ixz="0.00011755" -->
  <!-- 		  iyx="-0.00000203" iyy="0.0044585" iyz="-0.00004915" -->
  <!-- 		  izx="0.00011755" izy="-0.00004915" izz="0.00047615"/> -->
  <!--   </inertial> -->
  <!-- </link> -->
  <!-- <joint name="${prefix}_elbow_forearm_joint" type="fixed"> -->
  <!--   <origin xyz="0 0 0.0" rpy="0 0 0" /> -->
  <!--   <parent link="${p}_elbow_ball_link" /> -->
  <!--   <child link="${prefix}_elbow_forearm_link" /> -->
  <!-- </joint> -->
  <link name="r_elbow_forearm_link">
    <visual>
      <origin rpy="0 0 0" xyz="0 0 0"/>
      <geometry>
        <!-- <mesh filename="package://arm_description/meshes/forearm_visual.obj" /> -->
        <mesh filename="obj_meshes/forearm_visual.obj"/>
      </geometry>
    </visual>
    <collision>
      <origin rpy="0 0 0" xyz="0 0 0"/>
      <!-- <origin xyz="0 0 ${forearm_length/2}" rpy="0 0 0"/> -->
      <geometry>
        <!-- <mesh filename="package://arm_description/meshes/forearm_collider.obj" /> -->
        <mesh filename="obj_meshes/forearm_collider.obj"/>
      </geometry>
    </collision>
    <inertial>
      <origin rpy="0 0 0" xyz="0.00092892 -0.00254548 0.14021211"/>
      <mass value="0.90719109"/>
      <inertia ixx="0.00428278" ixy="-0.00000203" ixz="0.00011755" iyx="-0.00000203" iyy="0.0044585" iyz="-0.00004915" izx="0.00011755" izy="-0.00004915" izz="0.00047615"/>
    </inertial>
  </link>
  <joint name="r_elbow_forearm_joint" type="fixed">
    <origin rpy="0 0 0" xyz="0 0 0.0"/>
    <!-- <parent link="${p}_elbow_ball_link" /> -->
    <parent link="r_elbow_fix_link"/>
    <child link="r_elbow_forearm_link"/>
  </joint>
  <!-- <xacro:orbita3d -->
  <!--   name="${p}_wrist" parent="${p}_elbow_ball_link" -->
  <!--   length="${wrist_length}" radius="${wrist_radius}" mass="${wrist_mass}" -->
  <!--   xyz="0 0 ${forearm_length}" rpy="${pi} 0 0" -->
  <!--   damping="${damping}" friction="${friction}" -->
  <!-- /> -->
  <!--
      Orbita3d

    link                         (joint)

    ${parent}                    (${name}_base_joint) fixed
      ${name}_base_link          (${name}_roll) revolute
        ${name}_dummy_link1      (${name}_pitch) revolute
          ${name}_dummy_link2    (${name}_yaw) revolute
            ${name}_link         (${name}_ball_joint) fixed
              ${name}_ball_link
    -->
  <link name="r_wrist_dummy_link1">
    <inertial>
      <mass value="0.001"/>
      <origin rpy="0 0 0" xyz="0 0 0"/>
      <inertia ixx="1.4166666666666668e-07" ixy="0.0" ixz="0.0" iyy="1.4166666666666668e-07" iyz="0.0" izz="2.6666666666666667e-07"/>
    </inertial>
  </link>
  <link name="r_wrist_dummy_link2">
    <inertial>
      <mass value="0.001"/>
      <origin rpy="0 0 0" xyz="0 0 0"/>
      <inertia ixx="1.4166666666666668e-07" ixy="0.0" ixz="0.0" iyy="1.4166666666666668e-07" iyz="0.0" izz="2.6666666666666667e-07"/>
    </inertial>
  </link>
  <link name="r_wrist_link">
    <!-- <visual> -->
    <!-- 	<origin xyz="0 0 0" rpy="0 0 0"/> -->
    <!-- 	<geometry> -->
    <!--     <cylinder length="${length}" radius="${radius}"/> -->
    <!-- 	</geometry> -->
    <!-- 	<xacro:orbita3d_grey/> -->
    <!-- </visual> -->
    <!-- <collision> -->
    <!-- 	<origin xyz="0 0 ${length/2}" rpy="0 0 0"/> -->
    <!-- 	<geometry> -->
    <!--     <cylinder length="${length}" radius="${radius}"/> -->
    <!-- 	</geometry> -->
    <!-- </collision> -->
    <inertial>
      <mass value="0.098"/>
      <origin rpy="0 0 0" xyz="0 0 -0.005"/>
      <inertia ixx="1.3883333333333335e-05" ixy="0.0" ixz="0.0" iyy="1.3883333333333335e-05" iyz="0.0" izz="2.6133333333333336e-05"/>
    </inertial>
  </link>
  <link name="r_wrist_ball_link">
    <!-- <visual> -->
    <!-- 	<origin xyz="0 0 0" rpy="0 0 0"/> -->
    <!-- 	<geometry> -->
    <!--     <sphere radius="${radius*1.2}"/> -->
    <!-- 	</geometry> -->
    <!-- 	<xacro:orbita3d_grey/> -->
    <!-- </visual> -->
    <!-- <collision> -->
    <!-- 	<origin xyz="0 0 0" rpy="0 0 0"/> -->
    <!-- 	<geometry> -->
    <!--     <sphere radius="${radius*1.2}"/> -->
    <!-- 	</geometry> -->
    <!-- </collision> -->
    <!-- <xacro:inertial_sphere mass="${mass*0.5}" diameter="${2*radius*1.2}"/> -->
    <inertial>
      <origin rpy="0.0 0.0 0.0" xyz="0.0 0.0 0.0"/>
      <mass value="0.001"/>
      <inertia ixx="1.0e-6" ixy="1.0e-8" ixz="1.0e-8" iyy="1.0e-6" iyz="1.0e-8" izz="1.0e-6"/>
    </inertial>
  </link>
  <joint name="r_wrist_ball_joint" type="fixed">
    <origin rpy="0 0 0" xyz="0 0 0"/>
    <parent link="r_wrist_link"/>
    <child link="r_wrist_ball_link"/>
  </joint>
  <link name="r_wrist_base_link">
    <!-- <visual> -->
    <!-- 	<origin xyz="0 0 0.0672" rpy="0 0 0"/> -->
    <!-- 	<geometry> -->
    <!--     <cylinder radius="0.0278" length="0.0336"/> -->
    <!-- 	</geometry> -->
    <!-- 	<xacro:orbita3d_grey/> -->
    <!-- </visual> -->
    <inertial>
      <origin rpy="0.0 0.0 0.0" xyz="0.0 0.0 0.0"/>
      <mass value="0.001"/>
      <inertia ixx="1.0e-6" ixy="1.0e-8" ixz="1.0e-8" iyy="1.0e-6" iyz="1.0e-8" izz="1.0e-6"/>
    </inertial>
  </link>
  <joint name="r_wrist_base_joint" type="fixed">
    <origin rpy="3.141592 0 1.5707963267948966" xyz="0 0 0.28"/>
    <parent link="r_elbow_forearm_link"/>
    <child link="r_wrist_base_link"/>
  </joint>
  <link name="r_wrist_out_link">
    <inertial>
      <origin rpy="0.0 0.0 0.0" xyz="0.0 0.0 0.0"/>
      <mass value="0.001"/>
      <inertia ixx="1.0e-6" ixy="1.0e-8" ixz="1.0e-8" iyy="1.0e-6" iyz="1.0e-8" izz="1.0e-6"/>
    </inertial>
  </link>
  <joint name="r_wrist_out_joint" type="fixed">
    <origin rpy="3.141592 0 0" xyz="0 0 0"/>
    <parent link="r_wrist_ball_link"/>
    <child link="r_wrist_out_link"/>
  </joint>
  <joint name="r_wrist_roll" type="revolute">
    <!-- <origin xyz="${xyz}" rpy="${rpy}"/> -->
    <origin rpy="0 0 0" xyz="0 0 0"/>
    <!-- <parent link="${parent}"/> -->
    <parent link="r_wrist_base_link"/>
    <child link="r_wrist_dummy_link1"/>
    <axis xyz="1 0 0"/>
    <limit effort="1000.0" lower="-0.35" upper="0.35" velocity="100.0"/>
    <dynamics damping="0.01" friction="0.1"/>
  </joint>
  <joint name="r_wrist_pitch" type="revolute">
    <origin rpy="0 0 0" xyz="0 0 0"/>
    <parent link="r_wrist_dummy_link1"/>
    <child link="r_wrist_dummy_link2"/>
    <axis xyz="0 1 0"/>
    <limit effort="1000.0" lower="-0.35" upper="0.35" velocity="100.0"/>
    <dynamics damping="0.01" friction="0.1"/>
  </joint>
  <joint name="r_wrist_yaw" type="revolute">
    <origin rpy="0 0 0" xyz="0 0 0"/>
    <parent link="r_wrist_dummy_link2"/>
    <child link="r_wrist_link"/>
    <axis xyz="0 0 1"/>
    <limit effort="1000.0" lower="-1.57" upper="1.57" velocity="100.0"/>
    <dynamics damping="0.01" friction="0.1"/>
  </joint>
  <ros2_control name="r_wrist" type="system">
    <hardware>
      <!-- Standard ROS fake system -->
      <!-- <plugin>fake_components/GenericSystem</plugin> -->
      <!-- Pollen controller fake system -->
      <plugin>orbita3d_system_hwi/Orbita3dSystem</plugin>
      <param name="config_file">/home/reachy/reachy_ws/install/orbita3d_description/share/orbita3d_description/config/fake.yaml</param>
    </hardware>
    <gpio name="r_wrist">
      <state_interface name="torque">
        <param name="initial_value">0.0</param>
      </state_interface>
      <state_interface name="errors"/>
      <command_interface name="torque"/>
    </gpio>
    <joint name="r_wrist_roll">
      <state_interface name="position">
        <param name="initial_value">0.0</param>
      </state_interface>
      <state_interface name="velocity">
        <param name="initial_value">0.0</param>
      </state_interface>
      <state_interface name="effort">
        <param name="initial_value">0.0</param>
      </state_interface>
      <command_interface name="position"/>
    </joint>
    <joint name="r_wrist_pitch">
      <state_interface name="position">
        <param name="initial_value">0.0</param>
      </state_interface>
      <state_interface name="velocity">
        <param name="initial_value">0.0</param>
      </state_interface>
      <state_interface name="effort">
        <param name="initial_value">0.0</param>
      </state_interface>
      <command_interface name="position"/>
    </joint>
    <joint name="r_wrist_yaw">
      <state_interface name="position">
        <param name="initial_value">0.0</param>
      </state_interface>
      <state_interface name="velocity">
        <param name="initial_value">0.0</param>
      </state_interface>
      <state_interface name="effort">
        <param name="initial_value">0.0</param>
      </state_interface>
      <command_interface name="position"/>
    </joint>
    <gpio name="r_wrist_raw_motor_1">
      <state_interface name="speed_limit"/>
      <command_interface name="speed_limit"/>
      <state_interface name="torque_limit"/>
      <command_interface name="torque_limit"/>
      <state_interface name="p_gain"/>
      <command_interface name="p_gain"/>
      <state_interface name="i_gain"/>
      <command_interface name="i_gain"/>
      <state_interface name="d_gain"/>
      <command_interface name="d_gain"/>
      <state_interface name="motor_temperature"/>
      <state_interface name="board_temperature"/>
      <state_interface name="motor_currents"/>
      <state_interface name="motor_velocities"/>
    </gpio>
    <gpio name="r_wrist_raw_motor_2">
      <state_interface name="speed_limit"/>
      <command_interface name="speed_limit"/>
      <state_interface name="torque_limit"/>
      <command_interface name="torque_limit"/>
      <state_interface name="p_gain"/>
      <command_interface name="p_gain"/>
      <state_interface name="i_gain"/>
      <command_interface name="i_gain"/>
      <state_interface name="d_gain"/>
      <command_interface name="d_gain"/>
      <state_interface name="motor_temperature"/>
      <state_interface name="board_temperature"/>
      <state_interface name="motor_currents"/>
      <state_interface name="motor_velocities"/>
    </gpio>
    <gpio name="r_wrist_raw_motor_3">
      <state_interface name="speed_limit"/>
      <command_interface name="speed_limit"/>
      <state_interface name="torque_limit"/>
      <command_interface name="torque_limit"/>
      <state_interface name="p_gain"/>
      <command_interface name="p_gain"/>
      <state_interface name="i_gain"/>
      <command_interface name="i_gain"/>
      <state_interface name="d_gain"/>
      <command_interface name="d_gain"/>
      <state_interface name="motor_temperature"/>
      <state_interface name="board_temperature"/>
      <state_interface name="motor_currents"/>
      <state_interface name="motor_velocities"/>
    </gpio>
  </ros2_control>
  <!-- <xacro:arm_control name="${p}_arm" prefix="${p}" config_file="${config_file}" /> -->
  <!-- <xacro:orbita2d_control name="${p}_shoulder" config_file="${shoulder_config_file}" /> -->
  <!-- <xacro:orbita2d_control name="${p}_elbow" config_file="${elbow_config_file}" /> -->
  <!-- <xacro:orbita3d_control name="${p}_wrist" config_file="${wrist_config_file}" /> -->
  <!-- URDF definition is so stupid we have to do that... -->
  <!-- <material name="gripperblack"> -->
  <!--     <color rgba="0.4 0.4 0.4 1"/> -->
  <!-- </material> -->
  <!-- <material name="gripperwhite"> -->
  <!--     <color rgba="0.9 0.9 0.9 1"/> -->
  <!-- </material> -->
  <!-- <material name="reachy_yellow"> -->
  <!--     <color rgba="0.8 0.8 0.0 1"/> -->
  <!-- </material> -->
  <!-- <material name="reachy_grey"> -->
  <!--     <color rgba="0.8 0.8 0.8 1"/> -->
  <!-- </material> -->
  <!-- <material name="reachy_metal"> -->
  <!--     <color rgba="0.85 0.85 0.85 1.0"/> -->
  <!-- </material> -->
  <!-- <material name="torsoblack"> -->
  <!--     <color rgba="0.5 0.5 0.5 1.0"/> -->
  <!-- </material> -->
  <!-- <material name="eyewhite"> -->
  <!--     <color rgba="1.0 1.0 1.0 1.0"/> -->
  <!-- </material> -->
  <!-- <material name="orbita2dmetal"> -->
  <!--     <color rgba="0.85 0.85 0.85 1.0"/> -->
  <!-- </material> -->
  <!-- <material name="orbita2dgrey"> -->
  <!--     <color rgba="0.8 0.8 0.8 1.0"/> -->
  <!-- </material> -->
  <!-- <material name="orbita3d_yellow"> -->
  <!--     <color rgba="0.8 0.8 0.0 1"/> -->
  <!-- </material> -->
  <!-- <material name="orbita3d_grey"> -->
  <!--     <color rgba="0.8 0.8 0.8 1"/> -->
  <!-- </material> -->
  <!-- <material name="gripperblack"> -->
  <!--     <color rgba="0.4 0.4 0.4 1"/> -->
  <!-- </material> -->
  <!-- <material name="gripperwhite"> -->
  <!--     <color rgba="0.9 0.9 0.9 1"/> -->
  <!-- </material> -->
  <link name="r_hand_palm_link">
    <collision>
      <origin rpy="0 0 0" xyz="0 0 0.0 "/>
      <geometry>
        <!-- <mesh filename="file://$(find dynamixel_description)/meshes/pincette_right_collider.obj" /> -->
        <mesh filename="obj_meshes/pincette_base_collider.obj"/>
      </geometry>
    </collision>
    <visual>
      <origin rpy="0 0 0" xyz="0 0 0"/>
      <geometry>
        <!-- <mesh filename="file://$(find dynamixel_description)/meshes/pincette_right_visual.obj" /> -->
        <mesh filename="obj_meshes/pincette_base_visual.obj"/>
      </geometry>
    </visual>
    <inertial>
      <origin rpy="0 0 0" xyz="0.0070087 0.00974766 0.04392328"/>
      <mass value="0.30798029"/>
      <inertia ixx="0.00021928" ixy="-0.00003149" ixz="-0.00001759" iyx="-0.00003149" iyy="0.00016859" iyz="-0.00001396" izx="-0.00001759" izy="-0.00001396" izz="0.0002333"/>
    </inertial>
  </link>
  <joint name="r_hand_palm" type="fixed">
    <origin rpy="0.0 0 0" xyz="0 0 0"/>
    <parent link="r_wrist_out_link"/>
    <child link="r_hand_palm_link"/>
  </joint>
  <link name="r_hand_virtual_gripper_link">
    <!-- <inertial> -->
    <!--   <origin xyz="0.0 0.0 0.0" rpy="0.0 0.0 0.0"/> -->
    <!--   <mass value="0.01"/> -->
    <!--   <inertia ixx="1.0e-6" ixy="1.0e-8" ixz="1.0e-8" iyy="1.0e-6" iyz="1.0e-8" izz="1.0e-6"/> -->
    <!-- </inertial> -->
    <inertial>
      <mass value="0.01"/>
      <origin rpy="0 0 0" xyz="0 0 0"/>
      <inertia ixx="1.666666666666667e-07" ixy="0.0" ixz="0.0" iyy="1.666666666666667e-07" iyz="0.0" izz="1.666666666666667e-07"/>
    </inertial>
  </link>
  <joint name="r_hand_finger" type="revolute">
    <origin rpy="0 0 0" xyz="0.0 0.0 0.070028"/>
    <parent link="r_hand_palm_link"/>
    <child link="r_hand_virtual_gripper_link"/>
    <axis xyz="1 0 0"/>
    <limit effort="100.0" lower="0.0" upper="2.27" velocity="10.0"/>
    <dynamics damping="0.01" friction="0.1"/>
  </joint>
  <link name="r_hand_proximal_link">
    <inertial>
      <origin rpy="0 0 0" xyz="0.00004101 0.002756 0.019654"/>
      <mass value="0.03926395"/>
      <inertia ixx="0.00001937" ixy="0.0" ixz="0.00000007" iyx="0.0" iyy="0.00002003" iyz="0.00000036" izx="0.00000007" izy="0.00000036" izz="0.00000463"/>
    </inertial>
    <collision>
      <origin rpy="0 0 0" xyz="0 0.00 0.0 "/>
      <geometry>
        <!-- <mesh filename="file://$(find arm_description)/meshes/pincette_proximal_collider.obj" /> -->
        <mesh filename="obj_meshes/pincette_proximal_collider.obj"/>
      </geometry>
    </collision>
    <visual>
      <origin rpy="0 0 0" xyz="0 0 0 "/>
      <geometry>
        <!-- <mesh filename="file://$(find arm_description)/meshes/pincette_proximal_visual.obj" /> -->
        <mesh filename="obj_meshes/pincette_proximal_visual.obj"/>
      </geometry>
    </visual>
  </link>
  <link name="r_hand_proximal_mimic_link">
    <inertial>
      <origin rpy="0 0 0" xyz="0.00004101 0.002756 0.019654"/>
      <mass value="0.03926395"/>
      <inertia ixx="0.00001937" ixy="0.0" ixz="0.00000007" iyx="0.0" iyy="0.00002003" iyz="0.00000036" izx="0.00000007" izy="0.00000036" izz="0.00000463"/>
    </inertial>
    <collision>
      <origin rpy="0 0 0" xyz="0 0.0 0.0 "/>
      <geometry>
        <!-- <box size="0.031 0.026 0.06"/> -->
        <!-- <mesh filename="file://$(find arm_description)/meshes/pincette_proximal_collider.obj" /> -->
        <mesh filename="obj_meshes/pincette_proximal_collider.obj"/>
      </geometry>
    </collision>
    <visual>
      <origin rpy="0 0 0" xyz="0 0 0 "/>
      <geometry>
        <!-- <mesh filename="file://$(find arm_description)/meshes/pincette_proximal_visual.obj" /> -->
        <mesh filename="obj_meshes/pincette_proximal_visual.obj"/>
      </geometry>
    </visual>
  </link>
  <joint name="r_hand_finger_proximal" type="revolute">
    <origin rpy="0 0 0" xyz="-0.010196 0.03792 0.070028"/>
    <parent link="r_hand_palm_link"/>
    <child link="r_hand_proximal_link"/>
    <axis xyz="1 0 0"/>
    <limit effort="100.0" lower="-0.51" upper="0.554" velocity="10.0"/>
    <mimic joint="r_hand_finger" multiplier="-0.4689" offset="0.554"/>
    <dynamics damping="0.01" friction="0.1"/>
  </joint>
  <joint name="r_hand_finger_proximal_mimic" type="revolute">
    <origin rpy="0 0 3.141592653589793" xyz="-0.010196 -0.03792 0.070028"/>
    <parent link="r_hand_palm_link"/>
    <child link="r_hand_proximal_mimic_link"/>
    <axis xyz="1 0 0"/>
    <limit effort="100.0" lower="-0.51" upper="0.554" velocity="10.0"/>
    <dynamics damping="0.01" friction="0.1"/>
    <mimic joint="r_hand_finger_proximal" multiplier="1" offset="0"/>
  </joint>
  <link name="r_hand_distal_link">
    <inertial>
      <origin rpy="0 0 0" xyz="0.00000695 -0.00006402 0.01772685"/>
      <mass value="0.02821091"/>
      <inertia ixx="0.00000683" ixy="0.0" ixz="0.0" iyx="0.0" iyy="0.00000696" iyz="0.00000127" izx="0.0" izy="0.00000127" izz="0.0000028"/>
    </inertial>
    <collision>
      <origin rpy="0 0 0" xyz="0 0.0 0.0 "/>
      <geometry>
        <mesh filename="obj_meshes/pincette_distal_collider.obj"/>
      </geometry>
    </collision>
    <visual>
      <origin rpy="0 0 0" xyz="0 0 0 "/>
      <geometry>
        <mesh filename="obj_meshes/pincette_distal.obj"/>
      </geometry>
    </visual>
  </link>
  <joint name="r_hand_finger_distal" type="revolute">
    <origin rpy="0 0 0" xyz="0 0 0.049997"/>
    <parent link="r_hand_proximal_link"/>
    <child link="r_hand_distal_link"/>
    <axis xyz="1 0 0"/>
    <limit effort="100.0" lower="-0.51" upper="0.554" velocity="10.0"/>
    <!-- <mimic joint="${p}_finger_proximal" multiplier="-1" offset="0" /> -->
    <mimic joint="r_hand_finger" multiplier="0.4689" offset="-0.554"/>
    <dynamics damping="0.01" friction="0.1"/>
  </joint>
  <link name="r_hand_distal_mimic_link">
    <inertial>
      <origin rpy="0 0 0" xyz="0.00000695 -0.00006402 0.01772685"/>
      <mass value="0.02821091"/>
      <inertia ixx="0.00000683" ixy="0.0" ixz="0.0" iyx="0.0" iyy="0.00000696" iyz="0.00000127" izx="0.0" izy="0.00000127" izz="0.0000028"/>
    </inertial>
    <collision>
      <origin rpy="0 0 0" xyz="0 0.00 0.0 "/>
      <geometry>
        <mesh filename="obj_meshes/pincette_distal_collider.obj"/>
      </geometry>
    </collision>
    <visual>
      <origin rpy="0 0 0" xyz="0 0 0 "/>
      <geometry>
        <mesh filename="obj_meshes/pincette_distal.obj"/>
      </geometry>
    </visual>
  </link>
  <joint name="r_hand_finger_distal_mimic" type="revolute">
    <origin rpy="0 0 0" xyz="0 0 0.049997"/>
    <parent link="r_hand_proximal_mimic_link"/>
    <child link="r_hand_distal_mimic_link"/>
    <axis xyz="1 0 0"/>
    <limit effort="100.0" lower="-0.51" upper="0.554" velocity="10.0"/>
    <!-- <mimic joint="${p}_finger_proximal" multiplier="-1" offset="0" /> -->
    <mimic joint="r_hand_finger" multiplier="0.4689" offset="-0.554"/>
    <dynamics damping="0.01" friction="0.1"/>
  </joint>
  <!-- <gazebo reference="${p}_finger_distal_link"> -->
  <!--   <selfCollide>false</selfCollide> -->
  <!-- </gazebo> -->
  <!-- <gazebo reference="${p}_finger_distal_link_mimic"> -->
  <!--   <selfCollide>false</selfCollide> -->
  <!-- </gazebo> -->
  <link name="r_arm_tip">
    <inertial>
      <origin rpy="0.0 0.0 0.0" xyz="0.0 0.0 0.0"/>
      <mass value="0.001"/>
      <inertia ixx="1.0e-6" ixy="1.0e-8" ixz="1.0e-8" iyy="1.0e-6" iyz="1.0e-8" izz="1.0e-6"/>
    </inertial>
  </link>
  <joint name="r_tip_joint" type="fixed">
    <!-- Rotated to be aligned with trunk in resting pos (elbows at -90) -->
    <!-- <origin xyz="-0.012 0 0.14432" rpy="${pi} ${-pi/2} 0" /> -->
    <!-- <origin xyz="-0.012 0 0.14432" rpy="${pi} 0 0" /> -->
    <!-- Aligned with trunk in zero position -->
    <!-- <origin xyz="-0.012 0 0.14432" rpy="${pi} 0 0" /> -->
    <!-- Hard coded in symbolic ik... -->
    <origin rpy="3.141592653589793 0 0" xyz="0.0 0 0.10"/>
    <parent link="r_hand_palm_link"/>
    <child link="r_arm_tip"/>
  </joint>
  <link name="r_arm_tip_bottom">
    <inertial>
      <origin rpy="0.0 0.0 0.0" xyz="0.0 0.0 0.0"/>
      <mass value="0.001"/>
      <inertia ixx="1.0e-6" ixy="1.0e-8" ixz="1.0e-8" iyy="1.0e-6" iyz="1.0e-8" izz="1.0e-6"/>
    </inertial>
  </link>
  <joint name="r_tip_joint_bottom" type="fixed">
    <!-- <origin xyz="-0.028 0 0.14432" rpy="${pi} ${-pi/2} 0" /> -->
    <origin rpy="3.141592653589793 0 0" xyz="-0.028 0 0.14432"/>
    <parent link="r_hand_palm_link"/>
    <child link="r_arm_tip_bottom"/>
  </joint>
  <!-- URDF definition is so stupid we have to do that... -->
  <!-- <material name="gripperblack"> -->
  <!--     <color rgba="0.4 0.4 0.4 1"/> -->
  <!-- </material> -->
  <!-- <material name="gripperwhite"> -->
  <!--     <color rgba="0.9 0.9 0.9 1"/> -->
  <!-- </material> -->
  <!-- <material name="reachy_yellow"> -->
  <!--     <color rgba="0.8 0.8 0.0 1"/> -->
  <!-- </material> -->
  <!-- <material name="reachy_grey"> -->
  <!--     <color rgba="0.8 0.8 0.8 1"/> -->
  <!-- </material> -->
  <!-- <material name="reachy_metal"> -->
  <!--     <color rgba="0.85 0.85 0.85 1.0"/> -->
  <!-- </material> -->
  <!-- <material name="torsoblack"> -->
  <!--     <color rgba="0.5 0.5 0.5 1.0"/> -->
  <!-- </material> -->
  <!-- <material name="eyewhite"> -->
  <!--     <color rgba="1.0 1.0 1.0 1.0"/> -->
  <!-- </material> -->
  <!-- <material name="orbita2dmetal"> -->
  <!--     <color rgba="0.85 0.85 0.85 1.0"/> -->
  <!-- </material> -->
  <!-- <material name="orbita2dgrey"> -->
  <!--     <color rgba="0.8 0.8 0.8 1.0"/> -->
  <!-- </material> -->
  <!-- <material name="orbita3d_yellow"> -->
  <!--     <color rgba="0.8 0.8 0.0 1"/> -->
  <!-- </material> -->
  <!-- <material name="orbita3d_grey"> -->
  <!--     <color rgba="0.8 0.8 0.8 1"/> -->
  <!-- </material> -->
  <!-- URDF definition is so stupid we have to do that... -->
  <!-- <material name="gripperblack"> -->
  <!--     <color rgba="0.4 0.4 0.4 1"/> -->
  <!-- </material> -->
  <!-- <material name="gripperwhite"> -->
  <!--     <color rgba="0.9 0.9 0.9 1"/> -->
  <!-- </material> -->
  <!-- <material name="reachy_yellow"> -->
  <!--     <color rgba="0.8 0.8 0.0 1"/> -->
  <!-- </material> -->
  <!-- <material name="reachy_grey"> -->
  <!--     <color rgba="0.8 0.8 0.8 1"/> -->
  <!-- </material> -->
  <!-- <material name="reachy_metal"> -->
  <!--     <color rgba="0.85 0.85 0.85 1.0"/> -->
  <!-- </material> -->
  <!-- <material name="torsoblack"> -->
  <!--     <color rgba="0.5 0.5 0.5 1.0"/> -->
  <!-- </material> -->
  <!-- <material name="eyewhite"> -->
  <!--     <color rgba="1.0 1.0 1.0 1.0"/> -->
  <!-- </material> -->
  <!-- <material name="orbita2dmetal"> -->
  <!--     <color rgba="0.85 0.85 0.85 1.0"/> -->
  <!-- </material> -->
  <!-- <material name="orbita2dgrey"> -->
  <!--     <color rgba="0.8 0.8 0.8 1.0"/> -->
  <!-- </material> -->
  <!-- <material name="orbita3d_yellow"> -->
  <!--     <color rgba="0.8 0.8 0.0 1"/> -->
  <!-- </material> -->
  <!-- <material name="orbita3d_grey"> -->
  <!--     <color rgba="0.8 0.8 0.8 1"/> -->
  <!-- </material> -->
  <!-- <xacro:include filename="$(find reachy_description)/ros2_control/arm.ros2_control.xacro" /> -->
  <!-- <!-\- Orbita2d config -\-> -->
  <!-- <xacro:arg name="orbita2d_shoulder_config" default="$(find
    orbita2d_description)/config/fake.yaml"/> -->
  <!-- <xacro:arg name="orbita2d_elbow_config" default="$(find
    orbita2d_description)/config/fake.yaml"/> -->
  <!-- <!-\- Orbita3d config -\-> -->
  <!-- <xacro:arg name="orbita3d_wrist_config" default="$(find
    orbita3d_controller)/config/fake.yaml"/> -->
  <!-- Define robot model argument -->
  <!-- -15 degrees -->
  <!-- ARM PARAMETERS -->
  <link name="l_shoulder_base_link">
    <inertial>
      <origin rpy="0.0 0.0 0.0" xyz="0.0 0.0 0.0"/>
      <mass value="0.001"/>
      <inertia ixx="1.0e-6" ixy="1.0e-8" ixz="1.0e-8" iyy="1.0e-6" iyz="1.0e-8" izz="1.0e-6"/>
    </inertial>
  </link>
  <joint name="l_shoulder_base_joint" type="fixed">
    <!-- <origin xyz="${arm_offset_x} ${arm_offset_y*reflect} ${arm_offset_z}"
      rpy="${(1.5707963267948966+(virtual_shoulder_roll_offset - arm_offset_roll))*reflect} 0
      ${arm_offset_yaw*reflect}" /> -->
    <origin rpy="-1.3089969389957472 0 -0.17453292519943295" xyz="0.0 0.2 0.0"/>
    <parent link="torso"/>
    <child link="l_shoulder_base_link"/>
  </joint>
  <!--
      Orbita 2 dof

    link                         (joint)

    ${parent}                    (${name}_dummy_1) fixed
      ${name}_dummy_link1        (${name}_dummy_2) fixed
        ${name}_dummy_link2      (${name}_joint1) revolute
          ${name}_first_link     (${name}_joint2) revolute
      	    ${name}_ball_link    (${name}_dummy_out) fixed
	      ${name}_fix_link


    -->
  <!-- used to "place" the joint with the correct axis. For some reason rotation of the inertia matrix does not work... -->
  <link name="l_shoulder_dummy_link1">
    <inertial>
      <origin rpy="0.0 0.0 0.0" xyz="0.0 0.0 0.0"/>
      <mass value="0.001"/>
      <inertia ixx="1.0e-6" ixy="1.0e-8" ixz="1.0e-8" iyy="1.0e-6" iyz="1.0e-8" izz="1.0e-6"/>
    </inertial>
  </link>
  <joint name="l_shoulder_dummy_1" type="fixed">
    <origin rpy="0 0 0" xyz="0 0 0"/>
    <parent link="l_shoulder_base_link"/>
    <child link="l_shoulder_dummy_link1"/>
  </joint>
  <link name="l_shoulder_dummy_link2">
    <inertial>
      <origin rpy="0.0 0.0 0.0" xyz="0.0 0.0 0.0"/>
      <mass value="0.001"/>
      <inertia ixx="1.0e-6" ixy="1.0e-8" ixz="1.0e-8" iyy="1.0e-6" iyz="1.0e-8" izz="1.0e-6"/>
    </inertial>
  </link>
  <!-- used to rotatate the joint to respect the conventional axis -->
  <joint name="l_shoulder_dummy_2" type="fixed">
    <origin rpy="1.5707963267948966 0 0" xyz="0 0 0"/>
    <!-- <origin xyz="0 0 0" rpy="0 0 0"/> -->
    <parent link="l_shoulder_dummy_link1"/>
    <child link="l_shoulder_dummy_link2"/>
  </joint>
  <link name="l_shoulder_first_link">
    <visual>
      <origin rpy="-1.5707963267948966 0 0" xyz="0 0 0"/>
      <geometry>
        <!-- <mesh filename="file://$(find arm_description)/meshes/Orbita2D_ball.obj" /> -->
        <mesh filename="obj_meshes/2D_sphere_visual.obj"/>
      </geometry>
    </visual>
    <!-- <collision> -->
    <!--   <geometry> -->
    <!--     <sphere radius="0.0425"/> -->
    <!--   </geometry> -->
    <!-- </collision> -->
    <inertial>
      <!-- <origin xyz="0.0 0 0" rpy="1.5707963267948966 0 0"/> -->
      <!-- rotation does not work? -->
      <origin rpy="0 0 0" xyz="0.000096 -0.000015 -0.01777"/>
      <mass value="0.487"/>
      <inertia ixx="0.000577881945" ixy="-8.085000000000001e-7" ixz="-6.962790000000001e-7" iyx="-8.085000000000001e-7" iyy="0.000573075516" iyz="2.44386e-7" izx="-6.962790000000001e-7" izy="2.44386e-7" izz="0.000243343676"/>
    </inertial>
  </link>
  <!-- First joint  -->
  <joint name="l_shoulder_pitch" type="revolute">
    <origin rpy="0 0 0" xyz="0 0 0"/>
    <!-- <parent link="${parent}"/> -->
    <parent link="l_shoulder_dummy_link2"/>
    <child link="l_shoulder_first_link"/>
    <axis xyz="0 1 0"/>
    <!-- <axis xyz="0 0 -1"/> -->
    <limit effort="1000.0" lower="-3.141592653589793" upper="3.141592653589793" velocity="100.0"/>
    <safety_controller k_position="500" k_velocity="500" soft_lower_limit="-3.141592" soft_upper_limit="3.1415"/>
    <dynamics damping="0.01" friction="0.1"/>
  </joint>
  <!-- <!-\- Used to get back to the correct orientation -\-> -->
  <!-- <link name="${name}_dummy_link3"> -->
  <!-- </link> -->
  <!-- <joint name="${name}_dummy_3" type="fixed"> -->
  <!--   <!-\- <origin xyz="0 0 0" rpy="-1.5707963267948966 0 0"/> -\-> -->
  <!--   <origin xyz="0 0 0" rpy="3.141592653589793 0 0"/> -->
  <!--   <parent link="${name}_first_link"/> -->
  <!--   <child link="${name}_dummy_link3"/> -->
  <!-- </joint> -->
  <!-- Output link -->
  <link name="l_shoulder_ball_link">
    <inertial>
      <origin rpy="0.0 0.0 0.0" xyz="0.0 0.0 0.0"/>
      <mass value="0.001"/>
      <inertia ixx="1.0e-6" ixy="1.0e-8" ixz="1.0e-8" iyy="1.0e-6" iyz="1.0e-8" izz="1.0e-6"/>
    </inertial>
  </link>
  <joint name="l_shoulder_roll" type="revolute">
    <origin rpy=" 0 0 0" xyz="0 0 0"/>
    <parent link="l_shoulder_first_link"/>
    <child link="l_shoulder_ball_link"/>
    <axis xyz="1 0 0"/>
    <!-- <axis xyz="1 0 0"/> -->
    <limit effort="1000.0" lower="-0.0" upper="3.141592653589793" velocity="100.0"/>
    <safety_controller k_position="500" k_velocity="500" soft_lower_limit="-3.1415" soft_upper_limit="3.1415"/>
    <dynamics damping="0.01" friction="0.1"/>
  </joint>
  <link name="l_shoulder_fix_link">
    <inertial>
      <origin rpy="0.0 0.0 0.0" xyz="0.0 0.0 0.0"/>
      <mass value="0.001"/>
      <inertia ixx="1.0e-6" ixy="1.0e-8" ixz="1.0e-8" iyy="1.0e-6" iyz="1.0e-8" izz="1.0e-6"/>
    </inertial>
  </link>
  <!-- used to rotate the joint to respect the conventional axis -->
  <joint name="l_shoulder_dummy_out" type="fixed">
    <origin rpy="1.5707963267948966 0 0" xyz="0 0 0"/>
    <!-- <origin xyz="0 0 0" rpy="0 0 0"/> -->
    <parent link="l_shoulder_ball_link"/>
    <child link="l_shoulder_fix_link"/>
  </joint>
  <ros2_control name="l_shoulder" type="system">
    <hardware>
      <!-- Standard ROS fake system -->
      <!-- <plugin>fake_components/GenericSystem</plugin> -->
      <!-- Pollen controller fake system -->
      <plugin>orbita2d_system_hwi/Orbita2dSystem</plugin>
      <param name="config_file">/home/reachy/reachy_ws/install/orbita2d_description/share/orbita2d_description/config/fake.yaml</param>
    </hardware>
    <gpio name="l_shoulder">
      <state_interface name="torque">
        <param name="initial_value">0.0</param>
      </state_interface>
      <state_interface name="errors"/>
      <command_interface name="torque"/>
    </gpio>
    <joint name="l_shoulder_pitch">
      <state_interface name="position">
        <param name="initial_value">0.0</param>
      </state_interface>
      <state_interface name="velocity">
        <param name="initial_value">0.0</param>
      </state_interface>
      <state_interface name="effort">
        <param name="initial_value">0.0</param>
      </state_interface>
      <command_interface name="position"/>
    </joint>
    <joint name="l_shoulder_roll">
      <state_interface name="position">
        <param name="initial_value">0.0</param>
      </state_interface>
      <state_interface name="velocity">
        <param name="initial_value">0.0</param>
      </state_interface>
      <state_interface name="effort">
        <param name="initial_value">0.0</param>
      </state_interface>
      <command_interface name="position"/>
    </joint>
    <gpio name="l_shoulder_raw_motor_1">
      <state_interface name="speed_limit"/>
      <command_interface name="speed_limit"/>
      <state_interface name="torque_limit"/>
      <command_interface name="torque_limit"/>
      <state_interface name="p_gain"/>
      <command_interface name="p_gain"/>
      <state_interface name="i_gain"/>
      <command_interface name="i_gain"/>
      <state_interface name="d_gain"/>
      <command_interface name="d_gain"/>
      <state_interface name="motor_temperature"/>
      <state_interface name="board_temperature"/>
      <state_interface name="motor_currents"/>
      <state_interface name="motor_velocities"/>
    </gpio>
    <gpio name="l_shoulder_raw_motor_2">
      <state_interface name="speed_limit"/>
      <command_interface name="speed_limit"/>
      <state_interface name="torque_limit"/>
      <command_interface name="torque_limit"/>
      <state_interface name="p_gain"/>
      <command_interface name="p_gain"/>
      <state_interface name="i_gain"/>
      <command_interface name="i_gain"/>
      <state_interface name="d_gain"/>
      <command_interface name="d_gain"/>
      <state_interface name="motor_temperature"/>
      <state_interface name="board_temperature"/>
      <state_interface name="motor_currents"/>
      <state_interface name="motor_velocities"/>
    </gpio>
  </ros2_control>
  <link name="l_elbow_arm_link">
    <visual>
      <origin rpy="0 0 0" xyz="0 0 0"/>
      <geometry>
        <!-- <mesh filename="package://arm_description/meshes/upper_arm_visual.obj" /> -->
        <mesh filename="obj_meshes/upper_arm_visual.obj"/>
      </geometry>
    </visual>
    <collision>
      <!-- <origin xyz="0 0 ${arm_length/2}" rpy="0 0 0"/> -->
      <origin rpy="0 0 0" xyz="0 0 0"/>
      <geometry>
        <!-- <mesh filename="package://arm_description/meshes/upper_arm_collider.obj" /> -->
        <mesh filename="obj_meshes/upper_arm_collider.obj"/>
      </geometry>
    </collision>
    <inertial>
      <origin rpy="0 0 0" xyz="-0.000669 0.000509 0.144798"/>
      <mass value="1.620"/>
      <inertia ixx="0.007864" ixy="0.000005410021" ixz="-0.000117782969" iyx="0.000005410021" iyy="0.006998" iyz="0.000121931452" izx="-0.000117782969" izy="0.000121931452" izz="0.001828"/>
    </inertial>
  </link>
  <joint name="l_elbow_arm_joint" type="fixed">
    <origin rpy="0 -1.5707963267948966 1.5707963267948966" xyz="0 0 0.0"/>
    <!-- <origin xyz="0 0 0.0" rpy="0 0 0" /> -->
    <!-- <parent link="${p}_shoulder_ball_link" /> -->
    <parent link="l_shoulder_fix_link"/>
    <child link="l_elbow_arm_link"/>
  </joint>
  <link name="l_elbow_base_link">
    <inertial>
      <origin rpy="0.0 0.0 0.0" xyz="0.0 0.0 0.0"/>
      <mass value="0.001"/>
      <inertia ixx="1.0e-6" ixy="1.0e-8" ixz="1.0e-8" iyy="1.0e-6" iyz="1.0e-8" izz="1.0e-6"/>
    </inertial>
  </link>
  <!-- <joint name="${prefix}_elbow_base_joint" type="fixed"> -->
  <!--   <origin xyz="0 0 0" rpy="0 ${(1.5707963267948966 + virtual_elbow_offset_yaw)*reflect} 0" /> -->
  <!--   <parent link="${p}_shoulder_ball_link" /> -->
  <!--   <child link="${prefix}_elbow_base_link" /> -->
  <!-- </joint> -->
  <!-- <xacro:orbita2d -->
  <!--   name="${p}_elbow" parent="${prefix}_elbow_base_link" -->
  <!--   length="${forearm_length}" radius="${forearm_radius}" mass="${forearm_mass}" -->
  <!--   xyz="0 -${arm_length} 0" rpy="${1.5707963267948966} 0 0" -->
  <!--   damping="${damping}" friction="${friction}" -->
  <!--   joint1="yaw" joint2="pitch" -->
  <!--   joint1_min_angle="-${pi/2}" joint1_max_angle="${pi/2}" -->
  <!--   joint2_min_angle="-2.25" joint2_max_angle="0.1" -->
  <!-- /> -->
  <joint name="l_elbow_base_joint" type="fixed">
    <origin rpy="0 0 0" xyz="0 0 0.28"/>
    <parent link="l_elbow_arm_link"/>
    <child link="l_elbow_base_link"/>
  </joint>
  <!--
      Orbita 2 dof

    link                         (joint)

    ${parent}                    (${name}_dummy_1) fixed
      ${name}_dummy_link1        (${name}_dummy_2) fixed
        ${name}_dummy_link2      (${name}_joint1) revolute
          ${name}_first_link     (${name}_joint2) revolute
      	    ${name}_ball_link    (${name}_dummy_out) fixed
	      ${name}_fix_link


    -->
  <!-- used to "place" the joint with the correct axis. For some reason rotation of the inertia matrix does not work... -->
  <link name="l_elbow_dummy_link1">
    <inertial>
      <origin rpy="0.0 0.0 0.0" xyz="0.0 0.0 0.0"/>
      <mass value="0.001"/>
      <inertia ixx="1.0e-6" ixy="1.0e-8" ixz="1.0e-8" iyy="1.0e-6" iyz="1.0e-8" izz="1.0e-6"/>
    </inertial>
  </link>
  <joint name="l_elbow_dummy_1" type="fixed">
    <origin rpy="0 0 0" xyz="0 0 0"/>
    <parent link="l_elbow_base_link"/>
    <child link="l_elbow_dummy_link1"/>
  </joint>
  <link name="l_elbow_dummy_link2">
    <inertial>
      <origin rpy="0.0 0.0 0.0" xyz="0.0 0.0 0.0"/>
      <mass value="0.001"/>
      <inertia ixx="1.0e-6" ixy="1.0e-8" ixz="1.0e-8" iyy="1.0e-6" iyz="1.0e-8" izz="1.0e-6"/>
    </inertial>
  </link>
  <!-- used to rotatate the joint to respect the conventional axis -->
  <joint name="l_elbow_dummy_2" type="fixed">
    <origin rpy="3.141592 0 -1.5707963267948966" xyz="0 0 0"/>
    <!-- <origin xyz="0 0 0" rpy="0 0 0"/> -->
    <parent link="l_elbow_dummy_link1"/>
    <child link="l_elbow_dummy_link2"/>
  </joint>
  <link name="l_elbow_first_link">
    <visual>
      <origin rpy="3.141592 0 1.5707963267948966" xyz="0 0 0"/>
      <geometry>
        <!-- <mesh filename="file://$(find arm_description)/meshes/Orbita2D_ball.obj" /> -->
        <mesh filename="obj_meshes/2D_sphere_visual.obj"/>
      </geometry>
    </visual>
    <!-- <collision> -->
    <!--   <geometry> -->
    <!--     <sphere radius="0.0425"/> -->
    <!--   </geometry> -->
    <!-- </collision> -->
    <inertial>
      <!-- <origin xyz="0.0 0 0" rpy="1.5707963267948966 0 0"/> -->
      <!-- rotation does not work? -->
      <origin rpy="0 0 0" xyz="0.000096 -0.000015 -0.01777"/>
      <mass value="0.487"/>
      <inertia ixx="0.000577881945" ixy="-8.085000000000001e-7" ixz="-6.962790000000001e-7" iyx="-8.085000000000001e-7" iyy="0.000573075516" iyz="2.44386e-7" izx="-6.962790000000001e-7" izy="2.44386e-7" izz="0.000243343676"/>
    </inertial>
  </link>
  <!-- First joint  -->
  <joint name="l_elbow_yaw" type="revolute">
    <origin rpy="0 0 0" xyz="0 0 0"/>
    <!-- <parent link="${parent}"/> -->
    <parent link="l_elbow_dummy_link2"/>
    <child link="l_elbow_first_link"/>
    <axis xyz="0 0 1"/>
    <!-- <axis xyz="0 0 -1"/> -->
    <limit effort="1000.0" lower="-3.141592653589793" upper="3.141592653589793" velocity="100.0"/>
    <safety_controller k_position="500" k_velocity="500" soft_lower_limit="-3.141592" soft_upper_limit="3.1415"/>
    <dynamics damping="0.01" friction="0.1"/>
  </joint>
  <!-- <!-\- Used to get back to the correct orientation -\-> -->
  <!-- <link name="${name}_dummy_link3"> -->
  <!-- </link> -->
  <!-- <joint name="${name}_dummy_3" type="fixed"> -->
  <!--   <!-\- <origin xyz="0 0 0" rpy="-1.5707963267948966 0 0"/> -\-> -->
  <!--   <origin xyz="0 0 0" rpy="3.141592653589793 0 0"/> -->
  <!--   <parent link="${name}_first_link"/> -->
  <!--   <child link="${name}_dummy_link3"/> -->
  <!-- </joint> -->
  <!-- Output link -->
  <link name="l_elbow_ball_link">
    <inertial>
      <origin rpy="0.0 0.0 0.0" xyz="0.0 0.0 0.0"/>
      <mass value="0.001"/>
      <inertia ixx="1.0e-6" ixy="1.0e-8" ixz="1.0e-8" iyy="1.0e-6" iyz="1.0e-8" izz="1.0e-6"/>
    </inertial>
  </link>
  <joint name="l_elbow_pitch" type="revolute">
    <origin rpy=" 0 0 0" xyz="0 0 0"/>
    <parent link="l_elbow_first_link"/>
    <child link="l_elbow_ball_link"/>
    <axis xyz="0 1 0"/>
    <!-- <axis xyz="1 0 0"/> -->
    <limit effort="1000.0" lower="-2.25" upper="0.1" velocity="100.0"/>
    <safety_controller k_position="500" k_velocity="500" soft_lower_limit="-3.1415" soft_upper_limit="3.1415"/>
    <dynamics damping="0.01" friction="0.1"/>
  </joint>
  <link name="l_elbow_fix_link">
    <inertial>
      <origin rpy="0.0 0.0 0.0" xyz="0.0 0.0 0.0"/>
      <mass value="0.001"/>
      <inertia ixx="1.0e-6" ixy="1.0e-8" ixz="1.0e-8" iyy="1.0e-6" iyz="1.0e-8" izz="1.0e-6"/>
    </inertial>
  </link>
  <!-- used to rotate the joint to respect the conventional axis -->
  <joint name="l_elbow_dummy_out" type="fixed">
    <origin rpy="3.141592 0 1.5707963267948966" xyz="0 0 0"/>
    <!-- <origin xyz="0 0 0" rpy="0 0 0"/> -->
    <parent link="l_elbow_ball_link"/>
    <child link="l_elbow_fix_link"/>
  </joint>
  <ros2_control name="l_elbow" type="system">
    <hardware>
      <!-- Standard ROS fake system -->
      <!-- <plugin>fake_components/GenericSystem</plugin> -->
      <!-- Pollen controller fake system -->
      <plugin>orbita2d_system_hwi/Orbita2dSystem</plugin>
      <param name="config_file">/home/reachy/reachy_ws/install/orbita2d_description/share/orbita2d_description/config/fake.yaml</param>
    </hardware>
    <gpio name="l_elbow">
      <state_interface name="torque">
        <param name="initial_value">0.0</param>
      </state_interface>
      <state_interface name="errors"/>
      <command_interface name="torque"/>
    </gpio>
    <joint name="l_elbow_yaw">
      <state_interface name="position">
        <param name="initial_value">0.0</param>
      </state_interface>
      <state_interface name="velocity">
        <param name="initial_value">0.0</param>
      </state_interface>
      <state_interface name="effort">
        <param name="initial_value">0.0</param>
      </state_interface>
      <command_interface name="position"/>
    </joint>
    <joint name="l_elbow_pitch">
      <state_interface name="position">
        <param name="initial_value">0.0</param>
      </state_interface>
      <state_interface name="velocity">
        <param name="initial_value">0.0</param>
      </state_interface>
      <state_interface name="effort">
        <param name="initial_value">0.0</param>
      </state_interface>
      <command_interface name="position"/>
    </joint>
    <gpio name="l_elbow_raw_motor_1">
      <state_interface name="speed_limit"/>
      <command_interface name="speed_limit"/>
      <state_interface name="torque_limit"/>
      <command_interface name="torque_limit"/>
      <state_interface name="p_gain"/>
      <command_interface name="p_gain"/>
      <state_interface name="i_gain"/>
      <command_interface name="i_gain"/>
      <state_interface name="d_gain"/>
      <command_interface name="d_gain"/>
      <state_interface name="motor_temperature"/>
      <state_interface name="board_temperature"/>
      <state_interface name="motor_currents"/>
      <state_interface name="motor_velocities"/>
    </gpio>
    <gpio name="l_elbow_raw_motor_2">
      <state_interface name="speed_limit"/>
      <command_interface name="speed_limit"/>
      <state_interface name="torque_limit"/>
      <command_interface name="torque_limit"/>
      <state_interface name="p_gain"/>
      <command_interface name="p_gain"/>
      <state_interface name="i_gain"/>
      <command_interface name="i_gain"/>
      <state_interface name="d_gain"/>
      <command_interface name="d_gain"/>
      <state_interface name="motor_temperature"/>
      <state_interface name="board_temperature"/>
      <state_interface name="motor_currents"/>
      <state_interface name="motor_velocities"/>
    </gpio>
  </ros2_control>
  <!-- <link name="${prefix}_elbow_forearm_link"> -->
  <!--   <visual> -->
  <!--   	<origin xyz="0 0 0" rpy="0 0 0"/> -->
  <!--   	<geometry> -->
  <!-- 	  <mesh filename="package://arm_description/meshes/Orbita2D_forearm.obj" /> -->
  <!--   	</geometry> -->
  <!--   </visual> -->
  <!--   <inertial> -->
  <!--   	<origin xyz="0.00092892 -0.00254548 0.14021211" rpy="0 0 0"/> -->
  <!-- 	<mass value="0.90719109"/> -->
  <!-- 	 <inertia ixx="0.00428278" ixy="-0.00000203" ixz="0.00011755" -->
  <!-- 		  iyx="-0.00000203" iyy="0.0044585" iyz="-0.00004915" -->
  <!-- 		  izx="0.00011755" izy="-0.00004915" izz="0.00047615"/> -->
  <!--   </inertial> -->
  <!-- </link> -->
  <!-- <joint name="${prefix}_elbow_forearm_joint" type="fixed"> -->
  <!--   <origin xyz="0 0 0.0" rpy="0 0 0" /> -->
  <!--   <parent link="${p}_elbow_ball_link" /> -->
  <!--   <child link="${prefix}_elbow_forearm_link" /> -->
  <!-- </joint> -->
  <link name="l_elbow_forearm_link">
    <visual>
      <origin rpy="0 0 0" xyz="0 0 0"/>
      <geometry>
        <!-- <mesh filename="package://arm_description/meshes/forearm_visual.obj" /> -->
        <mesh filename="obj_meshes/forearm_visual.obj"/>
      </geometry>
    </visual>
    <collision>
      <origin rpy="0 0 0" xyz="0 0 0"/>
      <!-- <origin xyz="0 0 ${forearm_length/2}" rpy="0 0 0"/> -->
      <geometry>
        <!-- <mesh filename="package://arm_description/meshes/forearm_collider.obj" /> -->
        <mesh filename="obj_meshes/forearm_collider.obj"/>
      </geometry>
    </collision>
    <inertial>
      <origin rpy="0 0 0" xyz="0.00092892 -0.00254548 0.14021211"/>
      <mass value="0.90719109"/>
      <inertia ixx="0.00428278" ixy="-0.00000203" ixz="0.00011755" iyx="-0.00000203" iyy="0.0044585" iyz="-0.00004915" izx="0.00011755" izy="-0.00004915" izz="0.00047615"/>
    </inertial>
  </link>
  <joint name="l_elbow_forearm_joint" type="fixed">
    <origin rpy="0 0 0" xyz="0 0 0.0"/>
    <!-- <parent link="${p}_elbow_ball_link" /> -->
    <parent link="l_elbow_fix_link"/>
    <child link="l_elbow_forearm_link"/>
  </joint>
  <!-- <xacro:orbita3d -->
  <!--   name="${p}_wrist" parent="${p}_elbow_ball_link" -->
  <!--   length="${wrist_length}" radius="${wrist_radius}" mass="${wrist_mass}" -->
  <!--   xyz="0 0 ${forearm_length}" rpy="${pi} 0 0" -->
  <!--   damping="${damping}" friction="${friction}" -->
  <!-- /> -->
  <!--
      Orbita3d

    link                         (joint)

    ${parent}                    (${name}_base_joint) fixed
      ${name}_base_link          (${name}_roll) revolute
        ${name}_dummy_link1      (${name}_pitch) revolute
          ${name}_dummy_link2    (${name}_yaw) revolute
            ${name}_link         (${name}_ball_joint) fixed
              ${name}_ball_link
    -->
  <link name="l_wrist_dummy_link1">
    <inertial>
      <mass value="0.001"/>
      <origin rpy="0 0 0" xyz="0 0 0"/>
      <inertia ixx="1.4166666666666668e-07" ixy="0.0" ixz="0.0" iyy="1.4166666666666668e-07" iyz="0.0" izz="2.6666666666666667e-07"/>
    </inertial>
  </link>
  <link name="l_wrist_dummy_link2">
    <inertial>
      <mass value="0.001"/>
      <origin rpy="0 0 0" xyz="0 0 0"/>
      <inertia ixx="1.4166666666666668e-07" ixy="0.0" ixz="0.0" iyy="1.4166666666666668e-07" iyz="0.0" izz="2.6666666666666667e-07"/>
    </inertial>
  </link>
  <link name="l_wrist_link">
    <!-- <visual> -->
    <!-- 	<origin xyz="0 0 0" rpy="0 0 0"/> -->
    <!-- 	<geometry> -->
    <!--     <cylinder length="${length}" radius="${radius}"/> -->
    <!-- 	</geometry> -->
    <!-- 	<xacro:orbita3d_grey/> -->
    <!-- </visual> -->
    <!-- <collision> -->
    <!-- 	<origin xyz="0 0 ${length/2}" rpy="0 0 0"/> -->
    <!-- 	<geometry> -->
    <!--     <cylinder length="${length}" radius="${radius}"/> -->
    <!-- 	</geometry> -->
    <!-- </collision> -->
    <inertial>
      <mass value="0.098"/>
      <origin rpy="0 0 0" xyz="0 0 -0.005"/>
      <inertia ixx="1.3883333333333335e-05" ixy="0.0" ixz="0.0" iyy="1.3883333333333335e-05" iyz="0.0" izz="2.6133333333333336e-05"/>
    </inertial>
  </link>
  <link name="l_wrist_ball_link">
    <!-- <visual> -->
    <!-- 	<origin xyz="0 0 0" rpy="0 0 0"/> -->
    <!-- 	<geometry> -->
    <!--     <sphere radius="${radius*1.2}"/> -->
    <!-- 	</geometry> -->
    <!-- 	<xacro:orbita3d_grey/> -->
    <!-- </visual> -->
    <!-- <collision> -->
    <!-- 	<origin xyz="0 0 0" rpy="0 0 0"/> -->
    <!-- 	<geometry> -->
    <!--     <sphere radius="${radius*1.2}"/> -->
    <!-- 	</geometry> -->
    <!-- </collision> -->
    <!-- <xacro:inertial_sphere mass="${mass*0.5}" diameter="${2*radius*1.2}"/> -->
    <inertial>
      <origin rpy="0.0 0.0 0.0" xyz="0.0 0.0 0.0"/>
      <mass value="0.001"/>
      <inertia ixx="1.0e-6" ixy="1.0e-8" ixz="1.0e-8" iyy="1.0e-6" iyz="1.0e-8" izz="1.0e-6"/>
    </inertial>
  </link>
  <joint name="l_wrist_ball_joint" type="fixed">
    <origin rpy="0 0 0" xyz="0 0 0"/>
    <parent link="l_wrist_link"/>
    <child link="l_wrist_ball_link"/>
  </joint>
  <link name="l_wrist_base_link">
    <!-- <visual> -->
    <!-- 	<origin xyz="0 0 0.0672" rpy="0 0 0"/> -->
    <!-- 	<geometry> -->
    <!--     <cylinder radius="0.0278" length="0.0336"/> -->
    <!-- 	</geometry> -->
    <!-- 	<xacro:orbita3d_grey/> -->
    <!-- </visual> -->
    <inertial>
      <origin rpy="0.0 0.0 0.0" xyz="0.0 0.0 0.0"/>
      <mass value="0.001"/>
      <inertia ixx="1.0e-6" ixy="1.0e-8" ixz="1.0e-8" iyy="1.0e-6" iyz="1.0e-8" izz="1.0e-6"/>
    </inertial>
  </link>
  <joint name="l_wrist_base_joint" type="fixed">
    <origin rpy="3.141592 0 1.5707963267948966" xyz="0 0 0.28"/>
    <parent link="l_elbow_forearm_link"/>
    <child link="l_wrist_base_link"/>
  </joint>
  <link name="l_wrist_out_link">
    <inertial>
      <origin rpy="0.0 0.0 0.0" xyz="0.0 0.0 0.0"/>
      <mass value="0.001"/>
      <inertia ixx="1.0e-6" ixy="1.0e-8" ixz="1.0e-8" iyy="1.0e-6" iyz="1.0e-8" izz="1.0e-6"/>
    </inertial>
  </link>
  <joint name="l_wrist_out_joint" type="fixed">
    <origin rpy="3.141592 0 0" xyz="0 0 0"/>
    <parent link="l_wrist_ball_link"/>
    <child link="l_wrist_out_link"/>
  </joint>
  <joint name="l_wrist_roll" type="revolute">
    <!-- <origin xyz="${xyz}" rpy="${rpy}"/> -->
    <origin rpy="0 0 0" xyz="0 0 0"/>
    <!-- <parent link="${parent}"/> -->
    <parent link="l_wrist_base_link"/>
    <child link="l_wrist_dummy_link1"/>
    <axis xyz="1 0 0"/>
    <limit effort="1000.0" lower="-0.35" upper="0.35" velocity="100.0"/>
    <dynamics damping="0.01" friction="0.1"/>
  </joint>
  <joint name="l_wrist_pitch" type="revolute">
    <origin rpy="0 0 0" xyz="0 0 0"/>
    <parent link="l_wrist_dummy_link1"/>
    <child link="l_wrist_dummy_link2"/>
    <axis xyz="0 1 0"/>
    <limit effort="1000.0" lower="-0.35" upper="0.35" velocity="100.0"/>
    <dynamics damping="0.01" friction="0.1"/>
  </joint>
  <joint name="l_wrist_yaw" type="revolute">
    <origin rpy="0 0 0" xyz="0 0 0"/>
    <parent link="l_wrist_dummy_link2"/>
    <child link="l_wrist_link"/>
    <axis xyz="0 0 1"/>
    <limit effort="1000.0" lower="-1.57" upper="1.57" velocity="100.0"/>
    <dynamics damping="0.01" friction="0.1"/>
  </joint>
  <ros2_control name="l_wrist" type="system">
    <hardware>
      <!-- Standard ROS fake system -->
      <!-- <plugin>fake_components/GenericSystem</plugin> -->
      <!-- Pollen controller fake system -->
      <plugin>orbita3d_system_hwi/Orbita3dSystem</plugin>
      <param name="config_file">/home/reachy/reachy_ws/install/orbita3d_description/share/orbita3d_description/config/fake.yaml</param>
    </hardware>
    <gpio name="l_wrist">
      <state_interface name="torque">
        <param name="initial_value">0.0</param>
      </state_interface>
      <state_interface name="errors"/>
      <command_interface name="torque"/>
    </gpio>
    <joint name="l_wrist_roll">
      <state_interface name="position">
        <param name="initial_value">0.0</param>
      </state_interface>
      <state_interface name="velocity">
        <param name="initial_value">0.0</param>
      </state_interface>
      <state_interface name="effort">
        <param name="initial_value">0.0</param>
      </state_interface>
      <command_interface name="position"/>
    </joint>
    <joint name="l_wrist_pitch">
      <state_interface name="position">
        <param name="initial_value">0.0</param>
      </state_interface>
      <state_interface name="velocity">
        <param name="initial_value">0.0</param>
      </state_interface>
      <state_interface name="effort">
        <param name="initial_value">0.0</param>
      </state_interface>
      <command_interface name="position"/>
    </joint>
    <joint name="l_wrist_yaw">
      <state_interface name="position">
        <param name="initial_value">0.0</param>
      </state_interface>
      <state_interface name="velocity">
        <param name="initial_value">0.0</param>
      </state_interface>
      <state_interface name="effort">
        <param name="initial_value">0.0</param>
      </state_interface>
      <command_interface name="position"/>
    </joint>
    <gpio name="l_wrist_raw_motor_1">
      <state_interface name="speed_limit"/>
      <command_interface name="speed_limit"/>
      <state_interface name="torque_limit"/>
      <command_interface name="torque_limit"/>
      <state_interface name="p_gain"/>
      <command_interface name="p_gain"/>
      <state_interface name="i_gain"/>
      <command_interface name="i_gain"/>
      <state_interface name="d_gain"/>
      <command_interface name="d_gain"/>
      <state_interface name="motor_temperature"/>
      <state_interface name="board_temperature"/>
      <state_interface name="motor_currents"/>
      <state_interface name="motor_velocities"/>
    </gpio>
    <gpio name="l_wrist_raw_motor_2">
      <state_interface name="speed_limit"/>
      <command_interface name="speed_limit"/>
      <state_interface name="torque_limit"/>
      <command_interface name="torque_limit"/>
      <state_interface name="p_gain"/>
      <command_interface name="p_gain"/>
      <state_interface name="i_gain"/>
      <command_interface name="i_gain"/>
      <state_interface name="d_gain"/>
      <command_interface name="d_gain"/>
      <state_interface name="motor_temperature"/>
      <state_interface name="board_temperature"/>
      <state_interface name="motor_currents"/>
      <state_interface name="motor_velocities"/>
    </gpio>
    <gpio name="l_wrist_raw_motor_3">
      <state_interface name="speed_limit"/>
      <command_interface name="speed_limit"/>
      <state_interface name="torque_limit"/>
      <command_interface name="torque_limit"/>
      <state_interface name="p_gain"/>
      <command_interface name="p_gain"/>
      <state_interface name="i_gain"/>
      <command_interface name="i_gain"/>
      <state_interface name="d_gain"/>
      <command_interface name="d_gain"/>
      <state_interface name="motor_temperature"/>
      <state_interface name="board_temperature"/>
      <state_interface name="motor_currents"/>
      <state_interface name="motor_velocities"/>
    </gpio>
  </ros2_control>
  <!-- <xacro:arm_control name="${p}_arm" prefix="${p}" config_file="${config_file}" /> -->
  <!-- <xacro:orbita2d_control name="${p}_shoulder" config_file="${shoulder_config_file}" /> -->
  <!-- <xacro:orbita2d_control name="${p}_elbow" config_file="${elbow_config_file}" /> -->
  <!-- <xacro:orbita3d_control name="${p}_wrist" config_file="${wrist_config_file}" /> -->
  <!-- URDF definition is so stupid we have to do that... -->
  <!-- <material name="gripperblack"> -->
  <!--     <color rgba="0.4 0.4 0.4 1"/> -->
  <!-- </material> -->
  <!-- <material name="gripperwhite"> -->
  <!--     <color rgba="0.9 0.9 0.9 1"/> -->
  <!-- </material> -->
  <!-- <material name="reachy_yellow"> -->
  <!--     <color rgba="0.8 0.8 0.0 1"/> -->
  <!-- </material> -->
  <!-- <material name="reachy_grey"> -->
  <!--     <color rgba="0.8 0.8 0.8 1"/> -->
  <!-- </material> -->
  <!-- <material name="reachy_metal"> -->
  <!--     <color rgba="0.85 0.85 0.85 1.0"/> -->
  <!-- </material> -->
  <!-- <material name="torsoblack"> -->
  <!--     <color rgba="0.5 0.5 0.5 1.0"/> -->
  <!-- </material> -->
  <!-- <material name="eyewhite"> -->
  <!--     <color rgba="1.0 1.0 1.0 1.0"/> -->
  <!-- </material> -->
  <!-- <material name="orbita2dmetal"> -->
  <!--     <color rgba="0.85 0.85 0.85 1.0"/> -->
  <!-- </material> -->
  <!-- <material name="orbita2dgrey"> -->
  <!--     <color rgba="0.8 0.8 0.8 1.0"/> -->
  <!-- </material> -->
  <!-- <material name="orbita3d_yellow"> -->
  <!--     <color rgba="0.8 0.8 0.0 1"/> -->
  <!-- </material> -->
  <!-- <material name="orbita3d_grey"> -->
  <!--     <color rgba="0.8 0.8 0.8 1"/> -->
  <!-- </material> -->
  <!-- <material name="gripperblack"> -->
  <!--     <color rgba="0.4 0.4 0.4 1"/> -->
  <!-- </material> -->
  <!-- <material name="gripperwhite"> -->
  <!--     <color rgba="0.9 0.9 0.9 1"/> -->
  <!-- </material> -->
  <link name="l_hand_palm_link">
    <collision>
      <origin rpy="0 0 0" xyz="0 0 0.0 "/>
      <geometry>
        <!-- <mesh filename="file://$(find dynamixel_description)/meshes/pincette_right_collider.obj" /> -->
        <mesh filename="obj_meshes/pincette_base_collider.obj"/>
      </geometry>
    </collision>
    <visual>
      <origin rpy="0 0 0" xyz="0 0 0"/>
      <geometry>
        <!-- <mesh filename="file://$(find dynamixel_description)/meshes/pincette_right_visual.obj" /> -->
        <mesh filename="obj_meshes/pincette_base_visual.obj"/>
      </geometry>
    </visual>
    <inertial>
      <origin rpy="0 0 0" xyz="0.0070087 0.00974766 0.04392328"/>
      <mass value="0.30798029"/>
      <inertia ixx="0.00021928" ixy="-0.00003149" ixz="-0.00001759" iyx="-0.00003149" iyy="0.00016859" iyz="-0.00001396" izx="-0.00001759" izy="-0.00001396" izz="0.0002333"/>
    </inertial>
  </link>
  <joint name="l_hand_palm" type="fixed">
    <origin rpy="0.0 0 0" xyz="0 0 0"/>
    <parent link="l_wrist_out_link"/>
    <child link="l_hand_palm_link"/>
  </joint>
  <link name="l_hand_virtual_gripper_link">
    <!-- <inertial> -->
    <!--   <origin xyz="0.0 0.0 0.0" rpy="0.0 0.0 0.0"/> -->
    <!--   <mass value="0.01"/> -->
    <!--   <inertia ixx="1.0e-6" ixy="1.0e-8" ixz="1.0e-8" iyy="1.0e-6" iyz="1.0e-8" izz="1.0e-6"/> -->
    <!-- </inertial> -->
    <inertial>
      <mass value="0.01"/>
      <origin rpy="0 0 0" xyz="0 0 0"/>
      <inertia ixx="1.666666666666667e-07" ixy="0.0" ixz="0.0" iyy="1.666666666666667e-07" iyz="0.0" izz="1.666666666666667e-07"/>
    </inertial>
  </link>
  <joint name="l_hand_finger" type="revolute">
    <origin rpy="0 0 0" xyz="0.0 0.0 0.070028"/>
    <parent link="l_hand_palm_link"/>
    <child link="l_hand_virtual_gripper_link"/>
    <axis xyz="1 0 0"/>
    <limit effort="100.0" lower="0.0" upper="2.27" velocity="10.0"/>
    <dynamics damping="0.01" friction="0.1"/>
  </joint>
  <link name="l_hand_proximal_link">
    <inertial>
      <origin rpy="0 0 0" xyz="0.00004101 0.002756 0.019654"/>
      <mass value="0.03926395"/>
      <inertia ixx="0.00001937" ixy="0.0" ixz="0.00000007" iyx="0.0" iyy="0.00002003" iyz="0.00000036" izx="0.00000007" izy="0.00000036" izz="0.00000463"/>
    </inertial>
    <collision>
      <origin rpy="0 0 0" xyz="0 0.00 0.0 "/>
      <geometry>
        <!-- <mesh filename="file://$(find arm_description)/meshes/pincette_proximal_collider.obj" /> -->
        <mesh filename="obj_meshes/pincette_proximal_collider.obj"/>
      </geometry>
    </collision>
    <visual>
      <origin rpy="0 0 0" xyz="0 0 0 "/>
      <geometry>
        <!-- <mesh filename="file://$(find arm_description)/meshes/pincette_proximal_visual.obj" /> -->
        <mesh filename="obj_meshes/pincette_proximal_visual.obj"/>
      </geometry>
    </visual>
  </link>
  <link name="l_hand_proximal_mimic_link">
    <inertial>
      <origin rpy="0 0 0" xyz="0.00004101 0.002756 0.019654"/>
      <mass value="0.03926395"/>
      <inertia ixx="0.00001937" ixy="0.0" ixz="0.00000007" iyx="0.0" iyy="0.00002003" iyz="0.00000036" izx="0.00000007" izy="0.00000036" izz="0.00000463"/>
    </inertial>
    <collision>
      <origin rpy="0 0 0" xyz="0 0.0 0.0 "/>
      <geometry>
        <!-- <box size="0.031 0.026 0.06"/> -->
        <!-- <mesh filename="file://$(find arm_description)/meshes/pincette_proximal_collider.obj" /> -->
        <mesh filename="obj_meshes/pincette_proximal_collider.obj"/>
      </geometry>
    </collision>
    <visual>
      <origin rpy="0 0 0" xyz="0 0 0 "/>
      <geometry>
        <!-- <mesh filename="file://$(find arm_description)/meshes/pincette_proximal_visual.obj" /> -->
        <mesh filename="obj_meshes/pincette_proximal_visual.obj"/>
      </geometry>
    </visual>
  </link>
  <joint name="l_hand_finger_proximal" type="revolute">
    <origin rpy="0 0 0" xyz="-0.010196 0.03792 0.070028"/>
    <parent link="l_hand_palm_link"/>
    <child link="l_hand_proximal_link"/>
    <axis xyz="1 0 0"/>
    <limit effort="100.0" lower="-0.51" upper="0.554" velocity="10.0"/>
    <mimic joint="l_hand_finger" multiplier="-0.4689" offset="0.554"/>
    <dynamics damping="0.01" friction="0.1"/>
  </joint>
  <joint name="l_hand_finger_proximal_mimic" type="revolute">
    <origin rpy="0 0 3.141592653589793" xyz="-0.010196 -0.03792 0.070028"/>
    <parent link="l_hand_palm_link"/>
    <child link="l_hand_proximal_mimic_link"/>
    <axis xyz="1 0 0"/>
    <limit effort="100.0" lower="-0.51" upper="0.554" velocity="10.0"/>
    <dynamics damping="0.01" friction="0.1"/>
    <mimic joint="l_hand_finger_proximal" multiplier="1" offset="0"/>
  </joint>
  <link name="l_hand_distal_link">
    <inertial>
      <origin rpy="0 0 0" xyz="0.00000695 -0.00006402 0.01772685"/>
      <mass value="0.02821091"/>
      <inertia ixx="0.00000683" ixy="0.0" ixz="0.0" iyx="0.0" iyy="0.00000696" iyz="0.00000127" izx="0.0" izy="0.00000127" izz="0.0000028"/>
    </inertial>
    <collision>
      <origin rpy="0 0 0" xyz="0 0.0 0.0 "/>
      <geometry>
        <mesh filename="obj_meshes/pincette_distal_collider.obj"/>
      </geometry>
    </collision>
    <visual>
      <origin rpy="0 0 0" xyz="0 0 0 "/>
      <geometry>
        <mesh filename="obj_meshes/pincette_distal.obj"/>
      </geometry>
    </visual>
  </link>
  <joint name="l_hand_finger_distal" type="revolute">
    <origin rpy="0 0 0" xyz="0 0 0.049997"/>
    <parent link="l_hand_proximal_link"/>
    <child link="l_hand_distal_link"/>
    <axis xyz="1 0 0"/>
    <limit effort="100.0" lower="-0.51" upper="0.554" velocity="10.0"/>
    <!-- <mimic joint="${p}_finger_proximal" multiplier="-1" offset="0" /> -->
    <mimic joint="l_hand_finger" multiplier="0.4689" offset="-0.554"/>
    <dynamics damping="0.01" friction="0.1"/>
  </joint>
  <link name="l_hand_distal_mimic_link">
    <inertial>
      <origin rpy="0 0 0" xyz="0.00000695 -0.00006402 0.01772685"/>
      <mass value="0.02821091"/>
      <inertia ixx="0.00000683" ixy="0.0" ixz="0.0" iyx="0.0" iyy="0.00000696" iyz="0.00000127" izx="0.0" izy="0.00000127" izz="0.0000028"/>
    </inertial>
    <collision>
      <origin rpy="0 0 0" xyz="0 0.00 0.0 "/>
      <geometry>
        <mesh filename="obj_meshes/pincette_distal_collider.obj"/>
      </geometry>
    </collision>
    <visual>
      <origin rpy="0 0 0" xyz="0 0 0 "/>
      <geometry>
        <mesh filename="obj_meshes/pincette_distal.obj"/>
      </geometry>
    </visual>
  </link>
  <joint name="l_hand_finger_distal_mimic" type="revolute">
    <origin rpy="0 0 0" xyz="0 0 0.049997"/>
    <parent link="l_hand_proximal_mimic_link"/>
    <child link="l_hand_distal_mimic_link"/>
    <axis xyz="1 0 0"/>
    <limit effort="100.0" lower="-0.51" upper="0.554" velocity="10.0"/>
    <!-- <mimic joint="${p}_finger_proximal" multiplier="-1" offset="0" /> -->
    <mimic joint="l_hand_finger" multiplier="0.4689" offset="-0.554"/>
    <dynamics damping="0.01" friction="0.1"/>
  </joint>
  <!-- <gazebo reference="${p}_finger_distal_link"> -->
  <!--   <selfCollide>false</selfCollide> -->
  <!-- </gazebo> -->
  <!-- <gazebo reference="${p}_finger_distal_link_mimic"> -->
  <!--   <selfCollide>false</selfCollide> -->
  <!-- </gazebo> -->
  <link name="l_arm_tip">
    <inertial>
      <origin rpy="0.0 0.0 0.0" xyz="0.0 0.0 0.0"/>
      <mass value="0.001"/>
      <inertia ixx="1.0e-6" ixy="1.0e-8" ixz="1.0e-8" iyy="1.0e-6" iyz="1.0e-8" izz="1.0e-6"/>
    </inertial>
  </link>
  <joint name="l_tip_joint" type="fixed">
    <!-- Rotated to be aligned with trunk in resting pos (elbows at -90) -->
    <!-- <origin xyz="-0.012 0 0.14432" rpy="${pi} ${-pi/2} 0" /> -->
    <!-- <origin xyz="-0.012 0 0.14432" rpy="${pi} 0 0" /> -->
    <!-- Aligned with trunk in zero position -->
    <!-- <origin xyz="-0.012 0 0.14432" rpy="${pi} 0 0" /> -->
    <!-- Hard coded in symbolic ik... -->
    <origin rpy="3.141592653589793 0 0" xyz="0.0 0 0.10"/>
    <parent link="l_hand_palm_link"/>
    <child link="l_arm_tip"/>
  </joint>
  <link name="l_arm_tip_bottom">
    <inertial>
      <origin rpy="0.0 0.0 0.0" xyz="0.0 0.0 0.0"/>
      <mass value="0.001"/>
      <inertia ixx="1.0e-6" ixy="1.0e-8" ixz="1.0e-8" iyy="1.0e-6" iyz="1.0e-8" izz="1.0e-6"/>
    </inertial>
  </link>
  <joint name="l_tip_joint_bottom" type="fixed">
    <!-- <origin xyz="-0.028 0 0.14432" rpy="${pi} ${-pi/2} 0" /> -->
    <origin rpy="3.141592653589793 0 0" xyz="-0.028 0 0.14432"/>
    <parent link="l_hand_palm_link"/>
    <child link="l_arm_tip_bottom"/>
  </joint>
  <ros2_control name="gripper" type="system">
    <hardware>
      <!-- <plugin>fake_components/GenericSystem</plugin> -->
      <!-- test -->
      <plugin>dynamixel_2joints_system_hwi/DynamixelSystem</plugin>
      <param name="dxl_config_file">/home/reachy/reachy_ws/install/dynamixel_description/share/dynamixel_description/config/two_fake.yaml</param>
    </hardware>
    <gpio name="l_hand">
      <state_interface name="torque">
        <param name="initial_value">0.0</param>
      </state_interface>
      <command_interface name="torque"/>
    </gpio>
    <gpio name="r_hand">
      <state_interface name="torque">
        <param name="initial_value">0.0</param>
      </state_interface>
      <command_interface name="torque"/>
    </gpio>
    <joint name="l_hand_finger">
      <state_interface name="position">
        <param name="initial_value">0.0</param>
      </state_interface>
      <state_interface name="velocity">
        <param name="initial_value">0.0</param>
      </state_interface>
      <state_interface name="effort">
        <param name="initial_value">0.0</param>
      </state_interface>
      <command_interface name="position"/>
    </joint>
    <joint name="r_hand_finger">
      <state_interface name="position">
        <param name="initial_value">0.0</param>
      </state_interface>
      <state_interface name="velocity">
        <param name="initial_value">0.0</param>
      </state_interface>
      <state_interface name="effort">
        <param name="initial_value">0.0</param>
      </state_interface>
      <command_interface name="position"/>
    </joint>
    <gpio name="l_hand_raw_motor_1">
      <state_interface name="speed_limit"/>
      <command_interface name="speed_limit"/>
      <state_interface name="torque_limit"/>
      <command_interface name="torque_limit"/>
      <state_interface name="temperature"/>
      <state_interface name="mode"/>
      <command_interface name="mode"/>
      <state_interface name="p_gain"/>
      <command_interface name="p_gain"/>
      <state_interface name="i_gain"/>
      <command_interface name="i_gain"/>
      <state_interface name="d_gain"/>
      <command_interface name="d_gain"/>
      <state_interface name="current"/>
      <command_interface name="current"/>
    </gpio>
    <gpio name="r_hand_raw_motor_1">
      <state_interface name="speed_limit"/>
      <command_interface name="speed_limit"/>
      <state_interface name="torque_limit"/>
      <command_interface name="torque_limit"/>
      <state_interface name="temperature"/>
      <state_interface name="mode"/>
      <command_interface name="mode"/>
      <state_interface name="p_gain"/>
      <command_interface name="p_gain"/>
      <state_interface name="i_gain"/>
      <command_interface name="i_gain"/>
      <state_interface name="d_gain"/>
      <command_interface name="d_gain"/>
      <state_interface name="current"/>
      <command_interface name="current"/>
    </gpio>
    <!-- </xacro:unless> -->
  </ros2_control>
  <link name="depth_cam_l_optical">
    <inertial>
      <origin rpy="0.0 0.0 0.0" xyz="0.0 0.0 0.0"/>
      <mass value="0.001"/>
      <inertia ixx="1.0e-6" ixy="1.0e-8" ixz="1.0e-8" iyy="1.0e-6" iyz="1.0e-8" izz="1.0e-6"/>
    </inertial>
  </link>
  <link name="depth_cam_l_frame">
    <inertial>
      <origin rpy="0.0 0.0 0.0" xyz="0.0 0.0 0.0"/>
      <mass value="0.001"/>
      <inertia ixx="1.0e-6" ixy="1.0e-8" ixz="1.0e-8" iyy="1.0e-6" iyz="1.0e-8" izz="1.0e-6"/>
    </inertial>
  </link>
  <joint name="depth_cam_l_optical_joint" type="fixed">
    <origin rpy="-2.399827721492203 0.0 -1.5707963267948966" xyz="0.058 0.025 -0.03"/>
    <parent link="torso"/>
    <child link="depth_cam_l_optical"/>
  </joint>
  <joint name="depth_cam_l_frame_joint" type="fixed">
    <origin rpy="0.0 0.8290313946973066 0.0" xyz="0.058 0.025 -0.03"/>
    <parent link="torso"/>
    <child link="depth_cam_l_frame"/>
  </joint>
  <link name="depth_cam_rgb_optical">
    <inertial>
      <origin rpy="0.0 0.0 0.0" xyz="0.0 0.0 0.0"/>
      <mass value="0.001"/>
      <inertia ixx="1.0e-6" ixy="1.0e-8" ixz="1.0e-8" iyy="1.0e-6" iyz="1.0e-8" izz="1.0e-6"/>
    </inertial>
  </link>
  <link name="depth_cam_rgb_frame">
    <inertial>
      <origin rpy="0.0 0.0 0.0" xyz="0.0 0.0 0.0"/>
      <mass value="0.001"/>
      <inertia ixx="1.0e-6" ixy="1.0e-8" ixz="1.0e-8" iyy="1.0e-6" iyz="1.0e-8" izz="1.0e-6"/>
    </inertial>
  </link>
  <joint name="depth_cam_rgb_optical_joint" type="fixed">
    <origin rpy="-2.399827721492203 0.0 -1.5707963267948966" xyz="0.058 0.0155 -0.03"/>
    <parent link="torso"/>
    <child link="depth_cam_rgb_optical"/>
  </joint>
  <joint name="depth_cam_rgb_frame_joint" type="fixed">
    <origin rpy="0.0 0.8290313946973066 0.0" xyz="0.058 0.0155 -0.03"/>
    <parent link="torso"/>
    <child link="depth_cam_rgb_frame"/>
  </joint>
  <link name="depth_cam_r_optical">
    <inertial>
      <origin rpy="0.0 0.0 0.0" xyz="0.0 0.0 0.0"/>
      <mass value="0.001"/>
      <inertia ixx="1.0e-6" ixy="1.0e-8" ixz="1.0e-8" iyy="1.0e-6" iyz="1.0e-8" izz="1.0e-6"/>
    </inertial>
  </link>
  <link name="depth_cam_r_frame">
    <inertial>
      <origin rpy="0.0 0.0 0.0" xyz="0.0 0.0 0.0"/>
      <mass value="0.001"/>
      <inertia ixx="1.0e-6" ixy="1.0e-8" ixz="1.0e-8" iyy="1.0e-6" iyz="1.0e-8" izz="1.0e-6"/>
    </inertial>
  </link>
  <joint name="depth_cam_r_optical_joint" type="fixed">
    <origin rpy="-2.399827721492203 0.0 -1.5707963267948966" xyz="0.058 -0.025 -0.03"/>
    <parent link="torso"/>
    <child link="depth_cam_r_optical"/>
  </joint>
  <joint name="depth_cam_r_frame_joint" type="fixed">
    <origin rpy="0.0 0.8290313946973066 0.0 " xyz="0.058 -0.025 -0.03"/>
    <parent link="torso"/>
    <child link="depth_cam_r_frame"/>
  </joint>
  <gazebo reference="depth_cam_l_frame">
    <!-- <link name="left_camera"> -->
    <sensor name="left_camera" type="camera">
      <!-- Set always_on only sensor, not on plugin -->
      <always_on>0</always_on>
      <!-- Set update_rate only sensor, not on plugin -->
      <update_rate>30</update_rate>
      <camera name="depth_cam_l">
        <horizontal_fov>1.5707963267948966</horizontal_fov>
        <image>
          <width>1280</width>
          <height>720</height>
          <format>B8G8R8</format>
        </image>
        <distortion>
          <k1>0.006059</k1>
          <k2>-0.048786</k2>
          <k3>0.033282</k3>
          <p1>-0.000877</p1>
          <p2>-0.000732</p2>
          <center>0.5 0.5</center>
        </distortion>
        <noise>
          <type>gaussian</type>
          <mean>0.0</mean>
          <stddev>0.007</stddev>
        </noise>
      </camera>
      <!-- Use camera, not camera_triggered -->
      <plugin filename="libgazebo_ros_camera.so" name="depth_left_camera_controller">
        <ros>
          <namespace>camera</namespace>
          <remapping>left/image_raw:=/camera/left/color/image_raw</remapping>
          <remapping>left/image_raw/compressed:=/camera/left/color/image_raw/compressed</remapping>
          <remapping>left/camera_info:=/camera/left/color/camera_info</remapping>
        </ros>
        <camera_name>left</camera_name>
        <!-- <ros> -->
        <!--   <namespace>custom_ns</namespace> -->
        <!--   <argument>image_raw:=custom_img</argument> -->
        <!--   <argument>camera_info:=custom_info</argument> -->
        <!-- </ros> -->
        <!-- Set camera name. If empty, defaults to sensor name (i.e. "sensor_name") -->
        <!-- <camera_name>left_camera</camera_name> -->
        <!-- Set TF frame name. If empty, defaults to link name (i.e. "link_name") -->
        <frame_name>depth_cam_l_optical</frame_name>
        <hack_baseline>0.07</hack_baseline>
        <!-- No need to repeat distortion parameters or to set autoDistortion -->
      </plugin>
    </sensor>
  </gazebo>
  <gazebo reference="depth_cam_r_frame">
    <!-- <link name="left_camera"> -->
    <sensor name="right_camera" type="camera">
      <!-- Set always_on only sensor, not on plugin -->
      <always_on>0</always_on>
      <!-- Set update_rate only sensor, not on plugin -->
      <update_rate>30</update_rate>
      <camera name="depth_cam_r">
        <horizontal_fov>1.5707963267948966</horizontal_fov>
        <image>
          <width>1280</width>
          <height>720</height>
          <format>B8G8R8</format>
        </image>
        <distortion>
          <k1>0.006059</k1>
          <k2>-0.048786</k2>
          <k3>0.033282</k3>
          <p1>-0.000877</p1>
          <p2>-0.000732</p2>
          <center>0.5 0.5</center>
        </distortion>
        <noise>
          <type>gaussian</type>
          <mean>0.0</mean>
          <stddev>0.007</stddev>
        </noise>
      </camera>
      <!-- Use camera, not camera_triggered -->
      <plugin filename="libgazebo_ros_camera.so" name="depth_right_camera_controller">
        <ros>
          <namespace>camera</namespace>
          <remapping>right/image_raw:=/camera/right/color/image_raw</remapping>
          <remapping>right/image_raw/compressed:=/camera/right/color/image_raw/compressed</remapping>
          <remapping>right/camera_info:=/camera/right/color/camera_info</remapping>
          <!-- <remapping>image_raw:=image_raw</remapping> -->
          <!-- <remapping>camera_info:=camera_info</remapping> -->
        </ros>
        <camera_name>right</camera_name>
        <!-- <ros> -->
        <!--   <namespace>custom_ns</namespace> -->
        <!--   <argument>image_raw:=custom_img</argument> -->
        <!--   <argument>camera_info:=custom_info</argument> -->
        <!-- </ros> -->
        <!-- Set camera name. If empty, defaults to sensor name (i.e. "sensor_name") -->
        <!-- <camera_name>left_camera</camera_name> -->
        <!-- Set TF frame name. If empty, defaults to link name (i.e. "link_name") -->
        <frame_name>depth_cam_r_optical</frame_name>
        <hack_baseline>0.07</hack_baseline>
        <!-- No need to repeat distortion parameters or to set autoDistortion -->
      </plugin>
    </sensor>
  </gazebo>
  <gazebo reference="depth_cam_l_frame">
    <sensor name="depth_camera" type="depth">
      <always_on>true</always_on>
      <update_rate>30</update_rate>
      <pose>0 0 0 0 0 0</pose>
      <camera name="depth_camera">
        <horizontal_fov>1.5707963267948966</horizontal_fov>
        <image>
          <width>1280</width>
          <height>720</height>
          <format>B8G8R8</format>
        </image>
        <distortion>
          <k1>0.006059</k1>
          <k2>-0.048786</k2>
          <k3>0.033282</k3>
          <p1>-0.000877</p1>
          <p2>-0.000732</p2>
          <center>0.5 0.5</center>
        </distortion>
        <clip>
          <near>0.05</near>
          <far>8</far>
        </clip>
        <noise>
          <type>gaussian</type>
          <mean>0.0</mean>
          <stddev>0.07</stddev>
        </noise>
      </camera>
      <plugin filename="libgazebo_ros_camera.so" name="depth_driver">
        <ros>
          <namespace>/</namespace>
          <remapping>camera/image_raw:=camera/color/image_raw</remapping>
          <remapping>camera/image_raw/compressed:=camera/color/image_raw/compressed</remapping>
          <remapping>camera/camera_info:=camera/color/camera_info</remapping>
          <remapping>camera/image_depth:=camera/depth/image_raw</remapping>
          <remapping>camera/camera_info_depth:=camera/depth/camera_info</remapping>
          <remapping>camera/points:=camera/depth/points</remapping>
        </ros>
        <camera_name>camera</camera_name>
        <frame_name>depth_cam_l_optical</frame_name>
        <hack_baseline>0.07</hack_baseline>
        <min_depth>0.05</min_depth>
        <max_depth>8.0</max_depth>
      </plugin>
    </sensor>
  </gazebo>
  <!-- <link name="r_wrist_cam_frame"/> -->
  <!-- <joint name="r_wrist_cam_frame_joint" type="fixed"> -->
  <!--   <origin xyz="0 0 0" rpy="0.0 0 0"/> -->
  <!--   <parent link="r_gripper_palm_link"/> -->
  <!--   <child link="r_wrist_cam_frame"/> -->
  <!-- </joint> -->
  <!-- <link name="r_wrist_camera"/> -->
  <!-- <joint name="r_wrist_camera_joint" type="fixed"> -->
  <!--   <origin xyz="0.11 -0.01 0.08" rpy="0.35 -0.7 0"/> -->
  <!--   <parent link="r_wrist_cam_frame"/> -->
  <!--   <child link="r_wrist_camera"/> -->
  <!-- </joint> -->
</robot>
