<mujoco model="reachy2">
  <compiler angle="radian" meshdir="./obj_meshes/"/>
  <asset>
    <mesh name="mobile_base_visual" file="mobile_base_visual.obj"/>
    <mesh name="torso_visual_high" file="torso_visual_high.obj"/>
    <mesh name="torso_collider_no_cone" file="torso_collider_no_cone.obj"/>
    <mesh name="head_visual" file="head_visual.obj"/>
    <mesh name="head_collider" file="head_collider.obj"/>
    <mesh name="2D_sphere_visual" file="2D_sphere_visual.obj"/>
    <mesh name="upper_arm_visual" file="upper_arm_visual.obj"/>
    <mesh name="upper_arm_collider" file="upper_arm_collider.obj"/>
    <mesh name="forearm_visual" file="forearm_visual.obj"/>
    <mesh name="forearm_collider" file="forearm_collider.obj"/>
    <mesh name="pincette_right_collider" file="pincette_right_collider.obj"/>
    <mesh name="pincette_right_visual" file="pincette_right_visual.obj"/>
    <mesh name="pincette_proximal_collider" file="pincette_proximal_collider.obj"/>
    <mesh name="pincette_proximal_visual" file="pincette_proximal_visual.obj"/>
    <mesh name="pincette_distal_collider" file="pincette_distal_collider.obj"/>
    <mesh name="pincette_distal" file="pincette_distal.obj"/>
    <mesh name="pincette_left_collider" file="pincette_left_collider.obj"/>
    <mesh name="pincette_left_visual" file="pincette_left_visual.obj"/>
  </asset>

  <default>
	<joint damping="1" frictionloss="10"/>
	<position kp="100"/>
	</default>
  <worldbody>
    <body name="trunk">
        <freejoint/>
        <geom type="mesh" contype="0" conaffinity="0" group="1" density="0" rgba="0.8 0.8 0.8 1" mesh="mobile_base_visual"/>
        <geom size="0.245 0.13045" pos="0 0 0.13045" type="cylinder" rgba="0.8 0.8 0.8 1"/>
        <geom size="0.02 0.02 0.318" pos="-0.122 0 0.482" type="box" contype="0" conaffinity="0" group="1" density="0" rgba="0.8 0.8 0.8 1"/>
        <geom size="0.02 0.02 0.318" pos="-0.122 0 0.482" type="box" rgba="0.8 0.8 0.8 1"/>
        <geom pos="-0.0452 0 1" type="mesh" contype="0" conaffinity="0" group="1" density="0" mesh="torso_visual_high"/>
        <!-- <geom pos="-0.0452 0 1" type="mesh" mesh="torso_collider_no_cone"/> -->
        <geom size="0.02 0.02 0.32546" pos="0.019486 0.0852348 0.482" quat="0.965846 0.0254078 -0.103998 0.235966" type="box" contype="0" conaffinity="0" group="1" density="0" rgba="0.8 0.8 0.8 1"/>
        <geom size="0.02 0.02 0.32546" pos="0.019486 0.0852348 0.482" quat="0.965846 0.0254078 -0.103998 0.235966" type="box" rgba="0.8 0.8 0.8 1"/>
        <geom size="0.02 0.02 0.32546" pos="0.019486 -0.0852348 0.482" quat="0.965846 -0.0254078 -0.103998 -0.235966" type="box" contype="0" conaffinity="0" group="1" density="0" rgba="0.8 0.8 0.8 1"/>
        <geom size="0.02 0.02 0.32546" pos="0.019486 -0.0852348 0.482" quat="0.965846 -0.0254078 -0.103998 -0.235966" type="box" rgba="0.8 0.8 0.8 1"/>
        <body name="neck_dummy_link1" pos="-0.0452 0 1.125" quat="0.996195 0 0.0871557 0">
        <inertial pos="0 0 0" quat="0.5 0.5 -0.5 0.5" mass="0.005" diaginertia="3e-06 2.54167e-06 2.54167e-06"/>
        <joint name="neck_roll" pos="0 0 0" axis="1 0 0" range="-0.35 0.35" actuatorfrcrange="-1000 1000"/>
        <body name="neck_dummy_link2">
            <inertial pos="0 0 0" quat="0.5 0.5 -0.5 0.5" mass="0.005" diaginertia="3e-06 2.54167e-06 2.54167e-06"/>
            <joint name="neck_pitch" pos="0 0 0" axis="0 1 0" range="-0.35 0.35" actuatorfrcrange="-1000 1000"/>
            <body name="neck_link">
            <inertial pos="0.00474964 -4.81305e-05 0.0094431" quat="0.997531 0.000139363 0.0697058 -0.00852459" mass="0.82002" diaginertia="0.00259236 0.00237343 0.00120077"/>
            <joint name="neck_yaw" pos="0 0 0" axis="0 0 1" range="-1.57 1.57" actuatorfrcrange="-1000 1000"/>
            <geom type="mesh" contype="0" conaffinity="0" group="1" density="0" mesh="head_visual"/>
            <!-- <geom type="mesh" mesh="head_collider"/> -->
            <camera name="left_teleop_cam"  pos="0 0 0" euler="0 0 0"/>
            </body>
        </body>
        </body>
        <body name="r_shoulder_first_link" pos="-0.0452 -0.2 1" quat="0.987672 0.0864101 0.0113761 0.13003">
        <inertial pos="9.6e-05 -1.5e-05 -0.01777" quat="0.996708 0.000282525 0.00106617 -0.0810711" mass="0.487" diaginertia="0.000578016 0.000572943 0.000243342"/>
        <joint name="r_shoulder_pitch" pos="0 0 0" axis="0 1 0" range="-1.5708 1.5708" actuatorfrcrange="-1000 1000"/>
        <geom quat="0.707107 0.707107 0 0" type="mesh" contype="0" conaffinity="0" group="1" density="0" mesh="2D_sphere_visual"/>
        <body name="r_shoulder_ball_link">
            <inertial pos="0.000507434 -0.000666942 -0.144869" quat="0.708212 0.0149758 0.00141647 0.705839" mass="1.625" diaginertia="0.00796804 0.00710258 0.00182791"/>
            <joint name="r_shoulder_roll" pos="0 0 0" axis="1 0 0" range="-1.5708 0" actuatorfrcrange="-1000 1000"/>
            <geom quat="0 0.707107 0.707107 0" type="mesh" contype="0" conaffinity="0" group="1" density="0" mesh="upper_arm_visual"/>
            <!-- <geom quat="0 0.707107 0.707107 0" type="mesh" mesh="upper_arm_collider"/> -->
            <body name="r_elbow_first_link" pos="0 0 -0.28" quat="-1 3.26795e-07 0 0">
            <inertial pos="9.6e-05 -1.5e-05 -0.01777" quat="0.996708 0.000282525 0.00106617 -0.0810711" mass="0.487" diaginertia="0.000578016 0.000572943 0.000243342"/>
            <joint name="r_elbow_yaw" pos="0 0 0" axis="0 0 1" range="-1.5708 1.5708" actuatorfrcrange="-1000 1000"/>
            <geom quat="2.31079e-07 0.707107 -0.707107 -2.31079e-07" type="mesh" contype="0" conaffinity="0" group="1" density="0" mesh="2D_sphere_visual"/>
            <body name="r_elbow_ball_link">
                <inertial pos="-0.002537 0.000925858 -0.140058" quat="0.999817 -0.0151009 -0.00617344 -0.00995245" mass="0.910191" diaginertia="0.004521 0.00434813 0.000475022"/>
                <joint name="r_elbow_pitch" pos="0 0 0" axis="0 1 0" range="-2.25 0.1" actuatorfrcrange="-1000 1000" damping="0.1" frictionloss="0.1"/>
                <geom quat="2.31079e-07 0.707107 0.707107 2.31079e-07" type="mesh" contype="0" conaffinity="0" group="1" density="0" mesh="forearm_visual"/>
                <!-- <geom quat="2.31079e-07 0.707107 0.707107 2.31079e-07" type="mesh" mesh="forearm_collider"/> -->
                <body name="r_wrist_dummy_link1" pos="1.83005e-07 0 -0.28" quat="-1 0 3.26795e-07 0">
                <inertial pos="0 0 0" quat="0.5 0.5 -0.5 0.5" mass="0.001" diaginertia="2.66667e-07 1.41667e-07 1.41667e-07"/>
                <joint name="r_wrist_roll" pos="0 0 0" axis="1 0 0" range="-0.785398 0.785398" actuatorfrcrange="-1000 1000"/>
                <body name="r_wrist_dummy_link2">
                    <inertial pos="0 0 0" quat="0.5 0.5 -0.5 0.5" mass="0.001" diaginertia="2.66667e-07 1.41667e-07 1.41667e-07"/>
                    <joint name="r_wrist_pitch" pos="0 0 0" axis="0 1 0" range="-0.785398 0.785398" actuatorfrcrange="-1000 1000"/>
                    <body name="r_wrist_link">
                    <inertial pos="0.00665364 -0.00715931 -0.0354148" quat="0.929428 -0.299114 -0.160695 0.144467" mass="0.40898" diaginertia="0.000392877 0.000341836 0.000227578"/>
                    <joint name="r_wrist_yaw" pos="0 0 0" axis="0 0 1" range="-1.57 1.57" actuatorfrcrange="-1000 1000"/>
                    <geom size="0.02 0.005" type="cylinder" contype="0" conaffinity="0" group="1" density="0" rgba="0.8 0.8 0.8 1"/>
                    <geom size="0.02 0.005" pos="0 0 0.005" type="cylinder" rgba="0.8 0.8 0.8 1"/>
                    <!-- <geom quat="3.26795e-07 1 0 0" type="mesh" mesh="pincette_right_collider"/> -->
                    <geom quat="3.26795e-07 1 0 0" type="mesh" contype="0" conaffinity="0" group="1" density="0" mesh="pincette_right_visual"/>
                    <body name="r_hand_virtual_gripper_link" pos="0 -4.57696e-08 -0.070028" quat="3.26795e-07 1 0 0">
                        <inertial pos="0 0 0" quat="0.820473 0.339851 -0.17592 0.424708" mass="0.001" diaginertia="1.02e-06 9.9e-07 9.9e-07"/>
                        <joint name="r_hand_finger" pos="0 0 0" axis="1 0 0" range="0 2.27" actuatorfrcrange="-100 100"/>
                    </body>
                    <body name="r_hand_proximal_link" pos="-0.010196 -0.03792 -0.070028" quat="3.26795e-07 1 0 0">
                        <inertial pos="4.101e-05 0.002756 0.019654" quat="0.707941 0.00659338 -0.00992804 0.706171" mass="0.0392639" diaginertia="2.00384e-05 1.93703e-05 4.62126e-06"/>
                        <joint name="r_hand_finger_proximal" pos="0 0 0" axis="1 0 0" range="-0.51 0.554" actuatorfrcrange="-100 100"/>
                        <!-- <geom type="mesh" mesh="pincette_proximal_collider"/> -->
                        <geom type="mesh" contype="0" conaffinity="0" group="1" density="0" mesh="pincette_proximal_visual"/>
                        <body name="r_hand_distal_link" pos="0 0 0.049997">
                        <inertial pos="6.95e-06 -6.402e-05 0.0177268" quat="0.700477 0.096599 -0.096599 0.700477" mass="0.0282109" diaginertia="7.31707e-06 6.83e-06 2.44293e-06"/>
                        <joint name="r_hand_finger_distal" pos="0 0 0" axis="1 0 0" range="-0.51 0.554" actuatorfrcrange="-100 100"/>
                        <geom type="mesh" mesh="pincette_distal_collider"/>
                        <geom type="mesh" contype="0" conaffinity="0" group="1" density="0" mesh="pincette_distal"/>
                        </body>
                    </body>
                    <body name="r_hand_proximal_mimic_link" pos="-0.010196 0.03792 -0.070028" quat="0 3.26795e-07 -1 3.26795e-07">
                        <inertial pos="4.101e-05 0.002756 0.019654" quat="0.707941 0.00659338 -0.00992804 0.706171" mass="0.0392639" diaginertia="2.00384e-05 1.93703e-05 4.62126e-06"/>
                        <joint name="r_hand_finger_proximal_mimic" pos="0 0 0" axis="1 0 0" range="-0.51 0.554" actuatorfrcrange="-100 100"/>
                        <!-- <geom type="mesh" mesh="pincette_proximal_collider"/> -->
                        <geom type="mesh" contype="0" conaffinity="0" group="1" density="0" mesh="pincette_proximal_visual"/>
                        <body name="r_hand_distal_mimic_link" pos="0 0 0.049997">
                        <inertial pos="6.95e-06 -6.402e-05 0.0177268" quat="0.700477 0.096599 -0.096599 0.700477" mass="0.0282109" diaginertia="7.31707e-06 6.83e-06 2.44293e-06"/>
                        <joint name="r_hand_finger_distal_mimic" pos="0 0 0" axis="1 0 0" range="-0.51 0.554" actuatorfrcrange="-100 100" damping="0.1" frictionloss="0.1"/>
                        <!-- <geom type="mesh" mesh="pincette_distal_collider"/> -->
                        <geom type="mesh" contype="0" conaffinity="0" group="1" density="0" mesh="pincette_distal"/>
                        </body>
                    </body>
                    </body>
                </body>
                </body>
            </body>
            </body>
        </body>
        </body>
        <body name="l_shoulder_first_link" pos="-0.0452 0.2 1" quat="0.987672 -0.0864101 0.0113761 -0.13003">
        <inertial pos="9.6e-05 -1.5e-05 -0.01777" quat="0.996708 0.000282525 0.00106617 -0.0810711" mass="0.487" diaginertia="0.000578016 0.000572943 0.000243342"/>
        <joint name="l_shoulder_pitch" pos="0 0 0" axis="0 1 0" range="-1.5708 1.5708" actuatorfrcrange="-1000 1000"/>
        <geom quat="0.707107 -0.707107 0 0" type="mesh" contype="0" conaffinity="0" group="1" density="0" mesh="2D_sphere_visual"/>
        <body name="l_shoulder_ball_link">
            <inertial pos="-0.000507434 0.000666942 -0.144869" quat="0.708212 -0.0149787 -0.00142164 0.70584" mass="1.625" diaginertia="0.00796804 0.00710258 0.00182791"/>
            <joint name="l_shoulder_roll" pos="0 0 0" axis="1 0 0" range="0 1.5708" actuatorfrcrange="-1000 1000" damping="0.1" frictionloss="0.1"/>
            <geom quat="0 0.707107 -0.707107 0" type="mesh" contype="0" conaffinity="0" group="1" density="0" mesh="upper_arm_visual"/>
            <!-- <geom quat="0 0.707107 -0.707107 0" type="mesh" mesh="upper_arm_collider"/> -->
            <body name="l_elbow_first_link" pos="0 0 -0.28" quat="-1 3.26795e-07 0 0">
            <inertial pos="9.6e-05 -1.5e-05 -0.01777" quat="0.996708 0.000282525 0.00106617 -0.0810711" mass="0.487" diaginertia="0.000578016 0.000572943 0.000243342"/>
            <joint name="l_elbow_yaw" pos="0 0 0" axis="0 0 1" range="-1.5708 1.5708" actuatorfrcrange="-1000 1000"/>
            <geom quat="2.31079e-07 0.707107 0.707107 2.31079e-07" type="mesh" contype="0" conaffinity="0" group="1" density="0" mesh="2D_sphere_visual"/>
            <body name="l_elbow_ball_link">
                <inertial pos="-0.002537 0.000925858 -0.140058" quat="0.999817 -0.0151009 -0.00617344 -0.00995245" mass="0.910191" diaginertia="0.004521 0.00434813 0.000475022"/>
                <joint name="l_elbow_pitch" pos="0 0 0" axis="0 1 0" range="-2.25 0.1" actuatorfrcrange="-1000 1000"/>
                <geom quat="2.31079e-07 0.707107 0.707107 2.31079e-07" type="mesh" contype="0" conaffinity="0" group="1" density="0" mesh="forearm_visual"/>
                <!-- <geom quat="2.31079e-07 0.707107 0.707107 2.31079e-07" type="mesh" mesh="forearm_collider"/> -->
                <body name="l_wrist_dummy_link1" pos="1.83005e-07 0 -0.28" quat="-1 0 3.26795e-07 0">
                <inertial pos="0 0 0" quat="0.5 0.5 -0.5 0.5" mass="0.001" diaginertia="2.66667e-07 1.41667e-07 1.41667e-07"/>
                <joint name="l_wrist_roll" pos="0 0 0" axis="1 0 0" range="-0.785398 0.785398" actuatorfrcrange="-1000 1000"/>
                <body name="l_wrist_dummy_link2">
                    <inertial pos="0 0 0" quat="0.5 0.5 -0.5 0.5" mass="0.001" diaginertia="2.66667e-07 1.41667e-07 1.41667e-07"/>
                    <joint name="l_wrist_pitch" pos="0 0 0" axis="0 1 0" range="-0.785398 0.785398" actuatorfrcrange="-1000 1000"/>
                    <body name="l_wrist_link">
                    <inertial pos="0.00665364 0.00715926 -0.0354148" quat="0.934165 0.295002 -0.159399 -0.122072" mass="0.40898" diaginertia="0.00039149 0.000341463 0.000227058"/>
                    <joint name="l_wrist_yaw" pos="0 0 0" axis="0 0 1" range="-1.57 1.57" actuatorfrcrange="-1000 1000" damping="0.1" frictionloss="0.1"/>
                    <geom size="0.02 0.005" type="cylinder" contype="0" conaffinity="0" group="1" density="0" rgba="0.8 0.8 0.8 1"/>
                    <geom size="0.02 0.005" pos="0 0 0.005" type="cylinder" rgba="0.8 0.8 0.8 1"/>
                    <!-- <geom quat="3.26795e-07 1 0 0" type="mesh" mesh="pincette_left_collider"/> -->
                    <geom quat="3.26795e-07 1 0 0" type="mesh" contype="0" conaffinity="0" group="1" density="0" mesh="pincette_left_visual"/>
                    <body name="l_hand_virtual_gripper_link" pos="0 -4.57696e-08 -0.070028" quat="3.26795e-07 1 0 0">
                        <inertial pos="0 0 0" quat="0.820473 0.339851 -0.17592 0.424708" mass="0.001" diaginertia="1.02e-06 9.9e-07 9.9e-07"/>
                        <joint name="l_hand_finger" pos="0 0 0" axis="1 0 0" range="0 2.27" actuatorfrcrange="-100 100"/>
                    </body>
                    <body name="l_hand_proximal_link" pos="-0.010196 -0.03792 -0.070028" quat="3.26795e-07 1 0 0">
                        <inertial pos="4.101e-05 0.002756 0.019654" quat="0.707941 0.00659338 -0.00992804 0.706171" mass="0.0392639" diaginertia="2.00384e-05 1.93703e-05 4.62126e-06"/>
                        <joint name="l_hand_finger_proximal" pos="0 0 0" axis="1 0 0" range="-0.51 0.554" actuatorfrcrange="-100 100"/>
                        <!-- <geom type="mesh" mesh="pincette_proximal_collider"/> -->
                        <geom type="mesh" contype="0" conaffinity="0" group="1" density="0" mesh="pincette_proximal_visual"/>
                        <body name="l_hand_distal_link" pos="0 0 0.049997">
                        <inertial pos="6.95e-06 -6.402e-05 0.0177268" quat="0.700477 0.096599 -0.096599 0.700477" mass="0.0282109" diaginertia="7.31707e-06 6.83e-06 2.44293e-06"/>
                        <joint name="l_hand_finger_distal" pos="0 0 0" axis="1 0 0" range="-0.51 0.554" actuatorfrcrange="-100 100"/>
                        <!-- <geom type="mesh" mesh="pincette_distal_collider"/> -->
                        <geom type="mesh" contype="0" conaffinity="0" group="1" density="0" mesh="pincette_distal"/>
                        </body>
                    </body>
                    <body name="l_hand_proximal_mimic_link" pos="-0.010196 0.03792 -0.070028" quat="0 3.26795e-07 -1 3.26795e-07">
                        <inertial pos="4.101e-05 0.002756 0.019654" quat="0.707941 0.00659338 -0.00992804 0.706171" mass="0.0392639" diaginertia="2.00384e-05 1.93703e-05 4.62126e-06"/>
                        <joint name="l_hand_finger_proximal_mimic" pos="0 0 0" axis="1 0 0" range="-0.51 0.554" actuatorfrcrange="-100 100"/>
                        <!-- <geom type="mesh" mesh="pincette_proximal_collider"/> -->
                        <geom type="mesh" contype="0" conaffinity="0" group="1" density="0" mesh="pincette_proximal_visual"/>
                        <body name="l_hand_distal_mimic_link" pos="0 0 0.049997">
                        <inertial pos="6.95e-06 -6.402e-05 0.0177268" quat="0.700477 0.096599 -0.096599 0.700477" mass="0.0282109" diaginertia="7.31707e-06 6.83e-06 2.44293e-06"/>
                        <joint name="l_hand_finger_distal_mimic" pos="0 0 0" axis="1 0 0" range="-0.51 0.554" actuatorfrcrange="-100 100" damping="0.1" frictionloss="0.1"/>
                        <!-- <geom type="mesh" mesh="pincette_distal_collider"/> -->
                        <geom type="mesh" contype="0" conaffinity="0" group="1" density="0" mesh="pincette_distal"/>
                        </body>
                    </body>
                    </body>
                </body>
                </body>
            </body>
            </body>
        </body>
    </body>
  </body>
  </worldbody>
  <actuator>
    <position name="neck_roll" joint="neck_roll" gear="1" inheritrange="1"  />
    <position name="neck_pitch" joint="neck_pitch" gear="1" inheritrange="1"  />
    <position name="neck_yaw" joint="neck_yaw" gear="1" inheritrange="1"  />
    <position name="l_shoulder_pitch" joint="l_shoulder_pitch" gear="1" inheritrange="1"  />
    <position name="l_shoulder_roll" joint="l_shoulder_roll" gear="1" inheritrange="1"  />
    <position name="l_elbow_yaw" joint="l_elbow_yaw" gear="1" inheritrange="1"  />
    <position name="l_elbow_pitch" joint="l_elbow_pitch" gear="1" inheritrange="1"  />
    <position name="l_wrist_roll" joint="l_wrist_roll" gear="1" inheritrange="1"  />
    <position name="l_wrist_pitch" joint="l_wrist_pitch" gear="1" inheritrange="1"  />
    <position name="l_wrist_yaw" joint="l_wrist_yaw" gear="1" inheritrange="1"  />
    <position name="r_shoulder_pitch" joint="r_shoulder_pitch" gear="1" inheritrange="1"  />
    <position name="r_shoulder_roll" joint="r_shoulder_roll" gear="1" inheritrange="1"  />
    <position name="r_elbow_yaw" joint="r_elbow_yaw" gear="1" inheritrange="1"  />
    <position name="r_elbow_pitch" joint="r_elbow_pitch" gear="1" inheritrange="1"  />
    <position name="r_wrist_roll" joint="r_wrist_roll" gear="1" inheritrange="1"  />
    <position name="r_wrist_pitch" joint="r_wrist_pitch" gear="1" inheritrange="1"  />
    <position name="r_wrist_yaw" joint="r_wrist_yaw" gear="1" inheritrange="1"  />
    <!-- <position name="r_hand_finger" joint="r_hand_finger" gear="1" inheritrange="1"  />
    <position name="r_hand_finger_proximal" joint="r_hand_finger_proximal" gear="1" inheritrange="1"  />
    <position name="r_hand_finger_distal" joint="r_hand_finger_distal" gear="1" inheritrange="1"  />
    <position name="l_hand_finger" joint="l_hand_finger" gear="1" inheritrange="1"  />
    <position name="l_hand_finger_proximal" joint="l_hand_finger_proximal" gear="1" inheritrange="1"  />
    <position name="l_hand_finger_distal" joint="l_hand_finger_distal" gear="1" inheritrange="1"  />
    <position name="r_hand_finger_proximal_mimic" joint="r_hand_finger_proximal_mimic" gear="1" inheritrange="1"  />
    <position name="r_hand_finger_distal_mimic" joint="r_hand_finger_distal_mimic" gear="1" inheritrange="1"  />
    <position name="l_hand_finger_proximal_mimic" joint="l_hand_finger_proximal_mimic" gear="1" inheritrange="1"  />
    <position name="l_hand_finger_distal_mimic" joint="l_hand_finger_distal_mimic" gear="1" inheritrange="1"  /> -->
  </actuator>
</mujoco>
